Workbook

Sheet Painel
A1: Painel de Estoque — LX03
A2: Barry Callebaut · Estoque por posição no depósito (fonte: SAP LX03) — os cartões, gráficos e tabelas abaixo mudam sozinhos ao trocar os filtros ou ao rodar a atualização diária.
A3: =CONCATENATE("Última atualização: ",Parametros!$B$5," · Arquivo: ",Parametros!$B$6) -> Última atualização: 20/09/2026 21:12 · Arquivo: lx03_2026-09-20.xlsx
A4: FILTROS (selecione para atualizar todo o painel)
A5: Tipo de Depósito: | B5: (Todos) | D5: Centro: | E5: (Todos) | G5: Alerta: | H5: (Todos)
A7: INDICADORES GERAIS (conforme filtro selecionado acima)
A8: TOTAL EM KG | C8: TOTAL EM UN | E8: POSIÇÕES OCUPADAS | G8: POSIÇÕES VAZIAS | I8: TAXA DE OCUPAÇÃO | K8: MATERIAIS ÚNICOS (armazém)
A9: =SUMPRODUCT((Dados_SAP!$K$2:$K$10543="KG")*((Painel!$B$5="(Todos)")+(Dados_SAP!$A$2:$A$10543=Painel!$B$5)>0)*((Painel!$E$5="(Todos)")+(Dados_SAP!$P$2:$P$10543=Painel!$E$5)>0)*((Painel!$H$5="(Todos)")+(Dados_SAP!$S$2:$S$10543=Painel!$H$5)>0),Dados_SAP!$J$2:$J$10543) -> 4644718.8 | C9: =SUMPRODUCT((Dados_SAP!$K$2:$K$10543="UN")*((Painel!$B$5="(Todos)")+(Dados_SAP!$A$2:$A$10543=Painel!$B$5)>0)*((Painel!$E$5="(Todos)")+(Dados_SAP!$P$2:$P$10543=Painel!$E$5)>0)*((Painel!$H$5="(Todos)")+(Dados_SAP!$S$2:$S$10543=Painel!$H$5)>0),Dados_SAP!$J$2:$J$10543) -> 6163440.7 | E9: =SUMPRODUCT((Dados_SAP!$S$2:$S$10543<>"VAZIA")*((Painel!$B$5="(Todos)")+(Dados_SAP!$A$2:$A$10543=Painel!$B$5)>0)*((Painel!$E$5="(Todos)")+(Dados_SAP!$P$2:$P$10543=Painel!$E$5)>0)*((Painel!$H$5="(Todos)")+(Dados_SAP!$S$2:$S$10543=Painel!$H$5)>0)) -> 8762 | G9: =SUMPRODUCT((Dados_SAP!$S$2:$S$10543="VAZIA")*((Painel!$B$5="(Todos)")+(Dados_SAP!$A$2:$A$10543=Painel!$B$5)>0)*((Painel!$E$5="(Todos)")+(Dados_SAP!$P$2:$P$10543=Painel!$E$5)>0)*((Painel!$H$5="(Todos)")+(Dados_SAP!$S$2:$S$10543=Painel!$H$5)>0)) -> 1780 | I9: =IFERROR(SUMPRODUCT((Dados_SAP!$S$2:$S$10543<>"VAZIA")*((Painel!$B$5="(Todos)")+(Dados_SAP!$A$2:$A$10543=Painel!$B$5)>0)*((Painel!$E$5="(Todos)")+(Dados_SAP!$P$2:$P$10543=Painel!$E$5)>0)*((Painel!$H$5="(Todos)")+(Dados_SAP!$S$2:$S$10543=Painel!$H$5)>0))/(SUMPRODUCT((Dados_SAP!$S$2:$S$10543<>"VAZIA")*((Painel!$B$5="(Todos)")+(Dados_SAP!$A$2:$A$10543=Painel!$B$5)>0)*((Painel!$E$5="(Todos)")+(Dados_SAP!$P$2:$P$10543=Painel!$E$5)>0)*((Painel!$H$5="(Todos)")+(Dados_SAP!$S$2:$S$10543=Painel!$H$5)>0))+SUMPRODUCT((Dados_SAP!$S$2:$S$10543="VAZIA")*((Painel!$B$5="(Todos)")+(Dados_SAP!$A$2:$A$10543=Painel!$B$5)>0)*((Painel!$E$5="(Todos)")+(Dados_SAP!$P$2:$P$10543=Painel!$E$5)>0)*((Painel!$H$5="(Todos)")+(Dados_SAP!$S$2:$S$10543=Painel!$H$5)>0))),0) -> 0.83115158 | K9: 396
A11: PONTOS DE ATENÇÃO (conforme filtro de Tipo de Depósito e Centro)
A12: Categoria | C12: O que significa | H12: Qtd. Posições | J12: Peso (kg) | L12: % do KG filtrado | M12: Status
A13: VENCIDO | C13: Material já venceu | H13: =SUMPRODUCT((Dados_SAP!$S$2:$S$10543="VENCIDO")*((Painel!$B$5="(Todos)")+(Dados_SAP!$A$2:$A$10543=Painel!$B$5)>0)*((Painel!$E$5="(Todos)")+(Dados_SAP!$P$2:$P$10543=Painel!$E$5)>0)) -> 503 | J13: =SUMPRODUCT((Dados_SAP!$S$2:$S$10543="VENCIDO")*(Dados_SAP!$K$2:$K$10543="KG")*((Painel!$B$5="(Todos)")+(Dados_SAP!$A$2:$A$10543=Painel!$B$5)>0)*((Painel!$E$5="(Todos)")+(Dados_SAP!$P$2:$P$10543=Painel!$E$5)>0),Dados_SAP!$J$2:$J$10543) -> 51364.234 | L13: =IFERROR(SUMPRODUCT((Dados_SAP!$S$2:$S$10543="VENCIDO")*(Dados_SAP!$K$2:$K$10543="KG")*((Painel!$B$5="(Todos)")+(Dados_SAP!$A$2:$A$10543=Painel!$B$5)>0)*((Painel!$E$5="(Todos)")+(Dados_SAP!$P$2:$P$10543=Painel!$E$5)>0),Dados_SAP!$J$2:$J$10543)/SUMPRODUCT((Dados_SAP!$K$2:$K$10543="KG")*((Painel!$B$5="(Todos)")+(Dados_SAP!$A$2:$A$10543=Painel!$B$5)>0)*((Painel!$E$5="(Todos)")+(Dados_SAP!$P$2:$P$10543=Painel!$E$5)>0),Dados_SAP!$J$2:$J$10543),0) -> 0.011058631 | M13: =IF(H13>0,"🔴 ALERTA","✅ OK") -> 🔴 ALERTA
A14: PRÓX. VENCIMENTO | C14: Vence em breve | H14: =SUMPRODUCT((Dados_SAP!$S$2:$S$10543="PRÓX. VENCIMENTO")*((Painel!$B$5="(Todos)")+(Dados_SAP!$A$2:$A$10543=Painel!$B$5)>0)*((Painel!$E$5="(Todos)")+(Dados_SAP!$P$2:$P$10543=Painel!$E$5)>0)) -> 405 | J14: =SUMPRODUCT((Dados_SAP!$S$2:$S$10543="PRÓX. VENCIMENTO")*(Dados_SAP!$K$2:$K$10543="KG")*((Painel!$B$5="(Todos)")+(Dados_SAP!$A$2:$A$10543=Painel!$B$5)>0)*((Painel!$E$5="(Todos)")+(Dados_SAP!$P$2:$P$10543=Painel!$E$5)>0),Dados_SAP!$J$2:$J$10543) -> 88737.899 | L14: =IFERROR(SUMPRODUCT((Dados_SAP!$S$2:$S$10543="PRÓX. VENCIMENTO")*(Dados_SAP!$K$2:$K$10543="KG")*((Painel!$B$5="(Todos)")+(Dados_SAP!$A$2:$A$10543=Painel!$B$5)>0)*((Painel!$E$5="(Todos)")+(Dados_SAP!$P$2:$P$10543=Painel!$E$5)>0),Dados_SAP!$J$2:$J$10543)/SUMPRODUCT((Dados_SAP!$K$2:$K$10543="KG")*((Painel!$B$5="(Todos)")+(Dados_SAP!$A$2:$A$10543=Painel!$B$5)>0)*((Painel!$E$5="(Todos)")+(Dados_SAP!$P$2:$P$10543=Painel!$E$5)>0),Dados_SAP!$J$2:$J$10543),0) -> 0.019105117 | M14: =IF(H14>0,"🟡 ATENÇÃO","✅ OK") -> 🟡 ATENÇÃO
A15: QUALIDADE | C15: Em inspeção de qualidade | H15: =SUMPRODUCT((Dados_SAP!$S$2:$S$10543="QUALIDADE")*((Painel!$B$5="(Todos)")+(Dados_SAP!$A$2:$A$10543=Painel!$B$5)>0)*((Painel!$E$5="(Todos)")+(Dados_SAP!$P$2:$P$10543=Painel!$E$5)>0)) -> 1063 | J15: =SUMPRODUCT((Dados_SAP!$S$2:$S$10543="QUALIDADE")*(Dados_SAP!$K$2:$K$10543="KG")*((Painel!$B$5="(Todos)")+(Dados_SAP!$A$2:$A$10543=Painel!$B$5)>0)*((Painel!$E$5="(Todos)")+(Dados_SAP!$P$2:$P$10543=Painel!$E$5)>0),Dados_SAP!$J$2:$J$10543) -> 662047.19 | L15: =IFERROR(SUMPRODUCT((Dados_SAP!$S$2:$S$10543="QUALIDADE")*(Dados_SAP!$K$2:$K$10543="KG")*((Painel!$B$5="(Todos)")+(Dados_SAP!$A$2:$A$10543=Painel!$B$5)>0)*((Painel!$E$5="(Todos)")+(Dados_SAP!$P$2:$P$10543=Painel!$E$5)>0),Dados_SAP!$J$2:$J$10543)/SUMPRODUCT((Dados_SAP!$K$2:$K$10543="KG")*((Painel!$B$5="(Todos)")+(Dados_SAP!$A$2:$A$10543=Painel!$B$5)>0)*((Painel!$E$5="(Todos)")+(Dados_SAP!$P$2:$P$10543=Painel!$E$5)>0),Dados_SAP!$J$2:$J$10543),0) -> 0.14253763 | M15: =IF(H15>0,"🔴 ALERTA","✅ OK") -> 🔴 ALERTA
A16: BLOQUEADO | C16: Bloqueado para uso | H16: =SUMPRODUCT((Dados_SAP!$S$2:$S$10543="BLOQUEADO")*((Painel!$B$5="(Todos)")+(Dados_SAP!$A$2:$A$10543=Painel!$B$5)>0)*((Painel!$E$5="(Todos)")+(Dados_SAP!$P$2:$P$10543=Painel!$E$5)>0)) -> 593 | J16: =SUMPRODUCT((Dados_SAP!$S$2:$S$10543="BLOQUEADO")*(Dados_SAP!$K$2:$K$10543="KG")*((Painel!$B$5="(Todos)")+(Dados_SAP!$A$2:$A$10543=Painel!$B$5)>0)*((Painel!$E$5="(Todos)")+(Dados_SAP!$P$2:$P$10543=Painel!$E$5)>0),Dados_SAP!$J$2:$J$10543) -> 171647.12 | L16: =IFERROR(SUMPRODUCT((Dados_SAP!$S$2:$S$10543="BLOQUEADO")*(Dados_SAP!$K$2:$K$10543="KG")*((Painel!$B$5="(Todos)")+(Dados_SAP!$A$2:$A$10543=Painel!$B$5)>0)*((Painel!$E$5="(Todos)")+(Dados_SAP!$P$2:$P$10543=Painel!$E$5)>0),Dados_SAP!$J$2:$J$10543)/SUMPRODUCT((Dados_SAP!$K$2:$K$10543="KG")*((Painel!$B$5="(Todos)")+(Dados_SAP!$A$2:$A$10543=Painel!$B$5)>0)*((Painel!$E$5="(Todos)")+(Dados_SAP!$P$2:$P$10543=Painel!$E$5)>0),Dados_SAP!$J$2:$J$10543),0) -> 0.03695533 | M16: =IF(H16>0,"🔴 ALERTA","✅ OK") -> 🔴 ALERTA
A17: RESTRITO/DEVOLUÇÃO | C17: Estoque restrito/devolução | H17: =SUMPRODUCT((Dados_SAP!$S$2:$S$10543="RESTRITO/DEVOLUÇÃO")*((Painel!$B$5="(Todos)")+(Dados_SAP!$A$2:$A$10543=Painel!$B$5)>0)*((Painel!$E$5="(Todos)")+(Dados_SAP!$P$2:$P$10543=Painel!$E$5)>0)) -> 615 | J17: =SUMPRODUCT((Dados_SAP!$S$2:$S$10543="RESTRITO/DEVOLUÇÃO")*(Dados_SAP!$K$2:$K$10543="KG")*((Painel!$B$5="(Todos)")+(Dados_SAP!$A$2:$A$10543=Painel!$B$5)>0)*((Painel!$E$5="(Todos)")+(Dados_SAP!$P$2:$P$10543=Painel!$E$5)>0),Dados_SAP!$J$2:$J$10543) -> 98943.09 | L17: =IFERROR(SUMPRODUCT((Dados_SAP!$S$2:$S$10543="RESTRITO/DEVOLUÇÃO")*(Dados_SAP!$K$2:$K$10543="KG")*((Painel!$B$5="(Todos)")+(Dados_SAP!$A$2:$A$10543=Painel!$B$5)>0)*((Painel!$E$5="(Todos)")+(Dados_SAP!$P$2:$P$10543=Painel!$E$5)>0),Dados_SAP!$J$2:$J$10543)/SUMPRODUCT((Dados_SAP!$K$2:$K$10543="KG")*((Painel!$B$5="(Todos)")+(Dados_SAP!$A$2:$A$10543=Painel!$B$5)>0)*((Painel!$E$5="(Todos)")+(Dados_SAP!$P$2:$P$10543=Painel!$E$5)>0),Dados_SAP!$J$2:$J$10543),0) -> 0.021302278 | M17: =IF(H17>0,"🔴 ALERTA","✅ OK") -> 🔴 ALERTA
A18: QUARENTENA | C18: Em quarentena | H18: =SUMPRODUCT((Dados_SAP!$S$2:$S$10543="QUARENTENA")*((Painel!$B$5="(Todos)")+(Dados_SAP!$A$2:$A$10543=Painel!$B$5)>0)*((Painel!$E$5="(Todos)")+(Dados_SAP!$P$2:$P$10543=Painel!$E$5)>0)) -> 94 | J18: =SUMPRODUCT((Dados_SAP!$S$2:$S$10543="QUARENTENA")*(Dados_SAP!$K$2:$K$10543="KG")*((Painel!$B$5="(Todos)")+(Dados_SAP!$A$2:$A$10543=Painel!$B$5)>0)*((Painel!$E$5="(Todos)")+(Dados_SAP!$P$2:$P$10543=Painel!$E$5)>0),Dados_SAP!$J$2:$J$10543) -> 14100 | L18: =IFERROR(SUMPRODUCT((Dados_SAP!$S$2:$S$10543="QUARENTENA")*(Dados_SAP!$K$2:$K$10543="KG")*((Painel!$B$5="(Todos)")+(Dados_SAP!$A$2:$A$10543=Painel!$B$5)>0)*((Painel!$E$5="(Todos)")+(Dados_SAP!$P$2:$P$10543=Painel!$E$5)>0),Dados_SAP!$J$2:$J$10543)/SUMPRODUCT((Dados_SAP!$K$2:$K$10543="KG")*((Painel!$B$5="(Todos)")+(Dados_SAP!$A$2:$A$10543=Painel!$B$5)>0)*((Painel!$E$5="(Todos)")+(Dados_SAP!$P$2:$P$10543=Painel!$E$5)>0),Dados_SAP!$J$2:$J$10543),0) -> 0.0030357058 | M18: =IF(H18>0,"🔴 ALERTA","✅ OK") -> 🔴 ALERTA
A19: DESCARTE/DEVOLUÇÃO | C19: Em posição de descarte/devolução | H19: =SUMPRODUCT((Dados_SAP!$S$2:$S$10543="DESCARTE/DEVOLUÇÃO")*((Painel!$B$5="(Todos)")+(Dados_SAP!$A$2:$A$10543=Painel!$B$5)>0)*((Painel!$E$5="(Todos)")+(Dados_SAP!$P$2:$P$10543=Painel!$E$5)>0)) -> 19 | J19: =SUMPRODUCT((Dados_SAP!$S$2:$S$10543="DESCARTE/DEVOLUÇÃO")*(Dados_SAP!$K$2:$K$10543="KG")*((Painel!$B$5="(Todos)")+(Dados_SAP!$A$2:$A$10543=Painel!$B$5)>0)*((Painel!$E$5="(Todos)")+(Dados_SAP!$P$2:$P$10543=Painel!$E$5)>0),Dados_SAP!$J$2:$J$10543) -> 1996.5 | L19: =IFERROR(SUMPRODUCT((Dados_SAP!$S$2:$S$10543="DESCARTE/DEVOLUÇÃO")*(Dados_SAP!$K$2:$K$10543="KG")*((Painel!$B$5="(Todos)")+(Dados_SAP!$A$2:$A$10543=Painel!$B$5)>0)*((Painel!$E$5="(Todos)")+(Dados_SAP!$P$2:$P$10543=Painel!$E$5)>0),Dados_SAP!$J$2:$J$10543)/SUMPRODUCT((Dados_SAP!$K$2:$K$10543="KG")*((Painel!$B$5="(Todos)")+(Dados_SAP!$A$2:$A$10543=Painel!$B$5)>0)*((Painel!$E$5="(Todos)")+(Dados_SAP!$P$2:$P$10543=Painel!$E$5)>0),Dados_SAP!$J$2:$J$10543),0) -> 0.00042984303 | M19: =IF(H19>0,"🔴 ALERTA","✅ OK") -> 🔴 ALERTA
A20: SEM LOTE | C20: Sem lote (falta de rastreabilidade) | H20: =SUMPRODUCT((Dados_SAP!$S$2:$S$10543="SEM LOTE")*((Painel!$B$5="(Todos)")+(Dados_SAP!$A$2:$A$10543=Painel!$B$5)>0)*((Painel!$E$5="(Todos)")+(Dados_SAP!$P$2:$P$10543=Painel!$E$5)>0)) -> 232 | J20: =SUMPRODUCT((Dados_SAP!$S$2:$S$10543="SEM LOTE")*(Dados_SAP!$K$2:$K$10543="KG")*((Painel!$B$5="(Todos)")+(Dados_SAP!$A$2:$A$10543=Painel!$B$5)>0)*((Painel!$E$5="(Todos)")+(Dados_SAP!$P$2:$P$10543=Painel!$E$5)>0),Dados_SAP!$J$2:$J$10543) -> 2347.7 | L20: =IFERROR(SUMPRODUCT((Dados_SAP!$S$2:$S$10543="SEM LOTE")*(Dados_SAP!$K$2:$K$10543="KG")*((Painel!$B$5="(Todos)")+(Dados_SAP!$A$2:$A$10543=Painel!$B$5)>0)*((Painel!$E$5="(Todos)")+(Dados_SAP!$P$2:$P$10543=Painel!$E$5)>0),Dados_SAP!$J$2:$J$10543)/SUMPRODUCT((Dados_SAP!$K$2:$K$10543="KG")*((Painel!$B$5="(Todos)")+(Dados_SAP!$A$2:$A$10543=Painel!$B$5)>0)*((Painel!$E$5="(Todos)")+(Dados_SAP!$P$2:$P$10543=Painel!$E$5)>0),Dados_SAP!$J$2:$J$10543),0) -> 0.00050545578 | M20: =IF(H20>0,"🔴 ALERTA","✅ OK") -> 🔴 ALERTA
A21: PARADO/SEM GIRO | C21: Sem movimento há muito tempo | H21: =SUMPRODUCT((Dados_SAP!$S$2:$S$10543="PARADO/SEM GIRO")*((Painel!$B$5="(Todos)")+(Dados_SAP!$A$2:$A$10543=Painel!$B$5)>0)*((Painel!$E$5="(Todos)")+(Dados_SAP!$P$2:$P$10543=Painel!$E$5)>0)) -> 602 | J21: =SUMPRODUCT((Dados_SAP!$S$2:$S$10543="PARADO/SEM GIRO")*(Dados_SAP!$K$2:$K$10543="KG")*((Painel!$B$5="(Todos)")+(Dados_SAP!$A$2:$A$10543=Painel!$B$5)>0)*((Painel!$E$5="(Todos)")+(Dados_SAP!$P$2:$P$10543=Painel!$E$5)>0),Dados_SAP!$J$2:$J$10543) -> 351142.17 | L21: =IFERROR(SUMPRODUCT((Dados_SAP!$S$2:$S$10543="PARADO/SEM GIRO")*(Dados_SAP!$K$2:$K$10543="KG")*((Painel!$B$5="(Todos)")+(Dados_SAP!$A$2:$A$10543=Painel!$B$5)>0)*((Painel!$E$5="(Todos)")+(Dados_SAP!$P$2:$P$10543=Painel!$E$5)>0),Dados_SAP!$J$2:$J$10543)/SUMPRODUCT((Dados_SAP!$K$2:$K$10543="KG")*((Painel!$B$5="(Todos)")+(Dados_SAP!$A$2:$A$10543=Painel!$B$5)>0)*((Painel!$E$5="(Todos)")+(Dados_SAP!$P$2:$P$10543=Painel!$E$5)>0),Dados_SAP!$J$2:$J$10543),0) -> 0.075600307 | M21: =IF(H21>0,"🔴 ALERTA","✅ OK") -> 🔴 ALERTA
A23: Estoque (kg) por Tipo de Depósito
A61: TOP 10 — MAIOR ESTOQUE PARADO/SEM GIRO (kg) | H61: TOP 10 — MAIOR ESTOQUE VENCIDO (kg)
A62: Material | B62: Lote | C62: Posição | D62: Tipo Dep. | E62: kg | F62: Dias parado | H62: Material | I62: Lote | J62: Posição | K62: Tipo Dep. | L62: kg | M62: Dias vencido
A63: =IF(E63="","",INDEX(Dados_SAP!$C$2:$C$10543,MATCH(E63,Dados_SAP!$T$2:$T$10543,0))) -> RW000 | B63: =IF(E63="","",INDEX(Dados_SAP!$D$2:$D$10543,MATCH(E63,Dados_SAP!$T$2:$T$10543,0))) -> A26041-202 | C63: =IF(E63="","",INDEX(Dados_SAP!$B$2:$B$10543,MATCH(E63,Dados_SAP!$T$2:$T$10543,0))) -> 06-91-C | D63: =IF(E63="","",INDEX(Dados_SAP!$A$2:$A$10543,MATCH(E63,Dados_SAP!$T$2:$T$10543,0))) -> FGF | E63: =IFERROR(LARGE(Dados_SAP!$T$2:$T$10543,1),"") -> 1105.0002 | F63: =IF(E63="","",INDEX(Dados_SAP!$Q$2:$Q$10543,MATCH(E63,Dados_SAP!$T$2:$T$10543,0))) -> 213 | H63: =IF(L63="","",INDEX(Dados_SAP!$C$2:$C$10543,MATCH(L63,Dados_SAP!$U$2:$U$10543,0))) -> CHD-VR-7170405-A99 | I63: =IF(L63="","",INDEX(Dados_SAP!$D$2:$D$10543,MATCH(L63,Dados_SAP!$U$2:$U$10543,0))) -> 523115-01 | J63: =IF(L63="","",INDEX(Dados_SAP!$B$2:$B$10543,MATCH(L63,Dados_SAP!$U$2:$U$10543,0))) -> 01-PISO-A | K63: =IF(L63="","",INDEX(Dados_SAP!$A$2:$A$10543,MATCH(L63,Dados_SAP!$U$2:$U$10543,0))) -> PK1 | L63: =IFERROR(LARGE(Dados_SAP!$U$2:$U$10543,1),"") -> 3730.0008 | M63: =IF(L63="","",-INDEX(Dados_SAP!$R$2:$R$10543,MATCH(L63,Dados_SAP!$U$2:$U$10543,0))) -> 513
A64: =IF(E64="","",INDEX(Dados_SAP!$C$2:$C$10543,MATCH(E64,Dados_SAP!$T$2:$T$10543,0))) -> ILM-BL-0011021-A12 | B64: =IF(E64="","",INDEX(Dados_SAP!$D$2:$D$10543,MATCH(E64,Dados_SAP!$T$2:$T$10543,0))) -> A26158-01 | C64: =IF(E64="","",INDEX(Dados_SAP!$B$2:$B$10543,MATCH(E64,Dados_SAP!$T$2:$T$10543,0))) -> 15-117-D | D64: =IF(E64="","",INDEX(Dados_SAP!$A$2:$A$10543,MATCH(E64,Dados_SAP!$T$2:$T$10543,0))) -> FM1 | E64: =IFERROR(LARGE(Dados_SAP!$T$2:$T$10543,2),"") -> 1102.5008 | F64: =IF(E64="","",INDEX(Dados_SAP!$Q$2:$Q$10543,MATCH(E64,Dados_SAP!$T$2:$T$10543,0))) -> 94 | H64: =IF(L64="","",INDEX(Dados_SAP!$C$2:$C$10543,MATCH(L64,Dados_SAP!$U$2:$U$10543,0))) -> CRW-EZ-2002516-009 | I64: =IF(L64="","",INDEX(Dados_SAP!$D$2:$D$10543,MATCH(L64,Dados_SAP!$U$2:$U$10543,0))) -> A25205B11 | J64: =IF(L64="","",INDEX(Dados_SAP!$B$2:$B$10543,MATCH(L64,Dados_SAP!$U$2:$U$10543,0))) -> ALTAOMX | K64: =IF(L64="","",INDEX(Dados_SAP!$A$2:$A$10543,MATCH(L64,Dados_SAP!$U$2:$U$10543,0))) -> PK1 | L64: =IFERROR(LARGE(Dados_SAP!$U$2:$U$10543,2),"") -> 3200.0009 | M64: =IF(L64="","",-INDEX(Dados_SAP!$R$2:$R$10543,MATCH(L64,Dados_SAP!$U$2:$U$10543,0))) -> 58
A65: =IF(E65="","",INDEX(Dados_SAP!$C$2:$C$10543,MATCH(E65,Dados_SAP!$T$2:$T$10543,0))) -> ILM-BL-0011021-A12 | B65: =IF(E65="","",INDEX(Dados_SAP!$D$2:$D$10543,MATCH(E65,Dados_SAP!$T$2:$T$10543,0))) -> A26159-01 | C65: =IF(E65="","",INDEX(Dados_SAP!$B$2:$B$10543,MATCH(E65,Dados_SAP!$T$2:$T$10543,0))) -> 15-087-B | D65: =IF(E65="","",INDEX(Dados_SAP!$A$2:$A$10543,MATCH(E65,Dados_SAP!$T$2:$T$10543,0))) -> FM1 | E65: =IFERROR(LARGE(Dados_SAP!$T$2:$T$10543,3),"") -> 1102.5008 | F65: =IF(E65="","",INDEX(Dados_SAP!$Q$2:$Q$10543,MATCH(E65,Dados_SAP!$T$2:$T$10543,0))) -> 94 | H65: =IF(L65="","",INDEX(Dados_SAP!$C$2:$C$10543,MATCH(L65,Dados_SAP!$U$2:$U$10543,0))) -> CRM-DR-0001252-K15 | I65: =IF(L65="","",INDEX(Dados_SAP!$D$2:$D$10543,MATCH(L65,Dados_SAP!$U$2:$U$10543,0))) -> A24363B31 | J65: =IF(L65="","",INDEX(Dados_SAP!$B$2:$B$10543,MATCH(L65,Dados_SAP!$U$2:$U$10543,0))) -> DESCARTE | K65: =IF(L65="","",INDEX(Dados_SAP!$A$2:$A$10543,MATCH(L65,Dados_SAP!$U$2:$U$10543,0))) -> FLR | L65: =IFERROR(LARGE(Dados_SAP!$U$2:$U$10543,3),"") -> 1466.5203 | M65: =IF(L65="","",-INDEX(Dados_SAP!$R$2:$R$10543,MATCH(L65,Dados_SAP!$U$2:$U$10543,0))) -> 84
A66: =IF(E66="","",INDEX(Dados_SAP!$C$2:$C$10543,MATCH(E66,Dados_SAP!$T$2:$T$10543,0))) -> CRM-BL-0021380-A12 | B66: =IF(E66="","",INDEX(Dados_SAP!$D$2:$D$10543,MATCH(E66,Dados_SAP!$T$2:$T$10543,0))) -> A26035-21 | C66: =IF(E66="","",INDEX(Dados_SAP!$B$2:$B$10543,MATCH(E66,Dados_SAP!$T$2:$T$10543,0))) -> 15-004-B | D66: =IF(E66="","",INDEX(Dados_SAP!$A$2:$A$10543,MATCH(E66,Dados_SAP!$T$2:$T$10543,0))) -> FM1 | E66: =IFERROR(LARGE(Dados_SAP!$T$2:$T$10543,4),"") -> 1102.5007 | F66: =IF(E66="","",INDEX(Dados_SAP!$Q$2:$Q$10543,MATCH(E66,Dados_SAP!$T$2:$T$10543,0))) -> 102 | H66: =IF(L66="","",INDEX(Dados_SAP!$C$2:$C$10543,MATCH(L66,Dados_SAP!$U$2:$U$10543,0))) -> CRM-KB-0002618-E05 | I66: =IF(L66="","",INDEX(Dados_SAP!$D$2:$D$10543,MATCH(L66,Dados_SAP!$U$2:$U$10543,0))) -> A25042-01 | J66: =IF(L66="","",INDEX(Dados_SAP!$B$2:$B$10543,MATCH(L66,Dados_SAP!$U$2:$U$10543,0))) -> DEVOLUÇÃO | K66: =IF(L66="","",INDEX(Dados_SAP!$A$2:$A$10543,MATCH(L66,Dados_SAP!$U$2:$U$10543,0))) -> FLR | L66: =IFERROR(LARGE(Dados_SAP!$U$2:$U$10543,4),"") -> 1180.0003 | M66: =IF(L66="","",-INDEX(Dados_SAP!$R$2:$R$10543,MATCH(L66,Dados_SAP!$U$2:$U$10543,0))) -> 40
A67: =IF(E67="","",INDEX(Dados_SAP!$C$2:$C$10543,MATCH(E67,Dados_SAP!$T$2:$T$10543,0))) -> ILM-BL-0011021-A12 | B67: =IF(E67="","",INDEX(Dados_SAP!$D$2:$D$10543,MATCH(E67,Dados_SAP!$T$2:$T$10543,0))) -> A26157-01 | C67: =IF(E67="","",INDEX(Dados_SAP!$B$2:$B$10543,MATCH(E67,Dados_SAP!$T$2:$T$10543,0))) -> 15-002-C | D67: =IF(E67="","",INDEX(Dados_SAP!$A$2:$A$10543,MATCH(E67,Dados_SAP!$T$2:$T$10543,0))) -> FM1 | E67: =IFERROR(LARGE(Dados_SAP!$T$2:$T$10543,5),"") -> 1102.5007 | F67: =IF(E67="","",INDEX(Dados_SAP!$Q$2:$Q$10543,MATCH(E67,Dados_SAP!$T$2:$T$10543,0))) -> 100 | H67: =IF(L67="","",INDEX(Dados_SAP!$C$2:$C$10543,MATCH(L67,Dados_SAP!$U$2:$U$10543,0))) -> MALCHOC-W-123 | I67: =IF(L67="","",INDEX(Dados_SAP!$D$2:$D$10543,MATCH(L67,Dados_SAP!$U$2:$U$10543,0))) -> 252520402 | J67: =IF(L67="","",INDEX(Dados_SAP!$B$2:$B$10543,MATCH(L67,Dados_SAP!$U$2:$U$10543,0))) -> 06-29-D | K67: =IF(L67="","",INDEX(Dados_SAP!$A$2:$A$10543,MATCH(L67,Dados_SAP!$U$2:$U$10543,0))) -> FGF | L67: =IFERROR(LARGE(Dados_SAP!$U$2:$U$10543,5),"") -> 1000.0002 | M67: =IF(L67="","",-INDEX(Dados_SAP!$R$2:$R$10543,MATCH(L67,Dados_SAP!$U$2:$U$10543,0))) -> 11
A68: =IF(E68="","",INDEX(Dados_SAP!$C$2:$C$10543,MATCH(E68,Dados_SAP!$T$2:$T$10543,0))) -> CRM-BL-0021380-A12 | B68: =IF(E68="","",INDEX(Dados_SAP!$D$2:$D$10543,MATCH(E68,Dados_SAP!$T$2:$T$10543,0))) -> A26035-21 | C68: =IF(E68="","",INDEX(Dados_SAP!$B$2:$B$10543,MATCH(E68,Dados_SAP!$T$2:$T$10543,0))) -> 14-116-E | D68: =IF(E68="","",INDEX(Dados_SAP!$A$2:$A$10543,MATCH(E68,Dados_SAP!$T$2:$T$10543,0))) -> FM1 | E68: =IFERROR(LARGE(Dados_SAP!$T$2:$T$10543,6),"") -> 1102.5007 | F68: =IF(E68="","",INDEX(Dados_SAP!$Q$2:$Q$10543,MATCH(E68,Dados_SAP!$T$2:$T$10543,0))) -> 102 | H68: =IF(L68="","",INDEX(Dados_SAP!$C$2:$C$10543,MATCH(L68,Dados_SAP!$U$2:$U$10543,0))) -> ILM-KB-0021060-A17 | I68: =IF(L68="","",INDEX(Dados_SAP!$D$2:$D$10543,MATCH(L68,Dados_SAP!$U$2:$U$10543,0))) -> A25065-01 | J68: =IF(L68="","",INDEX(Dados_SAP!$B$2:$B$10543,MATCH(L68,Dados_SAP!$U$2:$U$10543,0))) -> 15-014-D | K68: =IF(L68="","",INDEX(Dados_SAP!$A$2:$A$10543,MATCH(L68,Dados_SAP!$U$2:$U$10543,0))) -> FM1 | L68: =IFERROR(LARGE(Dados_SAP!$U$2:$U$10543,6),"") -> 800.00074 | M68: =IF(L68="","",-INDEX(Dados_SAP!$R$2:$R$10543,MATCH(L68,Dados_SAP!$U$2:$U$10543,0))) -> 14
A69: =IF(E69="","",INDEX(Dados_SAP!$C$2:$C$10543,MATCH(E69,Dados_SAP!$T$2:$T$10543,0))) -> CRM-BL-0021380-A12 | B69: =IF(E69="","",INDEX(Dados_SAP!$D$2:$D$10543,MATCH(E69,Dados_SAP!$T$2:$T$10543,0))) -> A26035-21 | C69: =IF(E69="","",INDEX(Dados_SAP!$B$2:$B$10543,MATCH(E69,Dados_SAP!$T$2:$T$10543,0))) -> 14-116-D | D69: =IF(E69="","",INDEX(Dados_SAP!$A$2:$A$10543,MATCH(E69,Dados_SAP!$T$2:$T$10543,0))) -> FM1 | E69: =IFERROR(LARGE(Dados_SAP!$T$2:$T$10543,7),"") -> 1102.5007 | F69: =IF(E69="","",INDEX(Dados_SAP!$Q$2:$Q$10543,MATCH(E69,Dados_SAP!$T$2:$T$10543,0))) -> 102 | H69: =IF(L69="","",INDEX(Dados_SAP!$C$2:$C$10543,MATCH(L69,Dados_SAP!$U$2:$U$10543,0))) -> ILM-KB-0021060-A17 | I69: =IF(L69="","",INDEX(Dados_SAP!$D$2:$D$10543,MATCH(L69,Dados_SAP!$U$2:$U$10543,0))) -> A25065-01 | J69: =IF(L69="","",INDEX(Dados_SAP!$B$2:$B$10543,MATCH(L69,Dados_SAP!$U$2:$U$10543,0))) -> 14-00X-E | K69: =IF(L69="","",INDEX(Dados_SAP!$A$2:$A$10543,MATCH(L69,Dados_SAP!$U$2:$U$10543,0))) -> FM1 | L69: =IFERROR(LARGE(Dados_SAP!$U$2:$U$10543,7),"") -> 800.00066 | M69: =IF(L69="","",-INDEX(Dados_SAP!$R$2:$R$10543,MATCH(L69,Dados_SAP!$U$2:$U$10543,0))) -> 14
A70: =IF(E70="","",INDEX(Dados_SAP!$C$2:$C$10543,MATCH(E70,Dados_SAP!$T$2:$T$10543,0))) -> CRM-BL-0021380-A12 | B70: =IF(E70="","",INDEX(Dados_SAP!$D$2:$D$10543,MATCH(E70,Dados_SAP!$T$2:$T$10543,0))) -> A26035-21 | C70: =IF(E70="","",INDEX(Dados_SAP!$B$2:$B$10543,MATCH(E70,Dados_SAP!$T$2:$T$10543,0))) -> 14-114-F | D70: =IF(E70="","",INDEX(Dados_SAP!$A$2:$A$10543,MATCH(E70,Dados_SAP!$T$2:$T$10543,0))) -> FM1 | E70: =IFERROR(LARGE(Dados_SAP!$T$2:$T$10543,8),"") -> 1102.5007 | F70: =IF(E70="","",INDEX(Dados_SAP!$Q$2:$Q$10543,MATCH(E70,Dados_SAP!$T$2:$T$10543,0))) -> 102 | H70: =IF(L70="","",INDEX(Dados_SAP!$C$2:$C$10543,MATCH(L70,Dados_SAP!$U$2:$U$10543,0))) -> ILM-KB-0021060-A17 | I70: =IF(L70="","",INDEX(Dados_SAP!$D$2:$D$10543,MATCH(L70,Dados_SAP!$U$2:$U$10543,0))) -> A25065-01 | J70: =IF(L70="","",INDEX(Dados_SAP!$B$2:$B$10543,MATCH(L70,Dados_SAP!$U$2:$U$10543,0))) -> 14-00X-B | K70: =IF(L70="","",INDEX(Dados_SAP!$A$2:$A$10543,MATCH(L70,Dados_SAP!$U$2:$U$10543,0))) -> FM1 | L70: =IFERROR(LARGE(Dados_SAP!$U$2:$U$10543,8),"") -> 800.00066 | M70: =IF(L70="","",-INDEX(Dados_SAP!$R$2:$R$10543,MATCH(L70,Dados_SAP!$U$2:$U$10543,0))) -> 14
A71: =IF(E71="","",INDEX(Dados_SAP!$C$2:$C$10543,MATCH(E71,Dados_SAP!$T$2:$T$10543,0))) -> ILM-BL-0011021-A12 | B71: =IF(E71="","",INDEX(Dados_SAP!$D$2:$D$10543,MATCH(E71,Dados_SAP!$T$2:$T$10543,0))) -> A26157-01 | C71: =IF(E71="","",INDEX(Dados_SAP!$B$2:$B$10543,MATCH(E71,Dados_SAP!$T$2:$T$10543,0))) -> 14-111-E | D71: =IF(E71="","",INDEX(Dados_SAP!$A$2:$A$10543,MATCH(E71,Dados_SAP!$T$2:$T$10543,0))) -> FM1 | E71: =IFERROR(LARGE(Dados_SAP!$T$2:$T$10543,9),"") -> 1102.5007 | F71: =IF(E71="","",INDEX(Dados_SAP!$Q$2:$Q$10543,MATCH(E71,Dados_SAP!$T$2:$T$10543,0))) -> 100 | H71: =IF(L71="","",INDEX(Dados_SAP!$C$2:$C$10543,MATCH(L71,Dados_SAP!$U$2:$U$10543,0))) -> CRM-KB-0018900-A17 | I71: =IF(L71="","",INDEX(Dados_SAP!$D$2:$D$10543,MATCH(L71,Dados_SAP!$U$2:$U$10543,0))) -> A25001-01 | J71: =IF(L71="","",INDEX(Dados_SAP!$B$2:$B$10543,MATCH(L71,Dados_SAP!$U$2:$U$10543,0))) -> DESCARTE | K71: =IF(L71="","",INDEX(Dados_SAP!$A$2:$A$10543,MATCH(L71,Dados_SAP!$U$2:$U$10543,0))) -> FLR | L71: =IFERROR(LARGE(Dados_SAP!$U$2:$U$10543,9),"") -> 800.0003 | M71: =IF(L71="","",-INDEX(Dados_SAP!$R$2:$R$10543,MATCH(L71,Dados_SAP!$U$2:$U$10543,0))) -> 81
A72: =IF(E72="","",INDEX(Dados_SAP!$C$2:$C$10543,MATCH(E72,Dados_SAP!$T$2:$T$10543,0))) -> ILM-BL-0011021-A12 | B72: =IF(E72="","",INDEX(Dados_SAP!$D$2:$D$10543,MATCH(E72,Dados_SAP!$T$2:$T$10543,0))) -> A26157-01 | C72: =IF(E72="","",INDEX(Dados_SAP!$B$2:$B$10543,MATCH(E72,Dados_SAP!$T$2:$T$10543,0))) -> 14-101-C | D72: =IF(E72="","",INDEX(Dados_SAP!$A$2:$A$10543,MATCH(E72,Dados_SAP!$T$2:$T$10543,0))) -> FM1 | E72: =IFERROR(LARGE(Dados_SAP!$T$2:$T$10543,10),"") -> 1102.5007 | F72: =IF(E72="","",INDEX(Dados_SAP!$Q$2:$Q$10543,MATCH(E72,Dados_SAP!$T$2:$T$10543,0))) -> 100 | H72: =IF(L72="","",INDEX(Dados_SAP!$C$2:$C$10543,MATCH(L72,Dados_SAP!$U$2:$U$10543,0))) -> ILD-KB-7011022-A17 | I72: =IF(L72="","",INDEX(Dados_SAP!$D$2:$D$10543,MATCH(L72,Dados_SAP!$U$2:$U$10543,0))) -> A25011-02 | J72: =IF(L72="","",INDEX(Dados_SAP!$B$2:$B$10543,MATCH(L72,Dados_SAP!$U$2:$U$10543,0))) -> ALTAOMX | K72: =IF(L72="","",INDEX(Dados_SAP!$A$2:$A$10543,MATCH(L72,Dados_SAP!$U$2:$U$10543,0))) -> PK1 | L72: =IFERROR(LARGE(Dados_SAP!$U$2:$U$10543,10),"") -> 740.00088 | M72: =IF(L72="","",-INDEX(Dados_SAP!$R$2:$R$10543,MATCH(L72,Dados_SAP!$U$2:$U$10543,0))) -> 71
A77: Dados de apoio aos gráficos abaixo — não precisa editar; fora da área de impressão.
A78: Tipo de Depósito | B78: KG (filtrado)
A79: FM1 | B79: =SUMPRODUCT((Dados_SAP!$K$2:$K$10543="KG")*(Dados_SAP!$A$2:$A$10543="FM1")*((Painel!$B$5="(Todos)")+(Dados_SAP!$A$2:$A$10543=Painel!$B$5)>0)*((Painel!$E$5="(Todos)")+(Dados_SAP!$P$2:$P$10543=Painel!$E$5)>0)*((Painel!$H$5="(Todos)")+(Dados_SAP!$S$2:$S$10543=Painel!$H$5)>0),Dados_SAP!$J$2:$J$10543) -> 2280304.9
A80: FGF | B80: =SUMPRODUCT((Dados_SAP!$K$2:$K$10543="KG")*(Dados_SAP!$A$2:$A$10543="FGF")*((Painel!$B$5="(Todos)")+(Dados_SAP!$A$2:$A$10543=Painel!$B$5)>0)*((Painel!$E$5="(Todos)")+(Dados_SAP!$P$2:$P$10543=Painel!$E$5)>0)*((Painel!$H$5="(Todos)")+(Dados_SAP!$S$2:$S$10543=Painel!$H$5)>0),Dados_SAP!$J$2:$J$10543) -> 1227036.3
A81: PR2 | B81: =SUMPRODUCT((Dados_SAP!$K$2:$K$10543="KG")*(Dados_SAP!$A$2:$A$10543="PR2")*((Painel!$B$5="(Todos)")+(Dados_SAP!$A$2:$A$10543=Painel!$B$5)>0)*((Painel!$E$5="(Todos)")+(Dados_SAP!$P$2:$P$10543=Painel!$E$5)>0)*((Painel!$H$5="(Todos)")+(Dados_SAP!$S$2:$S$10543=Painel!$H$5)>0),Dados_SAP!$J$2:$J$10543) -> 305189.57
A82: FLR | B82: =SUMPRODUCT((Dados_SAP!$K$2:$K$10543="KG")*(Dados_SAP!$A$2:$A$10543="FLR")*((Painel!$B$5="(Todos)")+(Dados_SAP!$A$2:$A$10543=Painel!$B$5)>0)*((Painel!$E$5="(Todos)")+(Dados_SAP!$P$2:$P$10543=Painel!$E$5)>0)*((Painel!$H$5="(Todos)")+(Dados_SAP!$S$2:$S$10543=Painel!$H$5)>0),Dados_SAP!$J$2:$J$10543) -> 259748
A83: RM1 | B83: =SUMPRODUCT((Dados_SAP!$K$2:$K$10543="KG")*(Dados_SAP!$A$2:$A$10543="RM1")*((Painel!$B$5="(Todos)")+(Dados_SAP!$A$2:$A$10543=Painel!$B$5)>0)*((Painel!$E$5="(Todos)")+(Dados_SAP!$P$2:$P$10543=Painel!$E$5)>0)*((Painel!$H$5="(Todos)")+(Dados_SAP!$S$2:$S$10543=Painel!$H$5)>0),Dados_SAP!$J$2:$J$10543) -> 246870
A84: PK1 | B84: =SUMPRODUCT((Dados_SAP!$K$2:$K$10543="KG")*(Dados_SAP!$A$2:$A$10543="PK1")*((Painel!$B$5="(Todos)")+(Dados_SAP!$A$2:$A$10543=Painel!$B$5)>0)*((Painel!$E$5="(Todos)")+(Dados_SAP!$P$2:$P$10543=Painel!$E$5)>0)*((Painel!$H$5="(Todos)")+(Dados_SAP!$S$2:$S$10543=Painel!$H$5)>0),Dados_SAP!$J$2:$J$10543) -> 163428.1
...

Sheet Pontos_de_Atencao
A1: Pontos que Carecem de Monitoramento — Estoque LX03
A2: Lista consolidada, sem filtro (todo o armazém), pensada para leitura de diretoria. Atualiza sozinha a cada nova carga do SAP — nada aqui precisa ser preenchido à mão.
A4: Nº | B4: Ponto de Atenção | C4: O que significa | D4: Qtd. Posições | E4: Peso (kg) | F4: % do KG total | G4: Severidade | H4: Ação Recomendada
A5: 1 | B5: VENCIDO | C5: Material já venceu | D5: =COUNTIFS(Dados_SAP!$S$2:$S$10543,"VENCIDO") -> 503 | E5: =SUMIFS(Dados_SAP!$J$2:$J$10543,Dados_SAP!$S$2:$S$10543,"VENCIDO",Dados_SAP!$K$2:$K$10543,"KG") -> 51364.234 | F5: =IFERROR(E5/(SUMIFS(Dados_SAP!$J$2:$J$10543,Dados_SAP!$K$2:$K$10543,"KG")),0) -> 0.011058631 | G5: =IF(D5=0,"✅ OK","🔴 CRÍTICO") -> 🔴 CRÍTICO | H5: Separar fisicamente, abrir processo de baixa/descarte e investigar a causa raiz (previsão de consumo x validade).
A6: 2 | B6: PRÓX. VENCIMENTO | C6: Vence em breve | D6: =COUNTIFS(Dados_SAP!$S$2:$S$10543,"PRÓX. VENCIMENTO") -> 405 | E6: =SUMIFS(Dados_SAP!$J$2:$J$10543,Dados_SAP!$S$2:$S$10543,"PRÓX. VENCIMENTO",Dados_SAP!$K$2:$K$10543,"KG") -> 88737.899 | F6: =IFERROR(E6/(SUMIFS(Dados_SAP!$J$2:$J$10543,Dados_SAP!$K$2:$K$10543,"KG")),0) -> 0.019105117 | G6: =IF(D6=0,"✅ OK","🟠 ATENÇÃO") -> 🟠 ATENÇÃO | H6: Priorizar consumo/expedição por ordem de vencimento (FEFO) ou negociar saída antes do vencimento.
A7: 3 | B7: QUALIDADE | C7: Em inspeção de qualidade | D7: =COUNTIFS(Dados_SAP!$S$2:$S$10543,"QUALIDADE") -> 1063 | E7: =SUMIFS(Dados_SAP!$J$2:$J$10543,Dados_SAP!$S$2:$S$10543,"QUALIDADE",Dados_SAP!$K$2:$K$10543,"KG") -> 662047.19 | F7: =IFERROR(E7/(SUMIFS(Dados_SAP!$J$2:$J$10543,Dados_SAP!$K$2:$K$10543,"KG")),0) -> 0.14253763 | G7: =IF(D7=0,"✅ OK","🟠 ATENÇÃO") -> 🟠 ATENÇÃO | H7: Acompanhar com a Qualidade o prazo de liberação; escalar inspeções paradas há muito tempo.
A8: 4 | B8: BLOQUEADO | C8: Bloqueado para uso | D8: =COUNTIFS(Dados_SAP!$S$2:$S$10543,"BLOQUEADO") -> 593 | E8: =SUMIFS(Dados_SAP!$J$2:$J$10543,Dados_SAP!$S$2:$S$10543,"BLOQUEADO",Dados_SAP!$K$2:$K$10543,"KG") -> 171647.12 | F8: =IFERROR(E8/(SUMIFS(Dados_SAP!$J$2:$J$10543,Dados_SAP!$K$2:$K$10543,"KG")),0) -> 0.03695533 | G8: =IF(D8=0,"✅ OK","🟠 ATENÇÃO") -> 🟠 ATENÇÃO | H8: Identificar o motivo do bloqueio com o responsável e definir prazo para liberação ou descarte.
A9: 5 | B9: RESTRITO/DEVOLUÇÃO | C9: Estoque restrito/devolução | D9: =COUNTIFS(Dados_SAP!$S$2:$S$10543,"RESTRITO/DEVOLUÇÃO") -> 615 | E9: =SUMIFS(Dados_SAP!$J$2:$J$10543,Dados_SAP!$S$2:$S$10543,"RESTRITO/DEVOLUÇÃO",Dados_SAP!$K$2:$K$10543,"KG") -> 98943.09 | F9: =IFERROR(E9/(SUMIFS(Dados_SAP!$J$2:$J$10543,Dados_SAP!$K$2:$K$10543,"KG")),0) -> 0.021302278 | G9: =IF(D9=0,"✅ OK","🟠 ATENÇÃO") -> 🟠 ATENÇÃO | H9: Definir destino (retrabalho, devolução a fornecedor/cliente ou descarte) sem deixar acumular.
A10: 6 | B10: QUARENTENA | C10: Em quarentena | D10: =COUNTIFS(Dados_SAP!$S$2:$S$10543,"QUARENTENA") -> 94 | E10: =SUMIFS(Dados_SAP!$J$2:$J$10543,Dados_SAP!$S$2:$S$10543,"QUARENTENA",Dados_SAP!$K$2:$K$10543,"KG") -> 14100 | F10: =IFERROR(E10/(SUMIFS(Dados_SAP!$J$2:$J$10543,Dados_SAP!$K$2:$K$10543,"KG")),0) -> 0.0030357058 | G10: =IF(D10=0,"✅ OK","🟠 ATENÇÃO") -> 🟠 ATENÇÃO | H10: Confirmar com Qualidade/Compras a liberação do lote; monitorar o tempo em quarentena.
A11: 7 | B11: DESCARTE/DEVOLUÇÃO | C11: Em posição de descarte/devolução | D11: =COUNTIFS(Dados_SAP!$S$2:$S$10543,"DESCARTE/DEVOLUÇÃO") -> 19 | E11: =SUMIFS(Dados_SAP!$J$2:$J$10543,Dados_SAP!$S$2:$S$10543,"DESCARTE/DEVOLUÇÃO",Dados_SAP!$K$2:$K$10543,"KG") -> 1996.5 | F11: =IFERROR(E11/(SUMIFS(Dados_SAP!$J$2:$J$10543,Dados_SAP!$K$2:$K$10543,"KG")),0) -> 0.00042984303 | G11: =IF(D11=0,"✅ OK","🔴 CRÍTICO") -> 🔴 CRÍTICO | H11: Formalizar e executar o descarte/retorno — material parado aqui trava espaço e capital de giro.
A12: 8 | B12: SEM LOTE | C12: Sem lote (falta de rastreabilidade) | D12: =COUNTIFS(Dados_SAP!$S$2:$S$10543,"SEM LOTE") -> 232 | E12: =SUMIFS(Dados_SAP!$J$2:$J$10543,Dados_SAP!$S$2:$S$10543,"SEM LOTE",Dados_SAP!$K$2:$K$10543,"KG") -> 2347.7 | F12: =IFERROR(E12/(SUMIFS(Dados_SAP!$J$2:$J$10543,Dados_SAP!$K$2:$K$10543,"KG")),0) -> 0.00050545578 | G12: =IF(D12=0,"✅ OK","🔴 CRÍTICO") -> 🔴 CRÍTICO | H12: Corrigir o apontamento no SAP; lote é obrigatório para rastreabilidade em alimentos.
A13: 9 | B13: PARADO/SEM GIRO | C13: Sem movimento há muito tempo | D13: =COUNTIFS(Dados_SAP!$S$2:$S$10543,"PARADO/SEM GIRO") -> 602 | E13: =SUMIFS(Dados_SAP!$J$2:$J$10543,Dados_SAP!$S$2:$S$10543,"PARADO/SEM GIRO",Dados_SAP!$K$2:$K$10543,"KG") -> 351142.17 | F13: =IFERROR(E13/(SUMIFS(Dados_SAP!$J$2:$J$10543,Dados_SAP!$K$2:$K$10543,"KG")),0) -> 0.075600307 | G13: =IF(D13=0,"✅ OK","🟠 ATENÇÃO") -> 🟠 ATENÇÃO | H13: Revisar previsão de demanda, avaliar redistribuição entre centros ou promover o consumo do item.
A15: Para o detalhe posição-a-posição de cada ponto acima, use os filtros da aba Painel ou o filtro automático da aba Dados_SAP (coluna Alerta).

Sheet Dados_SAP
A1: Tipo de depósito | B1: Posição no depósito | C1: Material | D1: Lote | E1: Nº de quantos | F1: Tipo de estoque | G1: Unidade de depósito | H1: Estoque disponível | I1: Último movimento | J1: Estoque total | K1: UM básica | L1: Duração | M1: Inventário ativo | N1: Depósito | O1: Data do vencimento | P1: Centro | Q1: Duração (dias) | R1: Dias até vencer | S1: Alerta | T1: _chave_rank_parado | U1: _chave_rank_vencido
A2: 910 | B2: WA-ZONE | C2: << vazio >> | E2: 0 | H2: 0 | J2: 0 | L2: 0 | Q2: =IFERROR(VALUE(L2),"") -> 0 | R2: =IF(O2="","",O2-TODAY()) | S2: =IF(C2="<< vazio >>","VAZIA",IF(AND(O2<>"",R2<0),"VENCIDO",IF(AND(O2<>"",R2<=Parametros!$B$10),"PRÓX. VENCIMENTO",IF(F2="Q","QUALIDADE",IF(F2="S","BLOQUEADO",IF(F2="R","RESTRITO/DEVOLUÇÃO",IF(OR(N2="QUAR",N2="QRES"),"QUARENTENA",IF(OR(B2="DESCARTE",B2="DEVOLUÇÃO"),"DESCARTE/DEVOLUÇÃO",IF(AND(D2="",K2<>""),"SEM LOTE",IF(AND(Q2<>"",Q2>=Parametros!$B$11),"PARADO/SEM GIRO","OK")))))))))) -> VAZIA | T2: =IF(AND($S2="PARADO/SEM GIRO",$K2="KG",OR(Painel!$B$5="(Todos)",A2=Painel!$B$5)*OR(Painel!$E$5="(Todos)",P2=Painel!$E$5)),$J2+ROW()/10000000,"") | U2: =IF(AND($S2="VENCIDO",$K2="KG",OR(Painel!$B$5="(Todos)",A2=Painel!$B$5)*OR(Painel!$E$5="(Todos)",P2=Painel!$E$5)),$J2+ROW()/10000000,"")
A3: 911 | B3: BULK | C3: 14191832 | E3: 7 | H3: 1143.7 | I3: 46283 | J3: 1143.7 | K3: KG | L3: 10 | N3: 9999 | P3: BR01 | Q3: =IFERROR(VALUE(L3),"") -> 10 | R3: =IF(O3="","",O3-TODAY()) | S3: =IF(C3="<< vazio >>","VAZIA",IF(AND(O3<>"",R3<0),"VENCIDO",IF(AND(O3<>"",R3<=Parametros!$B$10),"PRÓX. VENCIMENTO",IF(F3="Q","QUALIDADE",IF(F3="S","BLOQUEADO",IF(F3="R","RESTRITO/DEVOLUÇÃO",IF(OR(N3="QUAR",N3="QRES"),"QUARENTENA",IF(OR(B3="DESCARTE",B3="DEVOLUÇÃO"),"DESCARTE/DEVOLUÇÃO",IF(AND(D3="",K3<>""),"SEM LOTE",IF(AND(Q3<>"",Q3>=Parametros!$B$11),"PARADO/SEM GIRO","OK")))))))))) -> SEM LOTE | T3: =IF(AND($S3="PARADO/SEM GIRO",$K3="KG",OR(Painel!$B$5="(Todos)",A3=Painel!$B$5)*OR(Painel!$E$5="(Todos)",P3=Painel!$E$5)),$J3+ROW()/10000000,"") | U3: =IF(AND($S3="VENCIDO",$K3="KG",OR(Painel!$B$5="(Todos)",A3=Painel!$B$5)*OR(Painel!$E$5="(Todos)",P3=Painel!$E$5)),$J3+ROW()/10000000,"")
A4: 911 | B4: BULK | C4: 44009711 | E4: 7 | H4: 4846 | I4: 46285 | J4: 4846 | K4: UN | L4: 13 | N4: 9999 | P4: BR01 | Q4: =IFERROR(VALUE(L4),"") -> 13 | R4: =IF(O4="","",O4-TODAY()) | S4: =IF(C4="<< vazio >>","VAZIA",IF(AND(O4<>"",R4<0),"VENCIDO",IF(AND(O4<>"",R4<=Parametros!$B$10),"PRÓX. VENCIMENTO",IF(F4="Q","QUALIDADE",IF(F4="S","BLOQUEADO",IF(F4="R","RESTRITO/DEVOLUÇÃO",IF(OR(N4="QUAR",N4="QRES"),"QUARENTENA",IF(OR(B4="DESCARTE",B4="DEVOLUÇÃO"),"DESCARTE/DEVOLUÇÃO",IF(AND(D4="",K4<>""),"SEM LOTE",IF(AND(Q4<>"",Q4>=Parametros!$B$11),"PARADO/SEM GIRO","OK")))))))))) -> SEM LOTE | T4: =IF(AND($S4="PARADO/SEM GIRO",$K4="KG",OR(Painel!$B$5="(Todos)",A4=Painel!$B$5)*OR(Painel!$E$5="(Todos)",P4=Painel!$E$5)),$J4+ROW()/10000000,"") | U4: =IF(AND($S4="VENCIDO",$K4="KG",OR(Painel!$B$5="(Todos)",A4=Painel!$B$5)*OR(Painel!$E$5="(Todos)",P4=Painel!$E$5)),$J4+ROW()/10000000,"")
A5: 911 | B5: BULK | C5: 44101020 | D5: 119690 | E5: 7 | H5: 15 | I5: 46272 | J5: 15 | K5: UN | L5: 13 | N5: 9999 | O5: 46569 | P5: BR01 | Q5: =IFERROR(VALUE(L5),"") -> 13 | R5: =IF(O5="","",O5-TODAY()) -> 284 | S5: =IF(C5="<< vazio >>","VAZIA",IF(AND(O5<>"",R5<0),"VENCIDO",IF(AND(O5<>"",R5<=Parametros!$B$10),"PRÓX. VENCIMENTO",IF(F5="Q","QUALIDADE",IF(F5="S","BLOQUEADO",IF(F5="R","RESTRITO/DEVOLUÇÃO",IF(OR(N5="QUAR",N5="QRES"),"QUARENTENA",IF(OR(B5="DESCARTE",B5="DEVOLUÇÃO"),"DESCARTE/DEVOLUÇÃO",IF(AND(D5="",K5<>""),"SEM LOTE",IF(AND(Q5<>"",Q5>=Parametros!$B$11),"PARADO/SEM GIRO","OK")))))))))) -> OK | T5: =IF(AND($S5="PARADO/SEM GIRO",$K5="KG",OR(Painel!$B$5="(Todos)",A5=Painel!$B$5)*OR(Painel!$E$5="(Todos)",P5=Painel!$E$5)),$J5+ROW()/10000000,"") | U5: =IF(AND($S5="VENCIDO",$K5="KG",OR(Painel!$B$5="(Todos)",A5=Painel!$B$5)*OR(Painel!$E$5="(Todos)",P5=Painel!$E$5)),$J5+ROW()/10000000,"")
A6: 911 | B6: BULK | C6: CRD-DR-7072302-039 | D6: A26217B11 | E6: 7 | H6: 20 | I6: 46275 | J6: 20 | K6: KG | L6: 10 | N6: 9999 | O6: 46970 | P6: BR01 | Q6: =IFERROR(VALUE(L6),"") -> 10 | R6: =IF(O6="","",O6-TODAY()) -> 685 | S6: =IF(C6="<< vazio >>","VAZIA",IF(AND(O6<>"",R6<0),"VENCIDO",IF(AND(O6<>"",R6<=Parametros!$B$10),"PRÓX. VENCIMENTO",IF(F6="Q","QUALIDADE",IF(F6="S","BLOQUEADO",IF(F6="R","RESTRITO/DEVOLUÇÃO",IF(OR(N6="QUAR",N6="QRES"),"QUARENTENA",IF(OR(B6="DESCARTE",B6="DEVOLUÇÃO"),"DESCARTE/DEVOLUÇÃO",IF(AND(D6="",K6<>""),"SEM LOTE",IF(AND(Q6<>"",Q6>=Parametros!$B$11),"PARADO/SEM GIRO","OK")))))))))) -> OK | T6: =IF(AND($S6="PARADO/SEM GIRO",$K6="KG",OR(Painel!$B$5="(Todos)",A6=Painel!$B$5)*OR(Painel!$E$5="(Todos)",P6=Painel!$E$5)),$J6+ROW()/10000000,"") | U6: =IF(AND($S6="VENCIDO",$K6="KG",OR(Painel!$B$5="(Todos)",A6=Painel!$B$5)*OR(Painel!$E$5="(Todos)",P6=Painel!$E$5)),$J6+ROW()/10000000,"")
A7: 911 | B7: BULK | C7: CRM-BL-0021380-B94 | D7: A25147-21 | E7: 7 | H7: 40.4 | I7: 46276 | J7: 40.4 | K7: KG | L7: 9 | N7: 9991 | P7: BR01 | Q7: =IFERROR(VALUE(L7),"") -> 9 | R7: =IF(O7="","",O7-TODAY()) | S7: =IF(C7="<< vazio >>","VAZIA",IF(AND(O7<>"",R7<0),"VENCIDO",IF(AND(O7<>"",R7<=Parametros!$B$10),"PRÓX. VENCIMENTO",IF(F7="Q","QUALIDADE",IF(F7="S","BLOQUEADO",IF(F7="R","RESTRITO/DEVOLUÇÃO",IF(OR(N7="QUAR",N7="QRES"),"QUARENTENA",IF(OR(B7="DESCARTE",B7="DEVOLUÇÃO"),"DESCARTE/DEVOLUÇÃO",IF(AND(D7="",K7<>""),"SEM LOTE",IF(AND(Q7<>"",Q7>=Parametros!$B$11),"PARADO/SEM GIRO","OK")))))))))) -> OK | T7: =IF(AND($S7="PARADO/SEM GIRO",$K7="KG",OR(Painel!$B$5="(Todos)",A7=Painel!$B$5)*OR(Painel!$E$5="(Todos)",P7=Painel!$E$5)),$J7+ROW()/10000000,"") | U7: =IF(AND($S7="VENCIDO",$K7="KG",OR(Painel!$B$5="(Todos)",A7=Painel!$B$5)*OR(Painel!$E$5="(Todos)",P7=Painel!$E$5)),$J7+ROW()/10000000,"")
A8: 911 | B8: BULK | C8: CRW-BL-2002514-B94 | D8: A26222-21 | E8: 7 | F8: S | H8: 30.3 | I8: 46274 | J8: 30.3 | K8: KG | L8: 11 | N8: 9999 | O8: 46609 | P8: BR01 | Q8: =IFERROR(VALUE(L8),"") -> 11 | R8: =IF(O8="","",O8-TODAY()) -> 324 | S8: =IF(C8="<< vazio >>","VAZIA",IF(AND(O8<>"",R8<0),"VENCIDO",IF(AND(O8<>"",R8<=Parametros!$B$10),"PRÓX. VENCIMENTO",IF(F8="Q","QUALIDADE",IF(F8="S","BLOQUEADO",IF(F8="R","RESTRITO/DEVOLUÇÃO",IF(OR(N8="QUAR",N8="QRES"),"QUARENTENA",IF(OR(B8="DESCARTE",B8="DEVOLUÇÃO"),"DESCARTE/DEVOLUÇÃO",IF(AND(D8="",K8<>""),"SEM LOTE",IF(AND(Q8<>"",Q8>=Parametros!$B$11),"PARADO/SEM GIRO","OK")))))))))) -> BLOQUEADO | T8: =IF(AND($S8="PARADO/SEM GIRO",$K8="KG",OR(Painel!$B$5="(Todos)",A8=Painel!$B$5)*OR(Painel!$E$5="(Todos)",P8=Painel!$E$5)),$J8+ROW()/10000000,"") | U8: =IF(AND($S8="VENCIDO",$K8="KG",OR(Painel!$B$5="(Todos)",A8=Painel!$B$5)*OR(Painel!$E$5="(Todos)",P8=Painel!$E$5)),$J8+ROW()/10000000,"")
A9: 911 | B9: BULK | C9: CRW-DR-2072602-039 | D9: A26206B11 | E9: 7 | H9: 20 | I9: 46275 | J9: 20 | K9: KG | L9: 10 | N9: 9999 | O9: 46593 | P9: BR01 | Q9: =IFERROR(VALUE(L9),"") -> 10 | R9: =IF(O9="","",O9-TODAY()) -> 308 | S9: =IF(C9="<< vazio >>","VAZIA",IF(AND(O9<>"",R9<0),"VENCIDO",IF(AND(O9<>"",R9<=Parametros!$B$10),"PRÓX. VENCIMENTO",IF(F9="Q","QUALIDADE",IF(F9="S","BLOQUEADO",IF(F9="R","RESTRITO/DEVOLUÇÃO",IF(OR(N9="QUAR",N9="QRES"),"QUARENTENA",IF(OR(B9="DESCARTE",B9="DEVOLUÇÃO"),"DESCARTE/DEVOLUÇÃO",IF(AND(D9="",K9<>""),"SEM LOTE",IF(AND(Q9<>"",Q9>=Parametros!$B$11),"PARADO/SEM GIRO","OK")))))))))) -> OK | T9: =IF(AND($S9="PARADO/SEM GIRO",$K9="KG",OR(Painel!$B$5="(Todos)",A9=Painel!$B$5)*OR(Painel!$E$5="(Todos)",P9=Painel!$E$5)),$J9+ROW()/10000000,"") | U9: =IF(AND($S9="VENCIDO",$K9="KG",OR(Painel!$B$5="(Todos)",A9=Painel!$B$5)*OR(Painel!$E$5="(Todos)",P9=Painel!$E$5)),$J9+ROW()/10000000,"")
A10: 911 | B10: PESQUISA | C10: 805-BR-D94 | D10: 251633359 | E10: 14 | H10: 2.8 | I10: 46280 | J10: 2.8 | K10: KG | L10: 5 | N10: 9999 | O10: 46550 | P10: BR01 | Q10: =IFERROR(VALUE(L10),"") -> 5 | R10: =IF(O10="","",O10-TODAY()) -> 265 | S10: =IF(C10="<< vazio >>","VAZIA",IF(AND(O10<>"",R10<0),"VENCIDO",IF(AND(O10<>"",R10<=Parametros!$B$10),"PRÓX. VENCIMENTO",IF(F10="Q","QUALIDADE",IF(F10="S","BLOQUEADO",IF(F10="R","RESTRITO/DEVOLUÇÃO",IF(OR(N10="QUAR",N10="QRES"),"QUARENTENA",IF(OR(B10="DESCARTE",B10="DEVOLUÇÃO"),"DESCARTE/DEVOLUÇÃO",IF(AND(D10="",K10<>""),"SEM LOTE",IF(AND(Q10<>"",Q10>=Parametros!$B$11),"PARADO/SEM GIRO","OK")))))))))) -> OK | T10: =IF(AND($S10="PARADO/SEM GIRO",$K10="KG",OR(Painel!$B$5="(Todos)",A10=Painel!$B$5)*OR(Painel!$E$5="(Todos)",P10=Painel!$E$5)),$J10+ROW()/10000000,"") | U10: =IF(AND($S10="VENCIDO",$K10="KG",OR(Painel!$B$5="(Todos)",A10=Painel!$B$5)*OR(Painel!$E$5="(Todos)",P10=Painel!$E$5)),$J10+ROW()/10000000,"")
A11: 911 | B11: PESQUISA | C11: 823-BR-25A | D11: 251950303 | E11: 14 | H11: 20.1 | I11: 46280 | J11: 20.1 | K11: KG | L11: 5 | N11: 9999 | O11: 46401 | P11: BR01 | Q11: =IFERROR(VALUE(L11),"") -> 5 | R11: =IF(O11="","",O11-TODAY()) -> 116 | S11: =IF(C11="<< vazio >>","VAZIA",IF(AND(O11<>"",R11<0),"VENCIDO",IF(AND(O11<>"",R11<=Parametros!$B$10),"PRÓX. VENCIMENTO",IF(F11="Q","QUALIDADE",IF(F11="S","BLOQUEADO",IF(F11="R","RESTRITO/DEVOLUÇÃO",IF(OR(N11="QUAR",N11="QRES"),"QUARENTENA",IF(OR(B11="DESCARTE",B11="DEVOLUÇÃO"),"DESCARTE/DEVOLUÇÃO",IF(AND(D11="",K11<>""),"SEM LOTE",IF(AND(Q11<>"",Q11>=Parametros!$B$11),"PARADO/SEM GIRO","OK")))))))))) -> OK | T11: =IF(AND($S11="PARADO/SEM GIRO",$K11="KG",OR(Painel!$B$5="(Todos)",A11=Painel!$B$5)*OR(Painel!$E$5="(Todos)",P11=Painel!$E$5)),$J11+ROW()/10000000,"") | U11: =IF(AND($S11="VENCIDO",$K11="KG",OR(Painel!$B$5="(Todos)",A11=Painel!$B$5)*OR(Painel!$E$5="(Todos)",P11=Painel!$E$5)),$J11+ROW()/10000000,"")
A12: 911 | B12: PESQUISA | C12: 823-BR-D94 | D12: 252103049 | E12: 14 | H12: 8.4 | I12: 46280 | J12: 8.4 | K12: KG | L12: 12 | N12: 9999 | O12: 46416 | P12: BR01 | Q12: =IFERROR(VALUE(L12),"") -> 12 | R12: =IF(O12="","",O12-TODAY()) -> 131 | S12: =IF(C12="<< vazio >>","VAZIA",IF(AND(O12<>"",R12<0),"VENCIDO",IF(AND(O12<>"",R12<=Parametros!$B$10),"PRÓX. VENCIMENTO",IF(F12="Q","QUALIDADE",IF(F12="S","BLOQUEADO",IF(F12="R","RESTRITO/DEVOLUÇÃO",IF(OR(N12="QUAR",N12="QRES"),"QUARENTENA",IF(OR(B12="DESCARTE",B12="DEVOLUÇÃO"),"DESCARTE/DEVOLUÇÃO",IF(AND(D12="",K12<>""),"SEM LOTE",IF(AND(Q12<>"",Q12>=Parametros!$B$11),"PARADO/SEM GIRO","OK")))))))))) -> OK | T12: =IF(AND($S12="PARADO/SEM GIRO",$K12="KG",OR(Painel!$B$5="(Todos)",A12=Painel!$B$5)*OR(Painel!$E$5="(Todos)",P12=Painel!$E$5)),$J12+ROW()/10000000,"") | U12: =IF(AND($S12="VENCIDO",$K12="KG",OR(Painel!$B$5="(Todos)",A12=Painel!$B$5)*OR(Painel!$E$5="(Todos)",P12=Painel!$E$5)),$J12+ROW()/10000000,"")
A13: 911 | B13: PESQUISA | C13: CHK-R30GOLD-E0-D94 | D13: 252753229 | E13: 14 | H13: 2.8 | I13: 46280 | J13: 2.8 | K13: KG | L13: 5 | N13: 9991 | O13: 46297 | P13: BR01 | Q13: =IFERROR(VALUE(L13),"") -> 5 | R13: =IF(O13="","",O13-TODAY()) -> 12 | S13: =IF(C13="<< vazio >>","VAZIA",IF(AND(O13<>"",R13<0),"VENCIDO",IF(AND(O13<>"",R13<=Parametros!$B$10),"PRÓX. VENCIMENTO",IF(F13="Q","QUALIDADE",IF(F13="S","BLOQUEADO",IF(F13="R","RESTRITO/DEVOLUÇÃO",IF(OR(N13="QUAR",N13="QRES"),"QUARENTENA",IF(OR(B13="DESCARTE",B13="DEVOLUÇÃO"),"DESCARTE/DEVOLUÇÃO",IF(AND(D13="",K13<>""),"SEM LOTE",IF(AND(Q13<>"",Q13>=Parametros!$B$11),"PARADO/SEM GIRO","OK")))))))))) -> PRÓX. VENCIMENTO | T13: =IF(AND($S13="PARADO/SEM GIRO",$K13="KG",OR(Painel!$B$5="(Todos)",A13=Painel!$B$5)*OR(Painel!$E$5="(Todos)",P13=Painel!$E$5)),$J13+ROW()/10000000,"") | U13: =IF(AND($S13="VENCIDO",$K13="KG",OR(Painel!$B$5="(Todos)",A13=Painel!$B$5)*OR(Painel!$E$5="(Todos)",P13=Painel!$E$5)),$J13+ROW()/10000000,"")
A14: 911 | B14: PESQUISA | C14: CRM-BL-0002614-B94 | D14: A26089-21 | E14: 14 | H14: 10.1 | I14: 46280 | J14: 10.1 | K14: KG | L14: 5 | N14: 9999 | O14: 46660 | P14: BR01 | Q14: =IFERROR(VALUE(L14),"") -> 5 | R14: =IF(O14="","",O14-TODAY()) -> 375 | S14: =IF(C14="<< vazio >>","VAZIA",IF(AND(O14<>"",R14<0),"VENCIDO",IF(AND(O14<>"",R14<=Parametros!$B$10),"PRÓX. VENCIMENTO",IF(F14="Q","QUALIDADE",IF(F14="S","BLOQUEADO",IF(F14="R","RESTRITO/DEVOLUÇÃO",IF(OR(N14="QUAR",N14="QRES"),"QUARENTENA",IF(OR(B14="DESCARTE",B14="DEVOLUÇÃO"),"DESCARTE/DEVOLUÇÃO",IF(AND(D14="",K14<>""),"SEM LOTE",IF(AND(Q14<>"",Q14>=Parametros!$B$11),"PARADO/SEM GIRO","OK")))))))))) -> OK | T14: =IF(AND($S14="PARADO/SEM GIRO",$K14="KG",OR(Painel!$B$5="(Todos)",A14=Painel!$B$5)*OR(Painel!$E$5="(Todos)",P14=Painel!$E$5)),$J14+ROW()/10000000,"") | U14: =IF(AND($S14="VENCIDO",$K14="KG",OR(Painel!$B$5="(Todos)",A14=Painel!$B$5)*OR(Painel!$E$5="(Todos)",P14=Painel!$E$5)),$J14+ROW()/10000000,"")
A15: 911 | B15: PESQUISA | C15: CRM-EZ-0075800-K15 | D15: A26191B31 | E15: 14 | H15: 12.12 | I15: 46280 | J15: 12.12 | K15: KG | L15: 5 | N15: 9999 | O15: 46762 | P15: BR01 | Q15: =IFERROR(VALUE(L15),"") -> 5 | R15: =IF(O15="","",O15-TODAY()) -> 477 | S15: =IF(C15="<< vazio >>","VAZIA",IF(AND(O15<>"",R15<0),"VENCIDO",IF(AND(O15<>"",R15<=Parametros!$B$10),"PRÓX. VENCIMENTO",IF(F15="Q","QUALIDADE",IF(F15="S","BLOQUEADO",IF(F15="R","RESTRITO/DEVOLUÇÃO",IF(OR(N15="QUAR",N15="QRES"),"QUARENTENA",IF(OR(B15="DESCARTE",B15="DEVOLUÇÃO"),"DESCARTE/DEVOLUÇÃO",IF(AND(D15="",K15<>""),"SEM LOTE",IF(AND(Q15<>"",Q15>=Parametros!$B$11),"PARADO/SEM GIRO","OK")))))))))) -> OK | T15: =IF(AND($S15="PARADO/SEM GIRO",$K15="KG",OR(Painel!$B$5="(Todos)",A15=Painel!$B$5)*OR(Painel!$E$5="(Todos)",P15=Painel!$E$5)),$J15+ROW()/10000000,"") | U15: =IF(AND($S15="VENCIDO",$K15="KG",OR(Painel!$B$5="(Todos)",A15=Painel!$B$5)*OR(Painel!$E$5="(Todos)",P15=Painel!$E$5)),$J15+ROW()/10000000,"")
A16: 911 | B16: PESQUISA | C16: CRW-BL-2002514-B94 | D16: A25296-21 | E16: 14 | H16: 10.1 | I16: 46280 | J16: 10.1 | K16: KG | L16: 5 | N16: 9991 | O16: 46318 | P16: BR01 | Q16: =IFERROR(VALUE(L16),"") -> 5 | R16: =IF(O16="","",O16-TODAY()) -> 33 | S16: =IF(C16="<< vazio >>","VAZIA",IF(AND(O16<>"",R16<0),"VENCIDO",IF(AND(O16<>"",R16<=Parametros!$B$10),"PRÓX. VENCIMENTO",IF(F16="Q","QUALIDADE",IF(F16="S","BLOQUEADO",IF(F16="R","RESTRITO/DEVOLUÇÃO",IF(OR(N16="QUAR",N16="QRES"),"QUARENTENA",IF(OR(B16="DESCARTE",B16="DEVOLUÇÃO"),"DESCARTE/DEVOLUÇÃO",IF(AND(D16="",K16<>""),"SEM LOTE",IF(AND(Q16<>"",Q16>=Parametros!$B$11),"PARADO/SEM GIRO","OK")))))))))) -> PRÓX. VENCIMENTO | T16: =IF(AND($S16="PARADO/SEM GIRO",$K16="KG",OR(Painel!$B$5="(Todos)",A16=Painel!$B$5)*OR(Painel!$E$5="(Todos)",P16=Painel!$E$5)),$J16+ROW()/10000000,"") | U16: =IF(AND($S16="VENCIDO",$K16="KG",OR(Painel!$B$5="(Todos)",A16=Painel!$B$5)*OR(Painel!$E$5="(Todos)",P16=Painel!$E$5)),$J16+ROW()/10000000,"")
A17: 911 | B17: PESQUISA | C17: ILD-BL-7011022-A12 | D17: A25317-21 | E17: 14 | H17: 10.5 | I17: 46274 | J17: 10.5 | K17: KG | L17: 11 | N17: 9999 | O17: 46520 | P17: BR01 | Q17: =IFERROR(VALUE(L17),"") -> 11 | R17: =IF(O17="","",O17-TODAY()) -> 235 | S17: =IF(C17="<< vazio >>","VAZIA",IF(AND(O17<>"",R17<0),"VENCIDO",IF(AND(O17<>"",R17<=Parametros!$B$10),"PRÓX. VENCIMENTO",IF(F17="Q","QUALIDADE",IF(F17="S","BLOQUEADO",IF(F17="R","RESTRITO/DEVOLUÇÃO",IF(OR(N17="QUAR",N17="QRES"),"QUARENTENA",IF(OR(B17="DESCARTE",B17="DEVOLUÇÃO"),"DESCARTE/DEVOLUÇÃO",IF(AND(D17="",K17<>""),"SEM LOTE",IF(AND(Q17<>"",Q17>=Parametros!$B$11),"PARADO/SEM GIRO","OK")))))))))) -> OK | T17: =IF(AND($S17="PARADO/SEM GIRO",$K17="KG",OR(Painel!$B$5="(Todos)",A17=Painel!$B$5)*OR(Painel!$E$5="(Todos)",P17=Painel!$E$5)),$J17+ROW()/10000000,"") | U17: =IF(AND($S17="VENCIDO",$K17="KG",OR(Painel!$B$5="(Todos)",A17=Painel!$B$5)*OR(Painel!$E$5="(Todos)",P17=Painel!$E$5)),$J17+ROW()/10000000,"")
A18: 911 | B18: PESQUISA | C18: ILD-BL-7016144-A12 | D18: A26092-21 | E18: 14 | H18: 10.5 | I18: 46274 | J18: 10.5 | K18: KG | L18: 11 | N18: 9999 | O18: 46662 | P18: BR01 | Q18: =IFERROR(VALUE(L18),"") -> 11 | R18: =IF(O18="","",O18-TODAY()) -> 377 | S18: =IF(C18="<< vazio >>","VAZIA",IF(AND(O18<>"",R18<0),"VENCIDO",IF(AND(O18<>"",R18<=Parametros!$B$10),"PRÓX. VENCIMENTO",IF(F18="Q","QUALIDADE",IF(F18="S","BLOQUEADO",IF(F18="R","RESTRITO/DEVOLUÇÃO",IF(OR(N18="QUAR",N18="QRES"),"QUARENTENA",IF(OR(B18="DESCARTE",B18="DEVOLUÇÃO"),"DESCARTE/DEVOLUÇÃO",IF(AND(D18="",K18<>""),"SEM LOTE",IF(AND(Q18<>"",Q18>=Parametros!$B$11),"PARADO/SEM GIRO","OK")))))))))) -> OK | T18: =IF(AND($S18="PARADO/SEM GIRO",$K18="KG",OR(Painel!$B$5="(Todos)",A18=Painel!$B$5)*OR(Painel!$E$5="(Todos)",P18=Painel!$E$5)),$J18+ROW()/10000000,"") | U18: =IF(AND($S18="VENCIDO",$K18="KG",OR(Painel!$B$5="(Todos)",A18=Painel!$B$5)*OR(Painel!$E$5="(Todos)",P18=Painel!$E$5)),$J18+ROW()/10000000,"")
A19: 911 | B19: PESQUISA | C19: ILM-BL-0011021-B94 | D19: A25332-21 | E19: 14 | H19: 10.1 | I19: 46274 | J19: 10.1 | K19: KG | L19: 11 | N19: 9999 | O19: 46535 | P19: BR01 | Q19: =IFERROR(VALUE(L19),"") -> 11 | R19: =IF(O19="","",O19-TODAY()) -> 250 | S19: =IF(C19="<< vazio >>","VAZIA",IF(AND(O19<>"",R19<0),"VENCIDO",IF(AND(O19<>"",R19<=Parametros!$B$10),"PRÓX. VENCIMENTO",IF(F19="Q","QUALIDADE",IF(F19="S","BLOQUEADO",IF(F19="R","RESTRITO/DEVOLUÇÃO",IF(OR(N19="QUAR",N19="QRES"),"QUARENTENA",IF(OR(B19="DESCARTE",B19="DEVOLUÇÃO"),"DESCARTE/DEVOLUÇÃO",IF(AND(D19="",K19<>""),"SEM LOTE",IF(AND(Q19<>"",Q19>=Parametros!$B$11),"PARADO/SEM GIRO","OK")))))))))) -> OK | T19: =IF(AND($S19="PARADO/SEM GIRO",$K19="KG",OR(Painel!$B$5="(Todos)",A19=Painel!$B$5)*OR(Painel!$E$5="(Todos)",P19=Painel!$E$5)),$J19+ROW()/10000000,"") | U19: =IF(AND($S19="VENCIDO",$K19="KG",OR(Painel!$B$5="(Todos)",A19=Painel!$B$5)*OR(Painel!$E$5="(Todos)",P19=Painel!$E$5)),$J19+ROW()/10000000,"")
A20: 911 | B20: PESQUISA | C20: ILM-BL-0016143-A12 | D20: A25326-21 | E20: 14 | H20: 10.5 | I20: 46274 | J20: 10.5 | K20: KG | L20: 11 | N20: 9999 | O20: 46529 | P20: BR01 | Q20: =IFERROR(VALUE(L20),"") -> 11 | R20: =IF(O20="","",O20-TODAY()) -> 244 | S20: =IF(C20="<< vazio >>","VAZIA",IF(AND(O20<>"",R20<0),"VENCIDO",IF(AND(O20<>"",R20<=Parametros!$B$10),"PRÓX. VENCIMENTO",IF(F20="Q","QUALIDADE",IF(F20="S","BLOQUEADO",IF(F20="R","RESTRITO/DEVOLUÇÃO",IF(OR(N20="QUAR",N20="QRES"),"QUARENTENA",IF(OR(B20="DESCARTE",B20="DEVOLUÇÃO"),"DESCARTE/DEVOLUÇÃO",IF(AND(D20="",K20<>""),"SEM LOTE",IF(AND(Q20<>"",Q20>=Parametros!$B$11),"PARADO/SEM GIRO","OK")))))))))) -> OK | T20: =IF(AND($S20="PARADO/SEM GIRO",$K20="KG",OR(Painel!$B$5="(Todos)",A20=Painel!$B$5)*OR(Painel!$E$5="(Todos)",P20=Painel!$E$5)),$J20+ROW()/10000000,"") | U20: =IF(AND($S20="VENCIDO",$K20="KG",OR(Painel!$B$5="(Todos)",A20=Painel!$B$5)*OR(Painel!$E$5="(Todos)",P20=Painel!$E$5)),$J20+ROW()/10000000,"")
... A23: 911 | B23: PESQUISA | C23: ILW-BL-2016145-B94 | D23: A26050-21 | E23: 14 | H23: 10.1 | I23: 46274 | J23: 10.1 | K23: KG | L23: 11 | N23: 9999 | O23: 46437 | P23: BR01 | Q23: =IFERROR(VALUE(L23),"") -> 11 | R23: =IF(O23="","",O23-TODAY()) -> 152 | S23: =IF(C23="<< vazio >>","VAZIA",IF(AND(O23<>"",R23<0),"VENCIDO",IF(AND(O23<>"",R23<=Parametros!$B$10),"PRÓX. VENCIMENTO",IF(F23="Q","QUALIDADE",IF(F23="S","BLOQUEADO",IF(F23="R","RESTRITO/DEVOLUÇÃO",IF(OR(N23="QUAR",N23="QRES"),"QUARENTENA",IF(OR(B23="DESCARTE",B23="DEVOLUÇÃO"),"DESCARTE/DEVOLUÇÃO",IF(AND(D23="",K23<>""),"SEM LOTE",IF(AND(Q23<>"",Q23>=Parametros!$B$11),"PARADO/SEM GIRO","OK")))))))))) -> OK | T23: =IF(AND($S23="PARADO/SEM GIRO",$K23="KG",OR(Painel!$B$5="(Todos)",A23=Painel!$B$5)*OR(Painel!$E$5="(Todos)",P23=Painel!$E$5)),$J23+ROW()/10000000,"") | U23: =IF(AND($S23="VENCIDO",$K23="KG",OR(Painel!$B$5="(Todos)",A23=Painel!$B$5)*OR(Painel!$E$5="(Todos)",P23=Painel!$E$5)),$J23+ROW()/10000000,"")
A24: 917 | B24: QUALITY | C24: << vazio >> | E24: 0 | H24: 0 | J24: 0 | L24: 0 | Q24: =IFERROR(VALUE(L24),"") -> 0 | R24: =IF(O24="","",O24-TODAY()) | S24: =IF(C24="<< vazio >>","VAZIA",IF(AND(O24<>"",R24<0),"VENCIDO",IF(AND(O24<>"",R24<=Parametros!$B$10),"PRÓX. VENCIMENTO",IF(F24="Q","QUALIDADE",IF(F24="S","BLOQUEADO",IF(F24="R","RESTRITO/DEVOLUÇÃO",IF(OR(N24="QUAR",N24="QRES"),"QUARENTENA",IF(OR(B24="DESCARTE",B24="DEVOLUÇÃO"),"DESCARTE/DEVOLUÇÃO",IF(AND(D24="",K24<>""),"SEM LOTE",IF(AND(Q24<>"",Q24>=Parametros!$B$11),"PARADO/SEM GIRO","OK")))))))))) -> VAZIA | T24: =IF(AND($S24="PARADO/SEM GIRO",$K24="KG",OR(Painel!$B$5="(Todos)",A24=Painel!$B$5)*OR(Painel!$E$5="(Todos)",P24=Painel!$E$5)),$J24+ROW()/10000000,"") | U24: =IF(AND($S24="VENCIDO",$K24="KG",OR(Painel!$B$5="(Todos)",A24=Painel!$B$5)*OR(Painel!$E$5="(Todos)",P24=Painel!$E$5)),$J24+ROW()/10000000,"")
A25: 922 | B25: TR-ZONE | C25: 70-30-38-BR-D94 | D25: 243323449 | E25: 79 | H25: 2.8 | I25: 46283 | J25: 2.8 | K25: KG | L25: 2 | N25: 9991 | P25: BR01 | Q25: =IFERROR(VALUE(L25),"") -> 2 | R25: =IF(O25="","",O25-TODAY()) | S25: =IF(C25="<< vazio >>","VAZIA",IF(AND(O25<>"",R25<0),"VENCIDO",IF(AND(O25<>"",R25<=Parametros!$B$10),"PRÓX. VENCIMENTO",IF(F25="Q","QUALIDADE",IF(F25="S","BLOQUEADO",IF(F25="R","RESTRITO/DEVOLUÇÃO",IF(OR(N25="QUAR",N25="QRES"),"QUARENTENA",IF(OR(B25="DESCARTE",B25="DEVOLUÇÃO"),"DESCARTE/DEVOLUÇÃO",IF(AND(D25="",K25<>""),"SEM LOTE",IF(AND(Q25<>"",Q25>=Parametros!$B$11),"PARADO/SEM GIRO","OK")))))))))) -> OK | T25: =IF(AND($S25="PARADO/SEM GIRO",$K25="KG",OR(Painel!$B$5="(Todos)",A25=Painel!$B$5)*OR(Painel!$E$5="(Todos)",P25=Painel!$E$5)),$J25+ROW()/10000000,"") | U25: =IF(AND($S25="VENCIDO",$K25="KG",OR(Painel!$B$5="(Todos)",A25=Painel!$B$5)*OR(Painel!$E$5="(Todos)",P25=Painel!$E$5)),$J25+ROW()/10000000,"")
A26: 922 | B26: TR-ZONE | C26: 70-30-38-BR-D94 | D26: 243323449 | E26: 79 | H26: -2.8 | I26: 46283 | J26: -2.8 | K26: KG | L26: 0 | N26: 9999 | P26: BR01 | Q26: =IFERROR(VALUE(L26),"") -> 0 | R26: =IF(O26="","",O26-TODAY()) | S26: =IF(C26="<< vazio >>","VAZIA",IF(AND(O26<>"",R26<0),"VENCIDO",IF(AND(O26<>"",R26<=Parametros!$B$10),"PRÓX. VENCIMENTO",IF(F26="Q","QUALIDADE",IF(F26="S","BLOQUEADO",IF(F26="R","RESTRITO/DEVOLUÇÃO",IF(OR(N26="QUAR",N26="QRES"),"QUARENTENA",IF(OR(B26="DESCARTE",B26="DEVOLUÇÃO"),"DESCARTE/DEVOLUÇÃO",IF(AND(D26="",K26<>""),"SEM LOTE",IF(AND(Q26<>"",Q26>=Parametros!$B$11),"PARADO/SEM GIRO","OK")))))))))) -> OK | T26: =IF(AND($S26="PARADO/SEM GIRO",$K26="KG",OR(Painel!$B$5="(Todos)",A26=Painel!$B$5)*OR(Painel!$E$5="(Todos)",P26=Painel!$E$5)),$J26+ROW()/10000000,"") | U26: =IF(AND($S26="VENCIDO",$K26="KG",OR(Painel!$B$5="(Todos)",A26=Painel!$B$5)*OR(Painel!$E$5="(Todos)",P26=Painel!$E$5)),$J26+ROW()/10000000,"")
A27: 922 | B27: TR-ZONE | C27: 805-BR-25A | D27: 251340301 | E27: 79 | H27: -20.1 | I27: 46266 | J27: -20.1 | K27: KG | L27: 0 | N27: 0355 | O27: 46521 | P27: BR01 | Q27: =IFERROR(VALUE(L27),"") -> 0 | R27: =IF(O27="","",O27-TODAY()) -> 236 | S27: =IF(C27="<< vazio >>","VAZIA",IF(AND(O27<>"",R27<0),"VENCIDO",IF(AND(O27<>"",R27<=Parametros!$B$10),"PRÓX. VENCIMENTO",IF(F27="Q","QUALIDADE",IF(F27="S","BLOQUEADO",IF(F27="R","RESTRITO/DEVOLUÇÃO",IF(OR(N27="QUAR",N27="QRES"),"QUARENTENA",IF(OR(B27="DESCARTE",B27="DEVOLUÇÃO"),"DESCARTE/DEVOLUÇÃO",IF(AND(D27="",K27<>""),"SEM LOTE",IF(AND(Q27<>"",Q27>=Parametros!$B$11),"PARADO/SEM GIRO","OK")))))))))) -> OK | T27: =IF(AND($S27="PARADO/SEM GIRO",$K27="KG",OR(Painel!$B$5="(Todos)",A27=Painel!$B$5)*OR(Painel!$E$5="(Todos)",P27=Painel!$E$5)),$J27+ROW()/10000000,"") | U27: =IF(AND($S27="VENCIDO",$K27="KG",OR(Painel!$B$5="(Todos)",A27=Painel!$B$5)*OR(Painel!$E$5="(Todos)",P27=Painel!$E$5)),$J27+ROW()/10000000,"")
A28: 922 | B28: TR-ZONE | C28: 805-BR-25A | D28: 251340301 | E28: 79 | H28: 20.1 | I28: 46266 | J28: 20.1 | K28: KG | L28: 19 | N28: 9999 | O28: 46521 | P28: BR01 | Q28: =IFERROR(VALUE(L28),"") -> 19 | R28: =IF(O28="","",O28-TODAY()) -> 236 | S28: =IF(C28="<< vazio >>","VAZIA",IF(AND(O28<>"",R28<0),"VENCIDO",IF(AND(O28<>"",R28<=Parametros!$B$10),"PRÓX. VENCIMENTO",IF(F28="Q","QUALIDADE",IF(F28="S","BLOQUEADO",IF(F28="R","RESTRITO/DEVOLUÇÃO",IF(OR(N28="QUAR",N28="QRES"),"QUARENTENA",IF(OR(B28="DESCARTE",B28="DEVOLUÇÃO"),"DESCARTE/DEVOLUÇÃO",IF(AND(D28="",K28<>""),"SEM LOTE",IF(AND(Q28<>"",Q28>=Parametros!$B$11),"PARADO/SEM GIRO","OK")))))))))) -> OK | T28: =IF(AND($S28="PARADO/SEM GIRO",$K28="KG",OR(Painel!$B$5="(Todos)",A28=Painel!$B$5)*OR(Painel!$E$5="(Todos)",P28=Painel!$E$5)),$J28+ROW()/10000000,"") | U28: =IF(AND($S28="VENCIDO",$K28="KG",OR(Painel!$B$5="(Todos)",A28=Painel!$B$5)*OR(Painel!$E$5="(Todos)",P28=Painel!$E$5)),$J28+ROW()/10000000,"")
A29: 922 | B29: TR-ZONE | C29: 823-BR-25A | D29: 251940301 | E29: 79 | H29: 80.4 | I29: 46244 | J29: 80.4 | K29: KG | L29: 41 | N29: 9999 | O29: 46400 | P29: BR01 | Q29: =IFERROR(VALUE(L29),"") -> 41 | R29: =IF(O29="","",O29-TODAY()) -> 115 | S29: =IF(C29="<< vazio >>","VAZIA",IF(AND(O29<>"",R29<0),"VENCIDO",IF(AND(O29<>"",R29<=Parametros!$B$10),"PRÓX. VENCIMENTO",IF(F29="Q","QUALIDADE",IF(F29="S","BLOQUEADO",IF(F29="R","RESTRITO/DEVOLUÇÃO",IF(OR(N29="QUAR",N29="QRES"),"QUARENTENA",IF(OR(B29="DESCARTE",B29="DEVOLUÇÃO"),"DESCARTE/DEVOLUÇÃO",IF(AND(D29="",K29<>""),"SEM LOTE",IF(AND(Q29<>"",Q29>=Parametros!$B$11),"PARADO/SEM GIRO","OK")))))))))) -> OK | T29: =IF(AND($S29="PARADO/SEM GIRO",$K29="KG",OR(Painel!$B$5="(Todos)",A29=Painel!$B$5)*OR(Painel!$E$5="(Todos)",P29=Painel!$E$5)),$J29+ROW()/10000000,"") | U29: =IF(AND($S29="VENCIDO",$K29="KG",OR(Painel!$B$5="(Todos)",A29=Painel!$B$5)*OR(Painel!$E$5="(Todos)",P29=Painel!$E$5)),$J29+ROW()/10000000,"")
A30: 922 | B30: TR-ZONE | C30: 823-BR-25A | D30: 251940302 | E30: 79 | H30: -100.5 | I30: 46244 | J30: -100.5 | K30: KG | L30: 0 | N30: 9999 | O30: 46400 | P30: BR01 | Q30: =IFERROR(VALUE(L30),"") -> 0 | R30: =IF(O30="","",O30-TODAY()) -> 115 | S30: =IF(C30="<< vazio >>","VAZIA",IF(AND(O30<>"",R30<0),"VENCIDO",IF(AND(O30<>"",R30<=Parametros!$B$10),"PRÓX. VENCIMENTO",IF(F30="Q","QUALIDADE",IF(F30="S","BLOQUEADO",IF(F30="R","RESTRITO/DEVOLUÇÃO",IF(OR(N30="QUAR",N30="QRES"),"QUARENTENA",IF(OR(B30="DESCARTE",B30="DEVOLUÇÃO"),"DESCARTE/DEVOLUÇÃO",IF(AND(D30="",K30<>""),"SEM LOTE",IF(AND(Q30<>"",Q30>=Parametros!$B$11),"PARADO/SEM GIRO","OK")))))))))) -> OK | T30: =IF(AND($S30="PARADO/SEM GIRO",$K30="KG",OR(Painel!$B$5="(Todos)",A30=Painel!$B$5)*OR(Painel!$E$5="(Todos)",P30=Painel!$E$5)),$J30+ROW()/10000000,"") | U30: =IF(AND($S30="VENCIDO",$K30="KG",OR(Painel!$B$5="(Todos)",A30=Painel!$B$5)*OR(Painel!$E$5="(Todos)",P30=Painel!$E$5)),$J30+ROW()/10000000,"")
A31: 922 | B31: TR-ZONE | C31: BIG-PF-1BO-401 | D31: 25287039 | E31: 79 | H31: -20 | I31: 46283 | J31: -20 | K31: KG | L31: 0 | N31: 9999 | P31: BR01 | Q31: =IFERROR(VALUE(L31),"") -> 0 | R31: =IF(O31="","",O31-TODAY()) | S31: =IF(C31="<< vazio >>","VAZIA",IF(AND(O31<>"",R31<0),"VENCIDO",IF(AND(O31<>"",R31<=Parametros!$B$10),"PRÓX. VENCIMENTO",IF(F31="Q","QUALIDADE",IF(F31="S","BLOQUEADO",IF(F31="R","RESTRITO/DEVOLUÇÃO",IF(OR(N31="QUAR",N31="QRES"),"QUARENTENA",IF(OR(B31="DESCARTE",B31="DEVOLUÇÃO"),"DESCARTE/DEVOLUÇÃO",IF(AND(D31="",K31<>""),"SEM LOTE",IF(AND(Q31<>"",Q31>=Parametros!$B$11),"PARADO/SEM GIRO","OK")))))))))) -> OK | T31: =IF(AND($S31="PARADO/SEM GIRO",$K31="KG",OR(Painel!$B$5="(Todos)",A31=Painel!$B$5)*OR(Painel!$E$5="(Todos)",P31=Painel!$E$5)),$J31+ROW()/10000000,"") | U31: =IF(AND($S31="VENCIDO",$K31="KG",OR(Painel!$B$5="(Todos)",A31=Painel!$B$5)*OR(Painel!$E$5="(Todos)",P31=Painel!$E$5)),$J31+ROW()/10000000,"")
A32: 922 | B32: TR-ZONE | C32: BIG-PF-1BO-401 | D32: 25287039 | E32: 79 | H32: 20 | I32: 46283 | J32: 20 | K32: KG | L32: 2 | N32: 9991 | P32: BR01 | Q32: =IFERROR(VALUE(L32),"") -> 2 | R32: =IF(O32="","",O32-TODAY()) | S32: =IF(C32="<< vazio >>","VAZIA",IF(AND(O32<>"",R32<0),"VENCIDO",IF(AND(O32<>"",R32<=Parametros!$B$10),"PRÓX. VENCIMENTO",IF(F32="Q","QUALIDADE",IF(F32="S","BLOQUEADO",IF(F32="R","RESTRITO/DEVOLUÇÃO",IF(OR(N32="QUAR",N32="QRES"),"QUARENTENA",IF(OR(B32="DESCARTE",B32="DEVOLUÇÃO"),"DESCARTE/DEVOLUÇÃO",IF(AND(D32="",K32<>""),"SEM LOTE",IF(AND(Q32<>"",Q32>=Parametros!$B$11),"PARADO/SEM GIRO","OK")))))))))) -> OK | T32: =IF(AND($S32="PARADO/SEM GIRO",$K32="KG",OR(Painel!$B$5="(Todos)",A32=Painel!$B$5)*OR(Painel!$E$5="(Todos)",P32=Painel!$E$5)),$J32+ROW()/10000000,"") | U32: =IF(AND($S32="VENCIDO",$K32="KG",OR(Painel!$B$5="(Todos)",A32=Painel!$B$5)*OR(Painel!$E$5="(Todos)",P32=Painel!$E$5)),$J32+ROW()/10000000,"")
A33: 922 | B33: TR-ZONE | C33: CHD-PO-7019570-K09 | D33: A25122-01 | E33: 79 | H33: -10.1 | I33: 46283 | J33: -10.1 | K33: KG | L33: 0 | N33: 9999 | P33: BR01 | Q33: =IFERROR(VALUE(L33),"") -> 0 | R33: =IF(O33="","",O33-TODAY()) | S33: =IF(C33="<< vazio >>","VAZIA",IF(AND(O33<>"",R33<0),"VENCIDO",IF(AND(O33<>"",R33<=Parametros!$B$10),"PRÓX. VENCIMENTO",IF(F33="Q","QUALIDADE",IF(F33="S","BLOQUEADO",IF(F33="R","RESTRITO/DEVOLUÇÃO",IF(OR(N33="QUAR",N33="QRES"),"QUARENTENA",IF(OR(B33="DESCARTE",B33="DEVOLUÇÃO"),"DESCARTE/DEVOLUÇÃO",IF(AND(D33="",K33<>""),"SEM LOTE",IF(AND(Q33<>"",Q33>=Parametros!$B$11),"PARADO/SEM GIRO","OK")))))))))) -> OK | T33: =IF(AND($S33="PARADO/SEM GIRO",$K33="KG",OR(Painel!$B$5="(Todos)",A33=Painel!$B$5)*OR(Painel!$E$5="(Todos)",P33=Painel!$E$5)),$J33+ROW()/10000000,"") | U33: =IF(AND($S33="VENCIDO",$K33="KG",OR(Painel!$B$5="(Todos)",A33=Painel!$B$5)*OR(Painel!$E$5="(Todos)",P33=Painel!$E$5)),$J33+ROW()/10000000,"")
