Workbook

Sheet Painel
A1: Painel — Volume Bruto x Capacidade de Separação (09 a 21/09/2026)
A2: GM — Fornecimentos / Peso Bruto | Equipe: 4 separadores + 3 operadores por turno | Escala 2x2 de 12h | Capacidade de referência: 35–40 t/dia
A4: Total de fornecimentos (09–21/09) | B4: Peso bruto total (t) | C4: Média diária (t/dia) | D4: Capacidade média de referência (t/dia) | E4: Dias ACIMA da capacidade máxima | F4: Dias DENTRO da faixa | G4: Dias ABAIXO da capacidade mínima | H4: Maior gap de separadores em 1 dia (est.)
A5: =Analise_Diaria!C18 -> 1379 | B5: =Analise_Diaria!F18 -> 586.87264 | C5: =Analise_Diaria!F18/13 -> 45.144049 | D5: =Dimensionamento!B19 -> 37.5 | E5: =COUNTIF(Analise_Diaria!J5:J17,"ACIMA DA CAPACIDADE") -> 7 | F5: =COUNTIF(Analise_Diaria!J5:J17,"DENTRO DA FAIXA") -> 0 | G5: =COUNTIF(Analise_Diaria!J5:J17,"ABAIXO DA CAPACIDADE") -> 6 | H5: =MAX(Analise_Diaria!L5:L17) -> 17.436026
A9: Volume Bruto Diário x Faixa de Capacidade (35–40 t/dia)
A31: Leitura rápida
A32: • De 09 a 21/09, o volume bruto diário oscilou entre 0,6 t e 127,2 t — muito acima ou abaixo da faixa de 35–40 t/dia declarada como capacidade.
A33: • Dias 12, 14, 15, 16, 17, 18 e 19/09 (sáb., seg., ter., qua., qui., sex. e sáb.) ficaram ACIMA da capacidade máxima, alguns em mais de 3x (ex.: 14/09 com ~127 t e 19/09 com ~92 t).
A34: • Dias 13 e 20/09 (domingos) e 21/09 (segunda, ainda em programação) ficaram bem ABAIXO da capacidade mínima — sugerindo concentração de "data do picking" em poucos dias em vez de distribuição uniforme.
A35: • Nos dias de pico (14/09 e 19/09), a equipe de 4 separadores por turno (8/dia) precisaria, na produtividade máxima de referência (5,0 t/separador/dia), de aproximadamente 25 e 18 separadores/dia, respectivamente — um gap de +17 e +10 separadores frente aos 8 instalados.
A36: • Atenção: "Data do picking" é um campo de status do sistema, não um apontamento de horas por turno. Os dias 19–21/09 ainda têm parte relevante dos pedidos em "GERAR/FATURAR" (não concluídos), então parte desse volume é programação, não execução confirmada.
A37: • Recomenda-se: (1) validar a concentração de volume com o time operacional (é pico real de demanda ou efeito de atualização em lote do status?); (2) planejar reforço temporário/hora-extra para os dias de pico identificados; (3) medir produtividade real por separador com apontamento de mão de obra para substituir a produtividade implícita usada aqui.

Sheet Dados_Filtrados
A1: Fornecimento | B1: Peso Bruto (kg) | C1: Peso Líquido (kg) | D1: Recebedor da Mercadoria | E1: Ponto de Expedição | F1: Cidade Destino | G1: Itinerário | H1: Data do Picking | I1: Saída de Mercadoria (prevista) | J1: Status Global Picking
A2: 17854238 | B2: 42.404 | C2: 40.1 | D2: VERONA GELATERIA LTDA | E2: BR19 | F2: RIO VERDE | G2: BR_CO | H2: 46274 | I2: 46275 | J2: FATURADO
A3: 17854324 | B3: 613.677 | C3: 565.6 | D3: SUMMEL DOCES BAZAR LTDA | E3: BR19 | F3: SAPUCAIA DO SUL | G3: BR_RS | H3: 46274 | I3: 46274 | J3: FATURADO
A4: 17854325 | B4: 657.51 | C4: 606 | D4: MERCADOCE DISTRIBUIDORA DOCES LTDA | E4: BR19 | F4: CURITIBA | G4: BR_PR | H4: 46274 | I4: 46274 | J4: FATURADO
A5: 17854327 | B5: 74.324 | C5: 68.68 | D5: SÓ FESTA ATACADO E VAREJO LTDA | E5: BR19 | F5: JOINVILLE | G5: BR_SC | H5: 46274 | I5: 46274 | J5: FATURADO
A6: 17854333 | B6: 109.585 | C6: 101 | D6: MARIA DE FATIMA MACHADO | E6: BR19 | F6: SANTANA DO LIVRAMENTO | G6: BR_RS | H6: 46274 | I6: 46274 | J6: FATURADO
A7: 17854335 | B7: 48.121 | C7: 44.44 | D7: RODRIGO CARDODO KUCH | E7: BR19 | F7: PARANAGUA | G7: BR_PR | H7: 46274 | I7: 46274 | J7: FATURADO
A8: 17854336 | B8: 32.876 | C8: 30.3 | D8: CHINA FESTAS LOJA | E8: BR19 | F8: IMBITUBA | G8: BR_SC | H8: 46274 | I8: 46274 | J8: FATURADO
A9: 17854339 | B9: 21.574 | C9: 20.2 | D9: TK PRODUTOS DE LIMPEZA E | E9: BR19 | F9: NOVA PETROPOLIS | G9: BR_RS | H9: 46274 | I9: 46274 | J9: FATURADO
A10: 17854340 | B10: 43.834 | C10: 40.4 | D10: MARCIO SANTOS RAMOS | E10: BR19 | F10: SAO BORJA | G10: BR_RS | H10: 46274 | I10: 46274 | J10: FATURADO
A11: 17854341 | B11: 21.7 | C11: 20 | D11: CONFRARIA DAS EMBALAGENS LTDA | E11: BR19 | F11: BENTO GONCALVES | G11: BR_RS | H11: 46274 | I11: 46274 | J11: FATURADO
A12: 17854343 | B12: 21.23 | C12: 20.2 | D12: COMERCIO DE ARTIGOS PARA ALIMENTOS | E12: BR19 | F12: SAPIRANGA | G12: BR_RS | H12: 46274 | I12: 46274 | J12: FATURADO
A13: 17854345 | B13: 591.759 | C13: 545.4 | D13: BAGGIO FESTAS COMERCIO DE | E13: BR19 | F13: CAXIAS DO SUL | G13: BR_RS | H13: 46274 | I13: 46274 | J13: FATURADO
... A215: 17857333 | B215: 54.793 | C215: 50.5 | D215: MARISIL COMERCIO DE EMBALAGENS | E215: BR19 | F215: GUAIBA | G215: BR_RS | H215: 46276 | I215: 46276 | J215: FATURADO
A216: 17858355 | B216: 2158 | C216: 2000 | D216: BIMBO DO BRASIL LTDA | E216: BR10 | F216: GUARAPUAVA | H216: 46276 | I216: 46276 | J216: FATURADO
A217: 17858356 | B217: 1791.14 | C217: 1660 | D217: BIMBO DO BRASIL LTDA | E217: BR10 | F217: GUARAPUAVA | H217: 46276 | I217: 46279 | J217: FATURADO
A218: 17858566 | B218: 13.236 | C218: 12 | D218: MADALENA BRIGADEIROS | E218: BR19 | F218: SANTOS | G218: BR_OMX | H218: 46276 | I218: 46276 | J218: GERAR
A219: 17858779 | B219: 40.475 | C219: 35 | D219: BRIOCHE DELIVERY LTDA | E219: BR19 | F219: MARINGA | G219: BR_PR | H219: 46276 | I219: 46279 | J219: FATURADO
A220: 17858787 | B220: 117.915 | C220: 109.08 | D220: VIAREGGIO INDUSTRIA & COMERCIO DE | E220: BR19 | F220: CURITIBA | G220: BR_PR | H220: 46276 | I220: 46279 | J220: FATURADO
A221: 17863765 | B221: 196.579 | C221: 190.2 | D221: BAUDELAIRE COOKIES LTDA | E221: BR19 | F221: APUCARANA | G221: BR_PR | H221: 46276 | I221: 46283 | J221: FATURADO
A222: 17863768 | B222: 4340 | C222: 4000 | D222: IBBT INDUSTRIA E COMERCIO DE | E222: BR19 | F222: COLOMBO | G222: BR_PR | H222: 46276 | I222: 46283 | J222: FATURADO
A223: 17863769 | B223: 157.22 | C223: 145.44 | D223: VIAREGGIO INDUSTRIA & COMERCIO DE | E223: BR19 | F223: CURITIBA | G223: BR_PR | H223: 46276 | I223: 46283 | J223: FATURADO
A224: 17867612 | B224: 542.5 | C224: 500 | D224: DEVORATA INDUSTRIA E COMERCIO DE | E224: BR19 | F224: GARIBALDI | G224: BR_RS | H224: 46276 | I224: 46276 | J224: GERAR
A225: 17867613 | B225: 325.5 | C225: 300 | D225: INDUSTRIA DE CHOCOLATES TREZE TILIA | E225: BR19 | F225: TREZE TILIAS | G225: BR_SC | H225: 46276 | I225: 46276 | J225: GERAR
A226: 17867614 | B226: 325.5 | C226: 300 | D226: HAPPS CHOCOLATE | E226: BR19 | F226: BLUMENAU | G226: BR_SC | H226: 46276 | I226: 46276 | J226: GERAR
A227: 17854292 | B227: 74.9 | C227: 70 | D227: DELICATESSEN CATETE EIRELI | E227: BR19 | F227: RIO DE JANEIRO | G227: BR_RJ | H227: 46277 | I227: 46279 | J227: FATURADO
A228: 17854293 | B228: 25.95 | C228: 25 | D228: TATIANE CRISTINE LEMOS AVILA | E228: BR19 | F228: PARATY | G228: BR_RJ | H228: 46277 | I228: 46279 | J228: FATURADO
A229: 17854296 | B229: 129.906 | C229: 126 | D229: ARMAZEM DAS TORTAS COMERCIO DE | E229: BR19 | F229: PETROPOLIS | G229: BR_RJ | H229: 46277 | I229: 46279 | J229: FATURADO
... A987: 17867619 | B987: 428 | C987: 400 | D987: D'LENA ALIMENTOS | E987: BR19 | F987: CONCÓRDIA | G987: BR_SC | H987: 46283 | I987: 46283 | J987: FATURADO
A988: 17867620 | B988: 331.7 | C988: 310 | D988: DELICIA INDUSTRIA E COMERCIO | E988: BR19 | F988: GUARULHOS | H988: 46283 | I988: 46283 | J988: GERAR
A989: 17867621 | B989: 5.925 | C989: 5 | D989: ZANON & DE BORTOLI LTDA ME | E989: BR19 | F989: CRUZ ALTA | G989: BR_RS | H989: 46283 | I989: 46284 | J989: FATURADO
A990: 17867623 | B990: 103.32 | C990: 90 | D990: PAO A MAO COMERCIO DE ALIMENTOS | E990: BR19 | F990: FLORIANÓPOLIS | G990: BR_SC | H990: 46283 | I990: 46283 | J990: FATURADO
A991: 17867624 | B991: 75.402 | C991: 72 | D991: LEILIANE PIETRO BIAZI | E991: BR19 | F991: SANTA HELENA | G991: BR_SC | H991: 46283 | I991: 46283 | J991: FATURADO
A992: 17867626 | B992: 321 | C992: 300 | D992: M3C INDUSTRIA DE ALIMENTOS LTDA | E992: BR19 | F992: DOIS IRMAOS | G992: BR_RS | H992: 46283 | I992: 46284 | J992: FATURADO
A993: 17867628 | B993: 6420 | C993: 6000 | D993: IBBT INDUSTRIA E COMERCIO DE | E993: BR19 | F993: COLOMBO | G993: BR_PR | H993: 46283 | I993: 46283 | J993: FATURADO
A994: 17867629 | B994: 557.5 | C994: 500 | D994: KADY KREM COM PROD ALIM LTDA | E994: BR19 | F994: SAO PAULO | G994: BR_OMX | H994: 46283 | I994: 46283 | J994: GERAR
A995: 17867630 | B995: 204.179 | C995: 193.5 | D995: PORTUA COMERCIO E PRODUCAO | E995: BR19 | F995: MONTENEGRO | G995: BR_RS | H995: 46283 | I995: 46283 | J995: FATURADO
A996: 17867643 | B996: 322.659 | C996: 311 | D996: BRIOCHE DELIVERY LTDA | E996: BR19 | F996: MARINGA | G996: BR_PR | H996: 46283 | I996: 46284 | J996: FATURADO
A997: 17867665 | B997: 97.65 | C997: 90 | D997: CHOCOLATE CASEIRO CAMPOS DO JORDAO | E997: BR19 | F997: CAMPOS DO JORDAO | H997: 46283 | I997: 46283 | J997: GERAR
A998: 17867673 | B998: 104.5 | C998: 100 | D998: DOCE MINAS INDUSTRIA E COMERCIO | E998: BR19 | F998: JUIZ DE FORA | H998: 46283 | I998: 46283 | J998: FATURADO
...

Sheet Dimensionamento
A1: Dimensionamento de Equipe e Capacidade Diária
A2: Premissas informadas pelo usuário + parâmetros de referência para a análise de 09 a 21/09/2026
A4: ESCALA E EQUIPE POR TURNO
A5: Separadores por turno | B5: 4
A6: Operadores por turno | B6: 3
A7: Turnos por dia (12h + 12h) | B7: 2
A8: Horas por turno | B8: 12
A9: Dias trabalhados por ciclo (2x2) | B9: 2
A11: EQUIPE TOTAL EM ATIVIDADE POR DIA (2 turnos)
A12: Separadores instalados / dia | B12: =B5*B7 -> 8 | C12: Separadores/turno x turnos/dia
A13: Operadores instalados / dia | B13: =B6*B7 -> 6 | C13: Operadores/turno x turnos/dia
A14: Total de pessoas em atividade / dia | B14: =B12+B13 -> 14
A16: CAPACIDADE DIÁRIA DE REFERÊNCIA
A17: Capacidade mínima (t/dia) | B17: 35
A18: Capacidade máxima (t/dia) | B18: 40
A19: Capacidade média de referência (t/dia) | B19: =AVERAGE(B17:B18) -> 37.5
A21: PRODUTIVIDADE IMPLÍCITA (referência p/ dimensionar picos)
A22: Produtividade mín. por separador (t/dia) | B22: =B17/B12 -> 4.375
A23: Produtividade máx. por separador (t/dia) | B23: =B18/B12 -> 5 | C23: Capacidade máx. dividida pelos 8 separadores instalados/dia
A24: Produtividade mín. por operador (t/dia) | B24: =B17/B13 -> 5.8333333
A25: Produtividade máx. por operador (t/dia) | B25: =B18/B13 -> 6.6666667
A27: Nota: a "produtividade implícita" é calculada dividindo a capacidade declarada (35–40 t/dia) pela equipe instalada por dia. Ela é usada apenas para estimar quantos separadores adicionais seriam necessários nos dias de pico (aba Analise_Diaria), não é um indicador medido em campo.

Sheet Analise_Diaria
A1: Análise Diária de Volume Bruto x Capacidade (09 a 21/09/2026)
A2: Data-base: "Data do picking" (dia em que a separação do pedido é atribuída). Dias 20 e 21/09 são total ou parcialmente programados (pedidos ainda em "GERAR/FATURAR").
A4: Data | B4: Dia da Semana | C4: Nº Fornecimentos | D4: % Faturado (concluído) | E4: Peso Bruto (kg) | F4: Peso Bruto (t) | G4: Capac. Mín (t) | H4: Capac. Máx (t) | I4: % da Capac. Máx | J4: Status | K4: Separadores Necessários (est.) | L4: Gap de Separadores (est.)
A5: 46274 | B5: =CHOOSE(WEEKDAY(A5),"Domingo","Segunda-feira","Terça-feira","Quarta-feira","Quinta-feira","Sexta-feira","Sábado") -> Quarta-feira | C5: =COUNTIFS(Dados_Filtrados!$H$2:$H$1380,A5) -> 85 | D5: =IFERROR(COUNTIFS(Dados_Filtrados!$H$2:$H$1380,A5,Dados_Filtrados!$J$2:$J$1380,"FATURADO")/C5,0) -> 1 | E5: =SUMIFS(Dados_Filtrados!$B$2:$B$1380,Dados_Filtrados!$H$2:$H$1380,A5) -> 12681.518 | F5: =E5/1000 -> 12.681518 | G5: =Dimensionamento!$B$17 -> 35 | H5: =Dimensionamento!$B$18 -> 40 | I5: =F5/H5 -> 0.31703795 | J5: =IF(F5>H5,"ACIMA DA CAPACIDADE",IF(F5<G5,"ABAIXO DA CAPACIDADE","DENTRO DA FAIXA")) -> ABAIXO DA CAPACIDADE | K5: =F5/Dimensionamento!$B$23 -> 2.5363036 | L5: =K5-Dimensionamento!$B$12 -> -5.4636964
A6: 46275 | B6: =CHOOSE(WEEKDAY(A6),"Domingo","Segunda-feira","Terça-feira","Quarta-feira","Quinta-feira","Sexta-feira","Sábado") -> Quinta-feira | C6: =COUNTIFS(Dados_Filtrados!$H$2:$H$1380,A6) -> 62 | D6: =IFERROR(COUNTIFS(Dados_Filtrados!$H$2:$H$1380,A6,Dados_Filtrados!$J$2:$J$1380,"FATURADO")/C6,0) -> 0.85483871 | E6: =SUMIFS(Dados_Filtrados!$B$2:$B$1380,Dados_Filtrados!$H$2:$H$1380,A6) -> 9523.06 | F6: =E6/1000 -> 9.52306 | G6: =Dimensionamento!$B$17 -> 35 | H6: =Dimensionamento!$B$18 -> 40 | I6: =F6/H6 -> 0.2380765 | J6: =IF(F6>H6,"ACIMA DA CAPACIDADE",IF(F6<G6,"ABAIXO DA CAPACIDADE","DENTRO DA FAIXA")) -> ABAIXO DA CAPACIDADE | K6: =F6/Dimensionamento!$B$23 -> 1.904612 | L6: =K6-Dimensionamento!$B$12 -> -6.095388
A7: 46276 | B7: =CHOOSE(WEEKDAY(A7),"Domingo","Segunda-feira","Terça-feira","Quarta-feira","Quinta-feira","Sexta-feira","Sábado") -> Sexta-feira | C7: =COUNTIFS(Dados_Filtrados!$H$2:$H$1380,A7) -> 78 | D7: =IFERROR(COUNTIFS(Dados_Filtrados!$H$2:$H$1380,A7,Dados_Filtrados!$J$2:$J$1380,"FATURADO")/C7,0) -> 0.94871795 | E7: =SUMIFS(Dados_Filtrados!$B$2:$B$1380,Dados_Filtrados!$H$2:$H$1380,A7) -> 22913.514 | F7: =E7/1000 -> 22.913514 | G7: =Dimensionamento!$B$17 -> 35 | H7: =Dimensionamento!$B$18 -> 40 | I7: =F7/H7 -> 0.57283785 | J7: =IF(F7>H7,"ACIMA DA CAPACIDADE",IF(F7<G7,"ABAIXO DA CAPACIDADE","DENTRO DA FAIXA")) -> ABAIXO DA CAPACIDADE | K7: =F7/Dimensionamento!$B$23 -> 4.5827028 | L7: =K7-Dimensionamento!$B$12 -> -3.4172972
A8: 46277 | B8: =CHOOSE(WEEKDAY(A8),"Domingo","Segunda-feira","Terça-feira","Quarta-feira","Quinta-feira","Sexta-feira","Sábado") -> Sábado | C8: =COUNTIFS(Dados_Filtrados!$H$2:$H$1380,A8) -> 155 | D8: =IFERROR(COUNTIFS(Dados_Filtrados!$H$2:$H$1380,A8,Dados_Filtrados!$J$2:$J$1380,"FATURADO")/C8,0) -> 0.7483871 | E8: =SUMIFS(Dados_Filtrados!$B$2:$B$1380,Dados_Filtrados!$H$2:$H$1380,A8) -> 84129.373 | F8: =E8/1000 -> 84.129373 | G8: =Dimensionamento!$B$17 -> 35 | H8: =Dimensionamento!$B$18 -> 40 | I8: =F8/H8 -> 2.1032343 | J8: =IF(F8>H8,"ACIMA DA CAPACIDADE",IF(F8<G8,"ABAIXO DA CAPACIDADE","DENTRO DA FAIXA")) -> ACIMA DA CAPACIDADE | K8: =F8/Dimensionamento!$B$23 -> 16.825875 | L8: =K8-Dimensionamento!$B$12 -> 8.8258746
A9: 46278 | B9: =CHOOSE(WEEKDAY(A9),"Domingo","Segunda-feira","Terça-feira","Quarta-feira","Quinta-feira","Sexta-feira","Sábado") -> Domingo | C9: =COUNTIFS(Dados_Filtrados!$H$2:$H$1380,A9) -> 4 | D9: =IFERROR(COUNTIFS(Dados_Filtrados!$H$2:$H$1380,A9,Dados_Filtrados!$J$2:$J$1380,"FATURADO")/C9,0) -> 1 | E9: =SUMIFS(Dados_Filtrados!$B$2:$B$1380,Dados_Filtrados!$H$2:$H$1380,A9) -> 627.214 | F9: =E9/1000 -> 0.627214 | G9: =Dimensionamento!$B$17 -> 35 | H9: =Dimensionamento!$B$18 -> 40 | I9: =F9/H9 -> 0.01568035 | J9: =IF(F9>H9,"ACIMA DA CAPACIDADE",IF(F9<G9,"ABAIXO DA CAPACIDADE","DENTRO DA FAIXA")) -> ABAIXO DA CAPACIDADE | K9: =F9/Dimensionamento!$B$23 -> 0.1254428 | L9: =K9-Dimensionamento!$B$12 -> -7.8745572
A10: 46279 | B10: =CHOOSE(WEEKDAY(A10),"Domingo","Segunda-feira","Terça-feira","Quarta-feira","Quinta-feira","Sexta-feira","Sábado") -> Segunda-feira | C10: =COUNTIFS(Dados_Filtrados!$H$2:$H$1380,A10) -> 147 | D10: =IFERROR(COUNTIFS(Dados_Filtrados!$H$2:$H$1380,A10,Dados_Filtrados!$J$2:$J$1380,"FATURADO")/C10,0) -> 0.78911565 | E10: =SUMIFS(Dados_Filtrados!$B$2:$B$1380,Dados_Filtrados!$H$2:$H$1380,A10) -> 127180.13 | F10: =E10/1000 -> 127.18013 | G10: =Dimensionamento!$B$17 -> 35 | H10: =Dimensionamento!$B$18 -> 40 | I10: =F10/H10 -> 3.1795032 | J10: =IF(F10>H10,"ACIMA DA CAPACIDADE",IF(F10<G10,"ABAIXO DA CAPACIDADE","DENTRO DA FAIXA")) -> ACIMA DA CAPACIDADE | K10: =F10/Dimensionamento!$B$23 -> 25.436026 | L10: =K10-Dimensionamento!$B$12 -> 17.436026
A11: 46280 | B11: =CHOOSE(WEEKDAY(A11),"Domingo","Segunda-feira","Terça-feira","Quarta-feira","Quinta-feira","Sexta-feira","Sábado") -> Terça-feira | C11: =COUNTIFS(Dados_Filtrados!$H$2:$H$1380,A11) -> 81 | D11: =IFERROR(COUNTIFS(Dados_Filtrados!$H$2:$H$1380,A11,Dados_Filtrados!$J$2:$J$1380,"FATURADO")/C11,0) -> 0.83950617 | E11: =SUMIFS(Dados_Filtrados!$B$2:$B$1380,Dados_Filtrados!$H$2:$H$1380,A11) -> 68043 | F11: =E11/1000 -> 68.043 | G11: =Dimensionamento!$B$17 -> 35 | H11: =Dimensionamento!$B$18 -> 40 | I11: =F11/H11 -> 1.701075 | J11: =IF(F11>H11,"ACIMA DA CAPACIDADE",IF(F11<G11,"ABAIXO DA CAPACIDADE","DENTRO DA FAIXA")) -> ACIMA DA CAPACIDADE | K11: =F11/Dimensionamento!$B$23 -> 13.6086 | L11: =K11-Dimensionamento!$B$12 -> 5.6086
A12: 46281 | B12: =CHOOSE(WEEKDAY(A12),"Domingo","Segunda-feira","Terça-feira","Quarta-feira","Quinta-feira","Sexta-feira","Sábado") -> Quarta-feira | C12: =COUNTIFS(Dados_Filtrados!$H$2:$H$1380,A12) -> 217 | D12: =IFERROR(COUNTIFS(Dados_Filtrados!$H$2:$H$1380,A12,Dados_Filtrados!$J$2:$J$1380,"FATURADO")/C12,0) -> 0.88940092 | E12: =SUMIFS(Dados_Filtrados!$B$2:$B$1380,Dados_Filtrados!$H$2:$H$1380,A12) -> 47813.547 | F12: =E12/1000 -> 47.813547 | G12: =Dimensionamento!$B$17 -> 35 | H12: =Dimensionamento!$B$18 -> 40 | I12: =F12/H12 -> 1.1953387 | J12: =IF(F12>H12,"ACIMA DA CAPACIDADE",IF(F12<G12,"ABAIXO DA CAPACIDADE","DENTRO DA FAIXA")) -> ACIMA DA CAPACIDADE | K12: =F12/Dimensionamento!$B$23 -> 9.5627094 | L12: =K12-Dimensionamento!$B$12 -> 1.5627094
A13: 46282 | B13: =CHOOSE(WEEKDAY(A13),"Domingo","Segunda-feira","Terça-feira","Quarta-feira","Quinta-feira","Sexta-feira","Sábado") -> Quinta-feira | C13: =COUNTIFS(Dados_Filtrados!$H$2:$H$1380,A13) -> 60 | D13: =IFERROR(COUNTIFS(Dados_Filtrados!$H$2:$H$1380,A13,Dados_Filtrados!$J$2:$J$1380,"FATURADO")/C13,0) -> 0.95 | E13: =SUMIFS(Dados_Filtrados!$B$2:$B$1380,Dados_Filtrados!$H$2:$H$1380,A13) -> 51929.111 | F13: =E13/1000 -> 51.929111 | G13: =Dimensionamento!$B$17 -> 35 | H13: =Dimensionamento!$B$18 -> 40 | I13: =F13/H13 -> 1.2982278 | J13: =IF(F13>H13,"ACIMA DA CAPACIDADE",IF(F13<G13,"ABAIXO DA CAPACIDADE","DENTRO DA FAIXA")) -> ACIMA DA CAPACIDADE | K13: =F13/Dimensionamento!$B$23 -> 10.385822 | L13: =K13-Dimensionamento!$B$12 -> 2.3858222
A14: 46283 | B14: =CHOOSE(WEEKDAY(A14),"Domingo","Segunda-feira","Terça-feira","Quarta-feira","Quinta-feira","Sexta-feira","Sábado") -> Sexta-feira | C14: =COUNTIFS(Dados_Filtrados!$H$2:$H$1380,A14) -> 138 | D14: =IFERROR(COUNTIFS(Dados_Filtrados!$H$2:$H$1380,A14,Dados_Filtrados!$J$2:$J$1380,"FATURADO")/C14,0) -> 0.79710145 | E14: =SUMIFS(Dados_Filtrados!$B$2:$B$1380,Dados_Filtrados!$H$2:$H$1380,A14) -> 59660.811 | F14: =E14/1000 -> 59.660811 | G14: =Dimensionamento!$B$17 -> 35 | H14: =Dimensionamento!$B$18 -> 40 | I14: =F14/H14 -> 1.4915203 | J14: =IF(F14>H14,"ACIMA DA CAPACIDADE",IF(F14<G14,"ABAIXO DA CAPACIDADE","DENTRO DA FAIXA")) -> ACIMA DA CAPACIDADE | K14: =F14/Dimensionamento!$B$23 -> 11.932162 | L14: =K14-Dimensionamento!$B$12 -> 3.9321622
A15: 46284 | B15: =CHOOSE(WEEKDAY(A15),"Domingo","Segunda-feira","Terça-feira","Quarta-feira","Quinta-feira","Sexta-feira","Sábado") -> Sábado | C15: =COUNTIFS(Dados_Filtrados!$H$2:$H$1380,A15) -> 278 | D15: =IFERROR(COUNTIFS(Dados_Filtrados!$H$2:$H$1380,A15,Dados_Filtrados!$J$2:$J$1380,"FATURADO")/C15,0) -> 0.032374101 | E15: =SUMIFS(Dados_Filtrados!$B$2:$B$1380,Dados_Filtrados!$H$2:$H$1380,A15) -> 91750.186 | F15: =E15/1000 -> 91.750186 | G15: =Dimensionamento!$B$17 -> 35 | H15: =Dimensionamento!$B$18 -> 40 | I15: =F15/H15 -> 2.2937546 | J15: =IF(F15>H15,"ACIMA DA CAPACIDADE",IF(F15<G15,"ABAIXO DA CAPACIDADE","DENTRO DA FAIXA")) -> ACIMA DA CAPACIDADE | K15: =F15/Dimensionamento!$B$23 -> 18.350037 | L15: =K15-Dimensionamento!$B$12 -> 10.350037
A16: 46285 | B16: =CHOOSE(WEEKDAY(A16),"Domingo","Segunda-feira","Terça-feira","Quarta-feira","Quinta-feira","Sexta-feira","Sábado") -> Domingo | C16: =COUNTIFS(Dados_Filtrados!$H$2:$H$1380,A16) -> 24 | D16: =IFERROR(COUNTIFS(Dados_Filtrados!$H$2:$H$1380,A16,Dados_Filtrados!$J$2:$J$1380,"FATURADO")/C16,0) -> 0.41666667 | E16: =SUMIFS(Dados_Filtrados!$B$2:$B$1380,Dados_Filtrados!$H$2:$H$1380,A16) -> 3840.874 | F16: =E16/1000 -> 3.840874 | G16: =Dimensionamento!$B$17 -> 35 | H16: =Dimensionamento!$B$18 -> 40 | I16: =F16/H16 -> 0.09602185 | J16: =IF(F16>H16,"ACIMA DA CAPACIDADE",IF(F16<G16,"ABAIXO DA CAPACIDADE","DENTRO DA FAIXA")) -> ABAIXO DA CAPACIDADE | K16: =F16/Dimensionamento!$B$23 -> 0.7681748 | L16: =K16-Dimensionamento!$B$12 -> -7.2318252
A17: 46286 | B17: =CHOOSE(WEEKDAY(A17),"Domingo","Segunda-feira","Terça-feira","Quarta-feira","Quinta-feira","Sexta-feira","Sábado") -> Segunda-feira | C17: =COUNTIFS(Dados_Filtrados!$H$2:$H$1380,A17) -> 50 | D17: =IFERROR(COUNTIFS(Dados_Filtrados!$H$2:$H$1380,A17,Dados_Filtrados!$J$2:$J$1380,"FATURADO")/C17,0) -> 0.48 | E17: =SUMIFS(Dados_Filtrados!$B$2:$B$1380,Dados_Filtrados!$H$2:$H$1380,A17) -> 6780.298 | F17: =E17/1000 -> 6.780298 | G17: =Dimensionamento!$B$17 -> 35 | H17: =Dimensionamento!$B$18 -> 40 | I17: =F17/H17 -> 0.16950745 | J17: =IF(F17>H17,"ACIMA DA CAPACIDADE",IF(F17<G17,"ABAIXO DA CAPACIDADE","DENTRO DA FAIXA")) -> ABAIXO DA CAPACIDADE | K17: =F17/Dimensionamento!$B$23 -> 1.3560596 | L17: =K17-Dimensionamento!$B$12 -> -6.6439404
A18: TOTAL / MÉDIA | C18: =SUM(C5:C17) -> 1379 | E18: =SUM(E5:E17) -> 586872.64 | F18: =SUM(F5:F17) -> 586.87264 | I18: =AVERAGE(I5:I17) -> 1.1286012
