Workbook

Sheet Painel
A1: Painel ZBR Importado | R1: =IF(A5="Todos","*",A5) -> * | AS1: Todos | AU1: 46274 | AV1: Todos | AW1: 2665-E4-U71 | AX1: 252800202 | AY1: =IF(OR($A$5="Todos",AW1=$A$5),1,0) -> 1 | AZ1: KG | BA1: Todas
A2: Entradas, saídas e estoque físico por SKU e lote · centro BR01 · movimentos de 09/09 a 01/10/2026 | R2: =IF(OR(D5="Todos",D5=""),"*",D5) -> * | AS2: 2665-E4-U71 | AU2: 46275 | AV2: =IFERROR(INDEX($AX$1:$AX$94,MATCH(1,$AY$1:$AY$94,0)),"") -> 252800202 | AW2: 70-30-38-BR-25A | AX2: 260070301 | AY2: =IF(OR($A$5="Todos",AW2=$A$5),MAX(AY$1:AY1)+1,0) -> 2 | AZ2: UN | BA2: Entrada
R3: =IF(A5="Todos",J5,IFERROR(INDEX($U$40:$U$133,MATCH(A5,$T$40:$T$133,0)),J5)) -> KG | AS3: 70-30-38-BR-25A | AU3: 46276 | AV3: =IFERROR(INDEX($AX$1:$AX$94,MATCH(2,$AY$1:$AY$94,0)),"") -> 260070301 | AW3: 70-30-38-BR-25A | AX3: 260370301 | AY3: =IF(OR($A$5="Todos",AW3=$A$5),MAX(AY$1:AY2)+1,0) -> 3 | AZ3: CX | BA3: Saída
A4: SKU | D4: LOTE | F4: DATA INICIAL | H4: DATA FINAL | J4: UNIDADE | K4: MOVIMENTAÇÃO | R4: =IF(K5="Entrada","Entrada",IF(K5="Saída","Saída",IF(K5="Recebido no 2008","Recebido no 2008",IF(K5="Estorno","Estorno","*")))) -> * | AS4: 70-30-38-BR-D94 | AU4: 46277 | AV4: =IFERROR(INDEX($AX$1:$AX$94,MATCH(3,$AY$1:$AY$94,0)),"") -> 260370301 | AW4: 70-30-38-BR-D94 | AX4: 253213449 | AY4: =IF(OR($A$5="Todos",AW4=$A$5),MAX(AY$1:AY3)+1,0) -> 4 | BA4: Recebido no 2008
A5: Todos | D5: Todos | F5: 46274 | H5: 46296 | J5: KG | K5: Todas | R5: =Resumo!$C$7 -> 0.01 | AS5: 805-BR-D94 | AU5: 46278 | AV5: =IFERROR(INDEX($AX$1:$AX$94,MATCH(4,$AY$1:$AY$94,0)),"") -> 253213449 | AW5: 805-BR-D94 | AX5: 251633359 | AY5: =IF(OR($A$5="Todos",AW5=$A$5),MAX(AY$1:AY4)+1,0) -> 5 | BA5: Estorno
A6: ▼ Filtros: clique numa célula azul e depois na seta que aparece ao lado para escolher. “Todos” mostra tudo. A lista de lotes mostra só os lotes do SKU escolhido. | AS6: 811-BR-25A | AU6: 46279 | AV6: =IFERROR(INDEX($AX$1:$AX$94,MATCH(5,$AY$1:$AY$94,0)),"") -> 251633359 | AW6: 805-BR-D94 | AX6: 260130779 | AY6: =IF(OR($A$5="Todos",AW6=$A$5),MAX(AY$1:AY5)+1,0) -> 6
A7: ="Mostrando: "&IF(A5="Todos","todos os SKUs",A5)&IF(D5="Todos",""," · lote "&D5)&" · "&DAY(F5)&"/"&MONTH(F5)&"/"&YEAR(F5)&" a "&DAY(H5)&"/"&MONTH(H5)&"/"&YEAR(H5)&" · unidade "&$R$3&IF(K5="Todas",""," · movimentação "&K5) -> Mostrando: todos os SKUs · 9/9/2026 a 1/10/2026 · unidade KG | AS7: 811-BR-D94 | AU7: 46280 | AV7: =IFERROR(INDEX($AX$1:$AX$94,MATCH(6,$AY$1:$AY$94,0)),"") -> 260130779 | AW7: 811-BR-25A | AX7: 250880301 | AY7: =IF(OR($A$5="Todos",AW7=$A$5),MAX(AY$1:AY6)+1,0) -> 7
AS8: 811NV-132 | AU8: 46281 | AV8: =IFERROR(INDEX($AX$1:$AX$94,MATCH(7,$AY$1:$AY$94,0)),"") -> 250880301 | AW8: 811-BR-25A | AX8: 252450301 | AY8: =IF(OR($A$5="Todos",AW8=$A$5),MAX(AY$1:AY7)+1,0) -> 8
A9: ="ENTROU · "&$R$3 -> ENTROU · KG | C9: ="SAIU · "&$R$3 -> SAIU · KG | F9: ="DEVERIA TER · "&$R$3 -> DEVERIA TER · KG | H9: ="ESTOQUE FÍSICO · "&$R$3 -> ESTOQUE FÍSICO · KG | J9: ="DIFERENÇA · "&$R$3 -> DIFERENÇA · KG | L9: ="Confere: "&COUNTIFS($AA$40:$AA$133,1,$AC$40:$AC$133,"Confere")&" SKU·lote" -> Confere: 58 SKU·lote | AS9: 811NV-595 | AU9: 46282 | AV9: =IFERROR(INDEX($AX$1:$AX$94,MATCH(8,$AY$1:$AY$94,0)),"") -> 252450301 | AW9: 811-BR-D94 | AX9: 251643289 | AY9: =IF(OR($A$5="Todos",AW9=$A$5),MAX(AY$1:AY8)+1,0) -> 9
A10: =SUMPRODUCT($AA$40:$AA$133,$W$40:$W$133) -> 65930.28 | C10: =SUMPRODUCT($AA$40:$AA$133,$X$40:$X$133) -> 26268.8 | F10: =A10-C10 -> 39661.48 | H10: =SUMPRODUCT($AA$40:$AA$133,$Y$40:$Y$133) -> 59270.487 | J10: =ROUND(H10-F10,3) -> 19609.007 | L10: ="Sobrando: "&COUNTIFS($AA$40:$AA$133,1,$AC$40:$AC$133,"Sobrando")&" SKU·lote" -> Sobrando: 20 SKU·lote | AS10: 823-BR-25A | AU10: 46283 | AV10: =IFERROR(INDEX($AX$1:$AX$94,MATCH(9,$AY$1:$AY$94,0)),"") -> 251643289 | AW10: 811NV-132 | AX10: 252510301 | AY10: =IF(OR($A$5="Todos",AW10=$A$5),MAX(AY$1:AY9)+1,0) -> 10
A11: transferido do 2008 para o ZBR | C11: vendas e entregas | F11: entrou − saiu | H11: o que tem no depósito hoje | J11: =IF(OR(F5<>DATE(2026,9,9),H5<>DATE(2026,10,1)),"período parcial: compare com cuidado",IF(ABS(J10)<=$R$5,"tudo confere",IF(J10>0,"sobrando no estoque","faltando no estoque"))) -> sobrando no estoque | L11: ="Faltando: "&COUNTIFS($AA$40:$AA$133,1,$AC$40:$AC$133,"Faltando")&" SKU·lote" -> Faltando: 3 SKU·lote | AS11: 823-BR-D94 | AU11: 46284 | AV11: =IFERROR(INDEX($AX$1:$AX$94,MATCH(10,$AY$1:$AY$94,0)),"") -> 252510301 | AW11: 811NV-132 | AX11: 253280301 | AY11: =IF(OR($A$5="Todos",AW11=$A$5),MAX(AY$1:AY10)+1,0) -> 11
AS12: 823NV-132 | AU12: 46285 | AV12: =IFERROR(INDEX($AX$1:$AX$94,MATCH(11,$AY$1:$AY$94,0)),"") -> 253280301 | AW12: 811NV-595 | AX12: 260900702 | AY12: =IF(OR($A$5="Todos",AW12=$A$5),MAX(AY$1:AY11)+1,0) -> 12
A13: Movimentação por dia | G13: Maiores diferenças | AS13: 823NV-595 | AU13: 46286 | AV13: =IFERROR(INDEX($AX$1:$AX$94,MATCH(12,$AY$1:$AY$94,0)),"") -> 260900702 | AW13: 811NV-595 | AX13: 260920702 | AY13: =IF(OR($A$5="Todos",AW13=$A$5),MAX(AY$1:AY12)+1,0) -> 13
A14: Azul: entrou no ZBR · Laranja: saiu (abaixo de zero). Recebimentos no 2008 ficam fora. | G14: Por SKU · lote. Diferença = estoque físico − (entrou − saiu). Amarelo: sobrando · Vermelho: faltando. | AS14: BIG-PF-1BO-401 | AU14: 46287 | AV14: =IFERROR(INDEX($AX$1:$AX$94,MATCH(13,$AY$1:$AY$94,0)),"") -> 260920702 | AW14: 811NV-595 | AX14: 261146101 | AY14: =IF(OR($A$5="Todos",AW14=$A$5),MAX(AY$1:AY13)+1,0) -> 14
AS15: CHD-BB-308BY-357 | AU15: 46288 | AV15: =IFERROR(INDEX($AX$1:$AX$94,MATCH(14,$AY$1:$AY$94,0)),"") -> 261146101 | AW15: 811NV-595 | AX15: 261146102 | AY15: =IF(OR($A$5="Todos",AW15=$A$5),MAX(AY$1:AY14)+1,0) -> 15
AS16: CHD-DR-75Y5-E1-U68 | AU16: 46289 | AV16: =IFERROR(INDEX($AX$1:$AX$94,MATCH(15,$AY$1:$AY$94,0)),"") -> 261146102 | AW16: 823-BR-25A | AX16: 252100301 | AY16: =IF(OR($A$5="Todos",AW16=$A$5),MAX(AY$1:AY15)+1,0) -> 16
AS17: CHD-SP-1M-2B-U77 | AU17: 46290 | AV17: =IFERROR(INDEX($AX$1:$AX$94,MATCH(16,$AY$1:$AY$94,0)),"") -> 252100301 | AW17: 823-BR-25A | AX17: 252900303 | AY17: =IF(OR($A$5="Todos",AW17=$A$5),MAX(AY$1:AY16)+1,0) -> 17
AS18: CHD-SP-1M-BR-U73 | AU18: 46291 | AV18: =IFERROR(INDEX($AX$1:$AX$94,MATCH(17,$AY$1:$AY$94,0)),"") -> 252900303 | AW18: 823-BR-25A | AX18: 252940301 | AY18: =IF(OR($A$5="Todos",AW18=$A$5),MAX(AY$1:AY17)+1,0) -> 18
AS19: CHD-SP-9Z4-BR-U73 | AU19: 46292 | AV19: =IFERROR(INDEX($AX$1:$AX$94,MATCH(18,$AY$1:$AY$94,0)),"") -> 252940301 | AW19: 823-BR-D94 | AX19: 252103049 | AY19: =IF(OR($A$5="Todos",AW19=$A$5),MAX(AY$1:AY18)+1,0) -> 19
AS20: CHD-TS-22350E0-999 | AU20: 46293 | AV20: =IFERROR(INDEX($AX$1:$AX$94,MATCH(19,$AY$1:$AY$94,0)),"") -> 252103049 | AW20: 823NV-132 | AX20: 260880201 | AY20: =IF(OR($A$5="Todos",AW20=$A$5),MAX(AY$1:AY19)+1,0) -> 20
AS21: CHD-VR-Z2S-E0-U68 | AU21: 46294 | AV21: =IFERROR(INDEX($AX$1:$AX$94,MATCH(20,$AY$1:$AY$94,0)),"") -> 260880201 | AW21: 823NV-595 | AX21: 260416102 | AY21: =IF(OR($A$5="Todos",AW21=$A$5),MAX(AY$1:AY20)+1,0) -> 21
AS22: CHK-D-413 | AU22: 46295 | AV22: =IFERROR(INDEX($AX$1:$AX$94,MATCH(21,$AY$1:$AY$94,0)),"") -> 260416102 | AW22: 823NV-595 | AX22: 261376101 | AY22: =IF(OR($A$5="Todos",AW22=$A$5),MAX(AY$1:AY21)+1,0) -> 22
AS23: CHK-R30GOLD-BR-25A | AU23: 46296 | AV23: =IFERROR(INDEX($AX$1:$AX$94,MATCH(22,$AY$1:$AY$94,0)),"") -> 261376101 | AW23: BIG-PF-1BO-401 | AX23: 26044019 | AY23: =IF(OR($A$5="Todos",AW23=$A$5),MAX(AY$1:AY22)+1,0) -> 23
AS24: CHK-R30GOLD-E0-D94 | AV24: =IFERROR(INDEX($AX$1:$AX$94,MATCH(23,$AY$1:$AY$94,0)),"") -> 26044019 | AW24: BIG-PF-1BO-401 | AX24: 26093039 | AY24: =IF(OR($A$5="Todos",AW24=$A$5),MAX(AY$1:AY23)+1,0) -> 24
AS25: CHK-W-413 | AV25: =IFERROR(INDEX($AX$1:$AX$94,MATCH(24,$AY$1:$AY$94,0)),"") -> 26093039 | AW25: BIG-PF-1BO-401 | AX25: 26126039 | AY25: =IF(OR($A$5="Todos",AW25=$A$5),MAX(AY$1:AY24)+1,0) -> 25
AS26: CHM-BS-9U15-E0-07B | AV26: =IFERROR(INDEX($AX$1:$AX$94,MATCH(25,$AY$1:$AY$94,0)),"") -> 26126039 | AW26: CHD-BB-308BY-357 | AX26: 250827800 | AY26: =IF(OR($A$5="Todos",AW26=$A$5),MAX(AY$1:AY25)+1,0) -> 26
AS27: CHM-CU-7X80-E5-U70 | AV27: =IFERROR(INDEX($AX$1:$AX$94,MATCH(26,$AY$1:$AY$94,0)),"") -> 250827800 | AW27: CHD-BB-308BY-357 | AX27: 2529678000 | AY27: =IF(OR($A$5="Todos",AW27=$A$5),MAX(AY$1:AY26)+1,0) -> 27
AS28: CHM-Q41ALUN-2B-U73 | AV28: =IFERROR(INDEX($AX$1:$AX$94,MATCH(27,$AY$1:$AY$94,0)),"") -> 2529678000 | AW28: CHD-BB-308BY-357 | AX28: 2529778000 | AY28: =IF(OR($A$5="Todos",AW28=$A$5),MAX(AY$1:AY27)+1,0) -> 28
AS29: CHM-SP-Z3L-BR-U73 | AV29: =IFERROR(INDEX($AX$1:$AX$94,MATCH(28,$AY$1:$AY$94,0)),"") -> 2529778000 | AW29: CHD-BB-308BY-357 | AX29: 2609078000 | AY29: =IF(OR($A$5="Todos",AW29=$A$5),MAX(AY$1:AY28)+1,0) -> 29
AS30: CHM-SP-Z3L-E0-U72 | AV30: =IFERROR(INDEX($AX$1:$AX$94,MATCH(29,$AY$1:$AY$94,0)),"") -> 2609078000 | AW30: CHD-BB-308BY-357 | AX30: 2609178000 | AY30: =IF(OR($A$5="Todos",AW30=$A$5),MAX(AY$1:AY29)+1,0) -> 30
AS31: CHM-TS-22351E0-999 | AV31: =IFERROR(INDEX($AX$1:$AX$94,MATCH(30,$AY$1:$AY$94,0)),"") -> 2609178000 | AW31: CHD-BB-308BY-357 | AX31: 2611378000 | AY31: =IF(OR($A$5="Todos",AW31=$A$5),MAX(AY$1:AY30)+1,0) -> 31
A32: Cruzamento por SKU e lote | E32: =COUNT($AB$40:$AB$133)&" linhas no filtro atual" -> 81 linhas no filtro atual | AS32: CHM-TS-P23-E0-999 | AV32: =IFERROR(INDEX($AX$1:$AX$94,MATCH(31,$AY$1:$AY$94,0)),"") -> 2611378000 | AW32: CHD-DR-75Y5-E1-U68 | AX32: 252810301 | AY32: =IF(OR($A$5="Todos",AW32=$A$5),MAX(AY$1:AY31)+1,0) -> 32
A33: SKU | B33: LOTE | C33: UM | D33: RECEBIDO 2008 | E33: ENTROU | F33: SAIU | G33: DEVERIA TER | H33: ESTOQUE FÍSICO | I33: DIFERENÇA | J33: SITUAÇÃO | K33: LANÇAMENTOS | L33: DESCRIÇÃO | AS33: CHM-VR-Z3S-E0-U68 | AV33: =IFERROR(INDEX($AX$1:$AX$94,MATCH(32,$AY$1:$AY$94,0)),"") -> 252810301 | AW33: CHD-SP-1M-2B-U77 | AX33: 260880101 | AY33: =IF(OR($A$5="Todos",AW33=$A$5),MAX(AY$1:AY32)+1,0) -> 33
A34: =IF(IFERROR(MATCH(1,$AB$40:$AB$133,0),0)=0,"",INDEX($T$40:$T$133,IFERROR(MATCH(1,$AB$40:$AB$133,0),0))) -> CHK-R30GOLD-BR-25A | B34: =IF(IFERROR(MATCH(1,$AB$40:$AB$133,0),0)=0,"",INDEX($AG$40:$AG$133,IFERROR(MATCH(1,$AB$40:$AB$133,0),0))) -> 261130301 | C34: =IF(IFERROR(MATCH(1,$AB$40:$AB$133,0),0)=0,"",INDEX($U$40:$U$133,IFERROR(MATCH(1,$AB$40:$AB$133,0),0))) -> KG | D34: =IF(IFERROR(MATCH(1,$AB$40:$AB$133,0),0)=0,"",INDEX($V$40:$V$133,IFERROR(MATCH(1,$AB$40:$AB$133,0),0))) -> 1025.1 | E34: =IF(IFERROR(MATCH(1,$AB$40:$AB$133,0),0)=0,"",INDEX($W$40:$W$133,IFERROR(MATCH(1,$AB$40:$AB$133,0),0))) -> 2673.3 | F34: =IF(IFERROR(MATCH(1,$AB$40:$AB$133,0),0)=0,"",INDEX($X$40:$X$133,IFERROR(MATCH(1,$AB$40:$AB$133,0),0))) -> 1005 | G34: =IF(A34="","",E34-F34) -> 1668.3 | H34: =IF(IFERROR(MATCH(1,$AB$40:$AB$133,0),0)=0,"",INDEX($Y$40:$Y$133,IFERROR(MATCH(1,$AB$40:$AB$133,0),0))) -> 1226.1 | I34: =IF(IFERROR(MATCH(1,$AB$40:$AB$133,0),0)=0,"",INDEX($Z$40:$Z$133,IFERROR(MATCH(1,$AB$40:$AB$133,0),0))) -> -442.2 | J34: =IF(IFERROR(MATCH(1,$AB$40:$AB$133,0),0)=0,"",INDEX($AC$40:$AC$133,IFERROR(MATCH(1,$AB$40:$AB$133,0),0))) -> Faltando | K34: =IF(IFERROR(MATCH(1,$AB$40:$AB$133,0),0)=0,"",INDEX($AD$40:$AD$133,IFERROR(MATCH(1,$AB$40:$AB$133,0),0))) -> 17 | L34: =IF(IFERROR(MATCH(1,$AB$40:$AB$133,0),0)=0,"",INDEX($AE$40:$AE$133,IFERROR(MATCH(1,$AB$40:$AB$133,0),0))&"") -> CA MOEDAS 2,01KG/UC 10UC/CX 30CX/PAL | AS34: CHM-VR-Z3S-E0-U72 | AV34: =IFERROR(INDEX($AX$1:$AX$94,MATCH(33,$AY$1:$AY$94,0)),"") -> 260880101 | AW34: CHD-SP-1M-BR-U73 | AX34: 260310301 | AY34: =IF(OR($A$5="Todos",AW34=$A$5),MAX(AY$1:AY33)+1,0) -> 34
A35: =IF(IFERROR(MATCH(2,$AB$40:$AB$133,0),0)=0,"",INDEX($T$40:$T$133,IFERROR(MATCH(2,$AB$40:$AB$133,0),0))) -> CHM-TS-P23-E0-999 | B35: =IF(IFERROR(MATCH(2,$AB$40:$AB$133,0),0)=0,"",INDEX($AG$40:$AG$133,IFERROR(MATCH(2,$AB$40:$AB$133,0),0))) -> 2605567696 | C35: =IF(IFERROR(MATCH(2,$AB$40:$AB$133,0),0)=0,"",INDEX($U$40:$U$133,IFERROR(MATCH(2,$AB$40:$AB$133,0),0))) -> KG | D35: =IF(IFERROR(MATCH(2,$AB$40:$AB$133,0),0)=0,"",INDEX($V$40:$V$133,IFERROR(MATCH(2,$AB$40:$AB$133,0),0))) -> 0 | E35: =IF(IFERROR(MATCH(2,$AB$40:$AB$133,0),0)=0,"",INDEX($W$40:$W$133,IFERROR(MATCH(2,$AB$40:$AB$133,0),0))) -> 261.12 | F35: =IF(IFERROR(MATCH(2,$AB$40:$AB$133,0),0)=0,"",INDEX($X$40:$X$133,IFERROR(MATCH(2,$AB$40:$AB$133,0),0))) -> 0 | G35: =IF(A35="","",E35-F35) -> 261.12 | H35: =IF(IFERROR(MATCH(2,$AB$40:$AB$133,0),0)=0,"",INDEX($Y$40:$Y$133,IFERROR(MATCH(2,$AB$40:$AB$133,0),0))) -> 0 | I35: =IF(IFERROR(MATCH(2,$AB$40:$AB$133,0),0)=0,"",INDEX($Z$40:$Z$133,IFERROR(MATCH(2,$AB$40:$AB$133,0),0))) -> -261.12 | J35: =IF(IFERROR(MATCH(2,$AB$40:$AB$133,0),0)=0,"",INDEX($AC$40:$AC$133,IFERROR(MATCH(2,$AB$40:$AB$133,0),0))) -> Faltando | K35: =IF(IFERROR(MATCH(2,$AB$40:$AB$133,0),0)=0,"",INDEX($AD$40:$AD$133,IFERROR(MATCH(2,$AB$40:$AB$133,0),0))) -> 1 | L35: =IF(IFERROR(MATCH(2,$AB$40:$AB$133,0),0)=0,"",INDEX($AE$40:$AE$133,IFERROR(MATCH(2,$AB$40:$AB$133,0),0))&"") | AS35: CHP-20SICHP-760 | AV35: =IFERROR(INDEX($AX$1:$AX$94,MATCH(34,$AY$1:$AY$94,0)),"") -> 260310301 | AW35: CHD-SP-1M-BR-U73 | AX35: 260880301 | AY35: =IF(OR($A$5="Todos",AW35=$A$5),MAX(AY$1:AY34)+1,0) -> 35
A36: =IF(IFERROR(MATCH(3,$AB$40:$AB$133,0),0)=0,"",INDEX($T$40:$T$133,IFERROR(MATCH(3,$AB$40:$AB$133,0),0))) -> BIG-PF-1BO-401 | B36: =IF(IFERROR(MATCH(3,$AB$40:$AB$133,0),0)=0,"",INDEX($AG$40:$AG$133,IFERROR(MATCH(3,$AB$40:$AB$133,0),0))) -> 26044019 | C36: =IF(IFERROR(MATCH(3,$AB$40:$AB$133,0),0)=0,"",INDEX($U$40:$U$133,IFERROR(MATCH(3,$AB$40:$AB$133,0),0))) -> KG | D36: =IF(IFERROR(MATCH(3,$AB$40:$AB$133,0),0)=0,"",INDEX($V$40:$V$133,IFERROR(MATCH(3,$AB$40:$AB$133,0),0))) -> 0 | E36: =IF(IFERROR(MATCH(3,$AB$40:$AB$133,0),0)=0,"",INDEX($W$40:$W$133,IFERROR(MATCH(3,$AB$40:$AB$133,0),0))) -> 480 | F36: =IF(IFERROR(MATCH(3,$AB$40:$AB$133,0),0)=0,"",INDEX($X$40:$X$133,IFERROR(MATCH(3,$AB$40:$AB$133,0),0))) -> 60 | G36: =IF(A36="","",E36-F36) -> 420 | H36: =IF(IFERROR(MATCH(3,$AB$40:$AB$133,0),0)=0,"",INDEX($Y$40:$Y$133,IFERROR(MATCH(3,$AB$40:$AB$133,0),0))) -> 210 | I36: =IF(IFERROR(MATCH(3,$AB$40:$AB$133,0),0)=0,"",INDEX($Z$40:$Z$133,IFERROR(MATCH(3,$AB$40:$AB$133,0),0))) -> -210 | J36: =IF(IFERROR(MATCH(3,$AB$40:$AB$133,0),0)=0,"",INDEX($AC$40:$AC$133,IFERROR(MATCH(3,$AB$40:$AB$133,0),0))) -> Faltando | K36: =IF(IFERROR(MATCH(3,$AB$40:$AB$133,0),0)=0,"",INDEX($AD$40:$AD$133,IFERROR(MATCH(3,$AB$40:$AB$133,0),0))) -> 5 | L36: =IF(IFERROR(MATCH(3,$AB$40:$AB$133,0),0)=0,"",INDEX($AE$40:$AE$133,IFERROR(MATCH(3,$AB$40:$AB$133,0),0))&"") -> CB PAILLETÉ FEUILLETINE 2.5KG/UC 4UC/BOX | AS36: CHR-Q37RB2-2B-U75 | AV36: =IFERROR(INDEX($AX$1:$AX$94,MATCH(35,$AY$1:$AY$94,0)),"") -> 260880301 | AW36: CHD-SP-9Z4-BR-U73 | AX36: 250500301 | AY36: =IF(OR($A$5="Todos",AW36=$A$5),MAX(AY$1:AY35)+1,0) -> 36
A37: =IF(IFERROR(MATCH(4,$AB$40:$AB$133,0),0)=0,"",INDEX($T$40:$T$133,IFERROR(MATCH(4,$AB$40:$AB$133,0),0))) -> 811-BR-D94 | B37: =IF(IFERROR(MATCH(4,$AB$40:$AB$133,0),0)=0,"",INDEX($AG$40:$AG$133,IFERROR(MATCH(4,$AB$40:$AB$133,0),0))) -> 251643289 | C37: =IF(IFERROR(MATCH(4,$AB$40:$AB$133,0),0)=0,"",INDEX($U$40:$U$133,IFERROR(MATCH(4,$AB$40:$AB$133,0),0))) -> KG | D37: =IF(IFERROR(MATCH(4,$AB$40:$AB$133,0),0)=0,"",INDEX($V$40:$V$133,IFERROR(MATCH(4,$AB$40:$AB$133,0),0))) -> 0 | E37: =IF(IFERROR(MATCH(4,$AB$40:$AB$133,0),0)=0,"",INDEX($W$40:$W$133,IFERROR(MATCH(4,$AB$40:$AB$133,0),0))) -> 2.8 | F37: =IF(IFERROR(MATCH(4,$AB$40:$AB$133,0),0)=0,"",INDEX($X$40:$X$133,IFERROR(MATCH(4,$AB$40:$AB$133,0),0))) -> 226.8 | G37: =IF(A37="","",E37-F37) -> -224 | H37: =IF(IFERROR(MATCH(4,$AB$40:$AB$133,0),0)=0,"",INDEX($Y$40:$Y$133,IFERROR(MATCH(4,$AB$40:$AB$133,0),0))) -> 5513.2 | I37: =IF(IFERROR(MATCH(4,$AB$40:$AB$133,0),0)=0,"",INDEX($Z$40:$Z$133,IFERROR(MATCH(4,$AB$40:$AB$133,0),0))) -> 5737.2 | J37: =IF(IFERROR(MATCH(4,$AB$40:$AB$133,0),0)=0,"",INDEX($AC$40:$AC$133,IFERROR(MATCH(4,$AB$40:$AB$133,0),0))) -> Sobrando | K37: =IF(IFERROR(MATCH(4,$AB$40:$AB$133,0),0)=0,"",INDEX($AD$40:$AD$133,IFERROR(MATCH(4,$AB$40:$AB$133,0),0))) -> 17 | L37: =IF(IFERROR(MATCH(4,$AB$40:$AB$133,0),0)=0,"",INDEX($AE$40:$AE$133,IFERROR(MATCH(4,$AB$40:$AB$133,0),0))&"") -> CA MOEDAS 0,4KG/UC 7UC/CX 144CX/PAL | AS37: CHR-Q37RB2-E0-D94 | AV37: =IFERROR(INDEX($AX$1:$AX$94,MATCH(36,$AY$1:$AY$94,0)),"") -> 250500301 | AW37: CHD-TS-22350E0-999 | AX37: 2520443650 | AY37: =IF(OR($A$5="Todos",AW37=$A$5),MAX(AY$1:AY36)+1,0) -> 37
A38: =IF(IFERROR(MATCH(5,$AB$40:$AB$133,0),0)=0,"",INDEX($T$40:$T$133,IFERROR(MATCH(5,$AB$40:$AB$133,0),0))) -> CHM-SP-Z3L-BR-U73 | B38: =IF(IFERROR(MATCH(5,$AB$40:$AB$133,0),0)=0,"",INDEX($AG$40:$AG$133,IFERROR(MATCH(5,$AB$40:$AB$133,0),0))) -> 251880301 | C38: =IF(IFERROR(MATCH(5,$AB$40:$AB$133,0),0)=0,"",INDEX($U$40:$U$133,IFERROR(MATCH(5,$AB$40:$AB$133,0),0))) -> KG | D38: =IF(IFERROR(MATCH(5,$AB$40:$AB$133,0),0)=0,"",INDEX($V$40:$V$133,IFERROR(MATCH(5,$AB$40:$AB$133,0),0))) -> 0 | E38: =IF(IFERROR(MATCH(5,$AB$40:$AB$133,0),0)=0,"",INDEX($W$40:$W$133,IFERROR(MATCH(5,$AB$40:$AB$133,0),0))) -> 966 | F38: =IF(IFERROR(MATCH(5,$AB$40:$AB$133,0),0)=0,"",INDEX($X$40:$X$133,IFERROR(MATCH(5,$AB$40:$AB$133,0),0))) -> 906 | G38: =IF(A38="","",E38-F38) -> 60 | H38: =IF(IFERROR(MATCH(5,$AB$40:$AB$133,0),0)=0,"",INDEX($Y$40:$Y$133,IFERROR(MATCH(5,$AB$40:$AB$133,0),0))) -> 3754.998 | I38: =IF(IFERROR(MATCH(5,$AB$40:$AB$133,0),0)=0,"",INDEX($Z$40:$Z$133,IFERROR(MATCH(5,$AB$40:$AB$133,0),0))) -> 3694.998 | J38: =IF(IFERROR(MATCH(5,$AB$40:$AB$133,0),0)=0,"",INDEX($AC$40:$AC$133,IFERROR(MATCH(5,$AB$40:$AB$133,0),0))) -> Sobrando | K38: =IF(IFERROR(MATCH(5,$AB$40:$AB$133,0),0)=0,"",INDEX($AD$40:$AD$133,IFERROR(MATCH(5,$AB$40:$AB$133,0),0))) -> 30 | L38: =IF(IFERROR(MATCH(5,$AB$40:$AB$133,0),0)=0,"",INDEX($AE$40:$AE$133,IFERROR(MATCH(5,$AB$40:$AB$133,0),0))&"") -> CA MILK LARGE FLAKES SPLITTERS 1KG/UC | AS38: CW2-BR-25A | AV38: =IFERROR(INDEX($AX$1:$AX$94,MATCH(37,$AY$1:$AY$94,0)),"") -> 2520443650 | AW38: CHD-VR-Z2S-E0-U68 | AX38: 261160301 | AY38: =IF(OR($A$5="Todos",AW38=$A$5),MAX(AY$1:AY37)+1,0) -> 38
A39: =IF(IFERROR(MATCH(6,$AB$40:$AB$133,0),0)=0,"",INDEX($T$40:$T$133,IFERROR(MATCH(6,$AB$40:$AB$133,0),0))) -> CHD-SP-9Z4-BR-U73 | B39: =IF(IFERROR(MATCH(6,$AB$40:$AB$133,0),0)=0,"",INDEX($AG$40:$AG$133,IFERROR(MATCH(6,$AB$40:$AB$133,0),0))) -> 250500301 | C39: =IF(IFERROR(MATCH(6,$AB$40:$AB$133,0),0)=0,"",INDEX($U$40:$U$133,IFERROR(MATCH(6,$AB$40:$AB$133,0),0))) -> KG | D39: =IF(IFERROR(MATCH(6,$AB$40:$AB$133,0),0)=0,"",INDEX($V$40:$V$133,IFERROR(MATCH(6,$AB$40:$AB$133,0),0))) -> 0 | E39: =IF(IFERROR(MATCH(6,$AB$40:$AB$133,0),0)=0,"",INDEX($W$40:$W$133,IFERROR(MATCH(6,$AB$40:$AB$133,0),0))) -> 240 | F39: =IF(IFERROR(MATCH(6,$AB$40:$AB$133,0),0)=0,"",INDEX($X$40:$X$133,IFERROR(MATCH(6,$AB$40:$AB$133,0),0))) -> 6 | G39: =IF(A39="","",E39-F39) -> 234 | H39: =IF(IFERROR(MATCH(6,$AB$40:$AB$133,0),0)=0,"",INDEX($Y$40:$Y$133,IFERROR(MATCH(6,$AB$40:$AB$133,0),0))) -> 3432 | I39: =IF(IFERROR(MATCH(6,$AB$40:$AB$133,0),0)=0,"",INDEX($Z$40:$Z$133,IFERROR(MATCH(6,$AB$40:$AB$133,0),0))) -> 3198 | J39: =IF(IFERROR(MATCH(6,$AB$40:$AB$133,0),0)=0,"",INDEX($AC$40:$AC$133,IFERROR(MATCH(6,$AB$40:$AB$133,0),0))) -> Sobrando | K39: =IF(IFERROR(MATCH(6,$AB$40:$AB$133,0),0)=0,"",INDEX($AD$40:$AD$133,IFERROR(MATCH(6,$AB$40:$AB$133,0),0))) -> 2 | L39: =IF(IFERROR(MATCH(6,$AB$40:$AB$133,0),0)=0,"",INDEX($AE$40:$AE$133,IFERROR(MATCH(6,$AB$40:$AB$133,0),0))&"") -> 96_FU:CHD-SP-1L-BR-U73 | AJ39: Produto | AK39: Sobrando | AL39: Faltando | AP39: Entrou no ZBR | AQ39: Saiu | AS39: CW2NV-595 | AV39: =IFERROR(INDEX($AX$1:$AX$94,MATCH(38,$AY$1:$AY$94,0)),"") -> 261160301 | AW39: CHK-D-413 | AX39: 261756201 | AY39: =IF(OR($A$5="Todos",AW39=$A$5),MAX(AY$1:AY38)+1,0) -> 39
A40: =IF(IFERROR(MATCH(7,$AB$40:$AB$133,0),0)=0,"",INDEX($T$40:$T$133,IFERROR(MATCH(7,$AB$40:$AB$133,0),0))) -> 823-BR-D94 | B40: =IF(IFERROR(MATCH(7,$AB$40:$AB$133,0),0)=0,"",INDEX($AG$40:$AG$133,IFERROR(MATCH(7,$AB$40:$AB$133,0),0))) -> 252103049 | C40: =IF(IFERROR(MATCH(7,$AB$40:$AB$133,0),0)=0,"",INDEX($U$40:$U$133,IFERROR(MATCH(7,$AB$40:$AB$133,0),0))) -> KG | D40: =IF(IFERROR(MATCH(7,$AB$40:$AB$133,0),0)=0,"",INDEX($V$40:$V$133,IFERROR(MATCH(7,$AB$40:$AB$133,0),0))) -> 0 | E40: =IF(IFERROR(MATCH(7,$AB$40:$AB$133,0),0)=0,"",INDEX($W$40:$W$133,IFERROR(MATCH(7,$AB$40:$AB$133,0),0))) -> 2.8 | F40: =IF(IFERROR(MATCH(7,$AB$40:$AB$133,0),0)=0,"",INDEX($X$40:$X$133,IFERROR(MATCH(7,$AB$40:$AB$133,0),0))) -> 677.6 | G40: =IF(A40="","",E40-F40) -> -674.8 | H40: =IF(IFERROR(MATCH(7,$AB$40:$AB$133,0),0)=0,"",INDEX($Y$40:$Y$133,IFERROR(MATCH(7,$AB$40:$AB$133,0),0))) -> 1853.6 | I40: =IF(IFERROR(MATCH(7,$AB$40:$AB$133,0),0)=0,"",INDEX($Z$40:$Z$133,IFERROR(MATCH(7,$AB$40:$AB$133,0),0))) -> 2528.4 | J40: =IF(IFERROR(MATCH(7,$AB$40:$AB$133,0),0)=0,"",INDEX($AC$40:$AC$133,IFERROR(MATCH(7,$AB$40:$AB$133,0),0))) -> Sobrando | K40: =IF(IFERROR(MATCH(7,$AB$40:$AB$133,0),0)=0,"",INDEX($AD$40:$AD$133,IFERROR(MATCH(7,$AB$40:$AB$133,0),0))) -> 53 | L40: =IF(IFERROR(MATCH(7,$AB$40:$AB$133,0),0)=0,"",INDEX($AE$40:$AE$133,IFERROR(MATCH(7,$AB$40:$AB$133,0),0))&"") -> CA MOEDAS 0,4KG/UC 7UC/CX 144CX/PAL | T40: CHK-R30GOLD-BR-25A | U40: KG | V40: =SUMIFS(Lançamentos!$H$2:$H$607,Lançamentos!$A$2:$A$607,">="&$F$5,Lançamentos!$A$2:$A$607,"<="&$H$5,Lançamentos!$C$2:$C$607,$T40,Lançamentos!$D$2:$D$607,$AG40,Lançamentos!$B$2:$B$607,"Recebido no 2008") -> 1025.1 | W40: =SUMIFS(Lançamentos!$I$2:$I$607,Lançamentos!$A$2:$A$607,">="&$F$5,Lançamentos!$A$2:$A$607,"<="&$H$5,Lançamentos!$C$2:$C$607,$T40,Lançamentos!$D$2:$D$607,$AG40) -> 2673.3 | X40: =SUMIFS(Lançamentos!$J$2:$J$607,Lançamentos!$A$2:$A$607,">="&$F$5,Lançamentos!$A$2:$A$607,"<="&$H$5,Lançamentos!$C$2:$C$607,$T40,Lançamentos!$D$2:$D$607,$AG40) -> 1005 | Y40: =SUMIFS('Estoque físico'!$J$2:$J$229,'Estoque físico'!$A$2:$A$229,$T40,'Estoque físico'!$B$2:$B$229,$AG40) -> 1226.1 | Z40: =ROUND(Y40-(W40-X40),3) -> -442.2 | AA40: =IF(AND(U40=$R$3,OR($R$1="*",T40=$R$1),OR($R$2="*",AG40=$R$2),ABS(V40)+ABS(W40)+ABS(X40)+ABS(Y40)>0),1,0) -> 1 | AB40: =IF(AA40=1,SUM(AA$40:AA40),"") -> 1 | AC40: =IF(ABS(Z40)<=$R$5,"Confere",IF(Z40>0,"Sobrando","Faltando")) -> Faltando | AD40: =COUNTIFS(Lançamentos!$A$2:$A$607,">="&$F$5,Lançamentos!$A$2:$A$607,"<="&$H$5,Lançamentos!$C$2:$C$607,$T40,Lançamentos!$D$2:$D$607,$AG40,Lançamentos!$B$2:$B$607,$R$4,Lançamentos!$G$2:$G$607,U40) -> 17 | AE40: CA MOEDAS 2,01KG/UC 10UC/CX 30CX/PAL | AF40: =IF(AND(AA40=1,AC40<>"Confere"),ABS(Z40)+ROW()/10000000,0) -> 442.2 | AG40: 261130301 | AH40: =LARGE($AF$40:$AF$133,1) -> 5737.2 | AI40: =IF(AH40>0,MATCH(AH40,$AF$40:$AF$133,0),"") -> 6 | AJ40: =IF(AI40="","",INDEX($T$40:$T$133,AI40)&" · "&INDEX($AG$40:$AG$133,AI40)) -> 811-BR-D94 · 251643289 | AK40: =IF(AI40="",0,MAX(INDEX($Z$40:$Z$133,AI40),0)) -> 5737.2 | AL40: =IF(AI40="",0,MIN(INDEX($Z$40:$Z$133,AI40),0)) -> 0 | AN40: 09/09 | AO40: 46274 | AP40: =IF(AND(AO40>=$F$5,AO40<=$H$5),SUMIFS(Lançamentos!$I$2:$I$607,Lançamentos!$A$2:$A$607,$AO40,Lançamentos!$C$2:$C$607,$R$1,Lançamentos!$D$2:$D$607,$R$2,Lançamentos!$G$2:$G$607,$R$3,Lançamentos!$B$2:$B$607,$R$4),0) -> 490.96 | AQ40: =IF(AND(AO40>=$F$5,AO40<=$H$5),-SUMIFS(Lançamentos!$J$2:$J$607,Lançamentos!$A$2:$A$607,$AO40,Lançamentos!$C$2:$C$607,$R$1,Lançamentos!$D$2:$D$607,$R$2,Lançamentos!$G$2:$G$607,$R$3,Lançamentos!$B$2:$B$607,$R$4),0) -> -11.2 | AS40: DCP-10BONOI-89B | AV40: =IFERROR(INDEX($AX$1:$AX$94,MATCH(39,$AY$1:$AY$94,0)),"") -> 261756201 | AW40: CHK-R30GOLD-BR-25A | AX40: 252750301 | AY40: =IF(OR($A$5="Todos",AW40=$A$5),MAX(AY$1:AY39)+1,0) -> 40
...

Sheet Cruzamento
A1: Cruzamento por SKU e lote
A2: Uma linha para cada SKU + lote · movimentos de 09/09 a 01/10/2026
A4: COMO LER
A5: ENTROU − SAIU = DEVERIA TER. Depois compare com o ESTOQUE FÍSICO (o que tem no depósito hoje).
A6: DIFERENÇA = Estoque físico − Deveria ter. 0 = Confere · positivo = Sobrando · negativo = Faltando.
A8: SKU·LOTE CONFEREM | C8: SKU·LOTE SOBRANDO | E8: SKU·LOTE FALTANDO
A9: =COUNTIF($J$13:$J$106,"Confere") -> 66 | C9: =COUNTIF($J$13:$J$106,"Sobrando") -> 23 | E9: =COUNTIF($J$13:$J$106,"Faltando") -> 5
A12: SKU | B12: LOTE | C12: DESCRIÇÃO | D12: UM | E12: ENTROU | F12: SAIU | G12: DEVERIA TER | H12: ESTOQUE FÍSICO | I12: DIFERENÇA | J12: SITUAÇÃO | K12: O QUE FAZER
A13: CHK-R30GOLD-BR-25A | B13: 261130301 | C13: CA MOEDAS 2,01KG/UC 10UC/CX 30CX/PAL | D13: KG | E13: =SUMIFS('Cruzamento por Lote'!$E$5:$E$98,'Cruzamento por Lote'!$A$5:$A$98,$A13,'Cruzamento por Lote'!$B$5:$B$98,$B13) -> 2673.3 | F13: =SUMIFS('Cruzamento por Lote'!$F$5:$F$98,'Cruzamento por Lote'!$A$5:$A$98,$A13,'Cruzamento por Lote'!$B$5:$B$98,$B13) -> 1005 | G13: =E13-F13 -> 1668.3 | H13: =SUMIFS('Cruzamento por Lote'!$H$5:$H$98,'Cruzamento por Lote'!$A$5:$A$98,$A13,'Cruzamento por Lote'!$B$5:$B$98,$B13) -> 1226.1 | I13: =ROUND(H13-G13,2) -> -442.2 | J13: =IF(ABS(I13)<=Resumo!$C$7,"Confere",IF(I13>0,"Sobrando","Faltando")) -> Faltando | K13: =IF(J13="Confere","Nada a fazer",IF(J13="Faltando","Procurar saída, ajuste ou devolução que não está na lista",IF(F13>E13,"Saiu mais do que entrou: confirmar o estoque que já existia antes de 09/09","Conferir estoque de antes de 09/09 ou entrada não lançada"))) -> Procurar saída, ajuste ou devolução que não está na lista
A14: CHM-TS-P23-E0-999 | B14: 2605567696 | D14: KG | E14: =SUMIFS('Cruzamento por Lote'!$E$5:$E$98,'Cruzamento por Lote'!$A$5:$A$98,$A14,'Cruzamento por Lote'!$B$5:$B$98,$B14) -> 261.12 | F14: =SUMIFS('Cruzamento por Lote'!$F$5:$F$98,'Cruzamento por Lote'!$A$5:$A$98,$A14,'Cruzamento por Lote'!$B$5:$B$98,$B14) -> 0 | G14: =E14-F14 -> 261.12 | H14: =SUMIFS('Cruzamento por Lote'!$H$5:$H$98,'Cruzamento por Lote'!$A$5:$A$98,$A14,'Cruzamento por Lote'!$B$5:$B$98,$B14) -> 0 | I14: =ROUND(H14-G14,2) -> -261.12 | J14: =IF(ABS(I14)<=Resumo!$C$7,"Confere",IF(I14>0,"Sobrando","Faltando")) -> Faltando | K14: =IF(J14="Confere","Nada a fazer",IF(J14="Faltando","Procurar saída, ajuste ou devolução que não está na lista",IF(F14>E14,"Saiu mais do que entrou: confirmar o estoque que já existia antes de 09/09","Conferir estoque de antes de 09/09 ou entrada não lançada"))) -> Procurar saída, ajuste ou devolução que não está na lista
A15: BIG-PF-1BO-401 | B15: 26044019 | C15: CB PAILLETÉ FEUILLETINE 2.5KG/UC 4UC/BOX | D15: KG | E15: =SUMIFS('Cruzamento por Lote'!$E$5:$E$98,'Cruzamento por Lote'!$A$5:$A$98,$A15,'Cruzamento por Lote'!$B$5:$B$98,$B15) -> 480 | F15: =SUMIFS('Cruzamento por Lote'!$F$5:$F$98,'Cruzamento por Lote'!$A$5:$A$98,$A15,'Cruzamento por Lote'!$B$5:$B$98,$B15) -> 60 | G15: =E15-F15 -> 420 | H15: =SUMIFS('Cruzamento por Lote'!$H$5:$H$98,'Cruzamento por Lote'!$A$5:$A$98,$A15,'Cruzamento por Lote'!$B$5:$B$98,$B15) -> 210 | I15: =ROUND(H15-G15,2) -> -210 | J15: =IF(ABS(I15)<=Resumo!$C$7,"Confere",IF(I15>0,"Sobrando","Faltando")) -> Faltando | K15: =IF(J15="Confere","Nada a fazer",IF(J15="Faltando","Procurar saída, ajuste ou devolução que não está na lista",IF(F15>E15,"Saiu mais do que entrou: confirmar o estoque que já existia antes de 09/09","Conferir estoque de antes de 09/09 ou entrada não lançada"))) -> Procurar saída, ajuste ou devolução que não está na lista
A16: NIBS-S502-X47 | B16: 253490619 | C16: CA NIBS S 0.8KG/UC 4UC/BOX 120BOX/PAL | D16: CX | E16: =SUMIFS('Cruzamento por Lote'!$E$5:$E$98,'Cruzamento por Lote'!$A$5:$A$98,$A16,'Cruzamento por Lote'!$B$5:$B$98,$B16) -> 487 | F16: =SUMIFS('Cruzamento por Lote'!$F$5:$F$98,'Cruzamento por Lote'!$A$5:$A$98,$A16,'Cruzamento por Lote'!$B$5:$B$98,$B16) -> 0 | G16: =E16-F16 -> 487 | H16: =SUMIFS('Cruzamento por Lote'!$H$5:$H$98,'Cruzamento por Lote'!$A$5:$A$98,$A16,'Cruzamento por Lote'!$B$5:$B$98,$B16) -> 367 | I16: =ROUND(H16-G16,2) -> -120 | J16: =IF(ABS(I16)<=Resumo!$C$7,"Confere",IF(I16>0,"Sobrando","Faltando")) -> Faltando | K16: =IF(J16="Confere","Nada a fazer",IF(J16="Faltando","Procurar saída, ajuste ou devolução que não está na lista",IF(F16>E16,"Saiu mais do que entrou: confirmar o estoque que já existia antes de 09/09","Conferir estoque de antes de 09/09 ou entrada não lançada"))) -> Procurar saída, ajuste ou devolução que não está na lista
A17: CHD-BB-308BY-357 | B17: 250827800 | C17: CB EXTRUDED 8CM STICKS 1.6KG/UC 15UC/BOX | D17: UN | E17: =SUMIFS('Cruzamento por Lote'!$E$5:$E$98,'Cruzamento por Lote'!$A$5:$A$98,$A17,'Cruzamento por Lote'!$B$5:$B$98,$B17) -> 30 | F17: =SUMIFS('Cruzamento por Lote'!$F$5:$F$98,'Cruzamento por Lote'!$A$5:$A$98,$A17,'Cruzamento por Lote'!$B$5:$B$98,$B17) -> 0 | G17: =E17-F17 -> 30 | H17: =SUMIFS('Cruzamento por Lote'!$H$5:$H$98,'Cruzamento por Lote'!$A$5:$A$98,$A17,'Cruzamento por Lote'!$B$5:$B$98,$B17) -> 4.219 | I17: =ROUND(H17-G17,2) -> -25.78 | J17: =IF(ABS(I17)<=Resumo!$C$7,"Confere",IF(I17>0,"Sobrando","Faltando")) -> Faltando | K17: =IF(J17="Confere","Nada a fazer",IF(J17="Faltando","Procurar saída, ajuste ou devolução que não está na lista",IF(F17>E17,"Saiu mais do que entrou: confirmar o estoque que já existia antes de 09/09","Conferir estoque de antes de 09/09 ou entrada não lançada"))) -> Procurar saída, ajuste ou devolução que não está na lista
A18: 811-BR-D94 | B18: 251643289 | C18: CA MOEDAS 0,4KG/UC 7UC/CX 144CX/PAL | D18: KG | E18: =SUMIFS('Cruzamento por Lote'!$E$5:$E$98,'Cruzamento por Lote'!$A$5:$A$98,$A18,'Cruzamento por Lote'!$B$5:$B$98,$B18) -> 2.8 | F18: =SUMIFS('Cruzamento por Lote'!$F$5:$F$98,'Cruzamento por Lote'!$A$5:$A$98,$A18,'Cruzamento por Lote'!$B$5:$B$98,$B18) -> 226.8 | G18: =E18-F18 -> -224 | H18: =SUMIFS('Cruzamento por Lote'!$H$5:$H$98,'Cruzamento por Lote'!$A$5:$A$98,$A18,'Cruzamento por Lote'!$B$5:$B$98,$B18) -> 5513.2 | I18: =ROUND(H18-G18,2) -> 5737.2 | J18: =IF(ABS(I18)<=Resumo!$C$7,"Confere",IF(I18>0,"Sobrando","Faltando")) -> Sobrando | K18: =IF(J18="Confere","Nada a fazer",IF(J18="Faltando","Procurar saída, ajuste ou devolução que não está na lista",IF(F18>E18,"Saiu mais do que entrou: confirmar o estoque que já existia antes de 09/09","Conferir estoque de antes de 09/09 ou entrada não lançada"))) -> Saiu mais do que entrou: confirmar o estoque que já existia antes de 09/09
A19: CHM-SP-Z3L-BR-U73 | B19: 251880301 | C19: CA MILK LARGE FLAKES SPLITTERS 1KG/UC | D19: KG | E19: =SUMIFS('Cruzamento por Lote'!$E$5:$E$98,'Cruzamento por Lote'!$A$5:$A$98,$A19,'Cruzamento por Lote'!$B$5:$B$98,$B19) -> 966 | F19: =SUMIFS('Cruzamento por Lote'!$F$5:$F$98,'Cruzamento por Lote'!$A$5:$A$98,$A19,'Cruzamento por Lote'!$B$5:$B$98,$B19) -> 906 | G19: =E19-F19 -> 60 | H19: =SUMIFS('Cruzamento por Lote'!$H$5:$H$98,'Cruzamento por Lote'!$A$5:$A$98,$A19,'Cruzamento por Lote'!$B$5:$B$98,$B19) -> 3754.998 | I19: =ROUND(H19-G19,2) -> 3695 | J19: =IF(ABS(I19)<=Resumo!$C$7,"Confere",IF(I19>0,"Sobrando","Faltando")) -> Sobrando | K19: =IF(J19="Confere","Nada a fazer",IF(J19="Faltando","Procurar saída, ajuste ou devolução que não está na lista",IF(F19>E19,"Saiu mais do que entrou: confirmar o estoque que já existia antes de 09/09","Conferir estoque de antes de 09/09 ou entrada não lançada"))) -> Conferir estoque de antes de 09/09 ou entrada não lançada
A20: CHD-SP-9Z4-BR-U73 | B20: 250500301 | C20: 96_FU:CHD-SP-1L-BR-U73 | D20: KG | E20: =SUMIFS('Cruzamento por Lote'!$E$5:$E$98,'Cruzamento por Lote'!$A$5:$A$98,$A20,'Cruzamento por Lote'!$B$5:$B$98,$B20) -> 240 | F20: =SUMIFS('Cruzamento por Lote'!$F$5:$F$98,'Cruzamento por Lote'!$A$5:$A$98,$A20,'Cruzamento por Lote'!$B$5:$B$98,$B20) -> 6 | G20: =E20-F20 -> 234 | H20: =SUMIFS('Cruzamento por Lote'!$H$5:$H$98,'Cruzamento por Lote'!$A$5:$A$98,$A20,'Cruzamento por Lote'!$B$5:$B$98,$B20) -> 3432 | I20: =ROUND(H20-G20,2) -> 3198 | J20: =IF(ABS(I20)<=Resumo!$C$7,"Confere",IF(I20>0,"Sobrando","Faltando")) -> Sobrando | K20: =IF(J20="Confere","Nada a fazer",IF(J20="Faltando","Procurar saída, ajuste ou devolução que não está na lista",IF(F20>E20,"Saiu mais do que entrou: confirmar o estoque que já existia antes de 09/09","Conferir estoque de antes de 09/09 ou entrada não lançada"))) -> Conferir estoque de antes de 09/09 ou entrada não lançada
A21: 823-BR-D94 | B21: 252103049 | C21: CA MOEDAS 0,4KG/UC 7UC/CX 144CX/PAL | D21: KG | E21: =SUMIFS('Cruzamento por Lote'!$E$5:$E$98,'Cruzamento por Lote'!$A$5:$A$98,$A21,'Cruzamento por Lote'!$B$5:$B$98,$B21) -> 2.8 | F21: =SUMIFS('Cruzamento por Lote'!$F$5:$F$98,'Cruzamento por Lote'!$A$5:$A$98,$A21,'Cruzamento por Lote'!$B$5:$B$98,$B21) -> 677.6 | G21: =E21-F21 -> -674.8 | H21: =SUMIFS('Cruzamento por Lote'!$H$5:$H$98,'Cruzamento por Lote'!$A$5:$A$98,$A21,'Cruzamento por Lote'!$B$5:$B$98,$B21) -> 1853.6 | I21: =ROUND(H21-G21,2) -> 2528.4 | J21: =IF(ABS(I21)<=Resumo!$C$7,"Confere",IF(I21>0,"Sobrando","Faltando")) -> Sobrando | K21: =IF(J21="Confere","Nada a fazer",IF(J21="Faltando","Procurar saída, ajuste ou devolução que não está na lista",IF(F21>E21,"Saiu mais do que entrou: confirmar o estoque que já existia antes de 09/09","Conferir estoque de antes de 09/09 ou entrada não lançada"))) -> Saiu mais do que entrou: confirmar o estoque que já existia antes de 09/09
A22: 805-BR-D94 | B22: 251633359 | C22: CA MOEDAS 0,4KG/UC 7UC/CX 144CX/PAL | D22: KG | E22: =SUMIFS('Cruzamento por Lote'!$E$5:$E$98,'Cruzamento por Lote'!$A$5:$A$98,$A22,'Cruzamento por Lote'!$B$5:$B$98,$B22) -> 313.6 | F22: =SUMIFS('Cruzamento por Lote'!$F$5:$F$98,'Cruzamento por Lote'!$A$5:$A$98,$A22,'Cruzamento por Lote'!$B$5:$B$98,$B22) -> 221.2 | G22: =E22-F22 -> 92.4 | H22: =SUMIFS('Cruzamento por Lote'!$H$5:$H$98,'Cruzamento por Lote'!$A$5:$A$98,$A22,'Cruzamento por Lote'!$B$5:$B$98,$B22) -> 1360.8 | I22: =ROUND(H22-G22,2) -> 1268.4 | J22: =IF(ABS(I22)<=Resumo!$C$7,"Confere",IF(I22>0,"Sobrando","Faltando")) -> Sobrando | K22: =IF(J22="Confere","Nada a fazer",IF(J22="Faltando","Procurar saída, ajuste ou devolução que não está na lista",IF(F22>E22,"Saiu mais do que entrou: confirmar o estoque que já existia antes de 09/09","Conferir estoque de antes de 09/09 ou entrada não lançada"))) -> Conferir estoque de antes de 09/09 ou entrada não lançada
A23: W3-BR-25A | B23: 253540301 | C23: CA MOEDAS 2,01KG/UC 10UC/CX 30CX/PAL | D23: KG | E23: =SUMIFS('Cruzamento por Lote'!$E$5:$E$98,'Cruzamento por Lote'!$A$5:$A$98,$A23,'Cruzamento por Lote'!$B$5:$B$98,$B23) -> 0 | F23: =SUMIFS('Cruzamento por Lote'!$F$5:$F$98,'Cruzamento por Lote'!$A$5:$A$98,$A23,'Cruzamento por Lote'!$B$5:$B$98,$B23) -> 542.7 | G23: =E23-F23 -> -542.7 | H23: =SUMIFS('Cruzamento por Lote'!$H$5:$H$98,'Cruzamento por Lote'!$A$5:$A$98,$A23,'Cruzamento por Lote'!$B$5:$B$98,$B23) -> 540.69 | I23: =ROUND(H23-G23,2) -> 1083.39 | J23: =IF(ABS(I23)<=Resumo!$C$7,"Confere",IF(I23>0,"Sobrando","Faltando")) -> Sobrando | K23: =IF(J23="Confere","Nada a fazer",IF(J23="Faltando","Procurar saída, ajuste ou devolução que não está na lista",IF(F23>E23,"Saiu mais do que entrou: confirmar o estoque que já existia antes de 09/09","Conferir estoque de antes de 09/09 ou entrada não lançada"))) -> Saiu mais do que entrou: confirmar o estoque que já existia antes de 09/09
A24: CW2-BR-25A | B24: 253470301 | C24: CA MOEDAS 2,01KG/UC 10UC/CX 30CX/PAL | D24: KG | E24: =SUMIFS('Cruzamento por Lote'!$E$5:$E$98,'Cruzamento por Lote'!$A$5:$A$98,$A24,'Cruzamento por Lote'!$B$5:$B$98,$B24) -> 763.8 | F24: =SUMIFS('Cruzamento por Lote'!$F$5:$F$98,'Cruzamento por Lote'!$A$5:$A$98,$A24,'Cruzamento por Lote'!$B$5:$B$98,$B24) -> 924.6 | G24: =E24-F24 -> -160.8 | H24: =SUMIFS('Cruzamento por Lote'!$H$5:$H$98,'Cruzamento por Lote'!$A$5:$A$98,$A24,'Cruzamento por Lote'!$B$5:$B$98,$B24) -> 763.8 | I24: =ROUND(H24-G24,2) -> 924.6 | J24: =IF(ABS(I24)<=Resumo!$C$7,"Confere",IF(I24>0,"Sobrando","Faltando")) -> Sobrando | K24: =IF(J24="Confere","Nada a fazer",IF(J24="Faltando","Procurar saída, ajuste ou devolução que não está na lista",IF(F24>E24,"Saiu mais do que entrou: confirmar o estoque que já existia antes de 09/09","Conferir estoque de antes de 09/09 ou entrada não lançada"))) -> Saiu mais do que entrou: confirmar o estoque que já existia antes de 09/09
A25: CHP-20SICHP-760 | B25: 252843369 | C25: CA SILKY CHOCO POWDER POWDER 1KG/UC | D25: KG | E25: =SUMIFS('Cruzamento por Lote'!$E$5:$E$98,'Cruzamento por Lote'!$A$5:$A$98,$A25,'Cruzamento por Lote'!$B$5:$B$98,$B25) -> 918 | F25: =SUMIFS('Cruzamento por Lote'!$F$5:$F$98,'Cruzamento por Lote'!$A$5:$A$98,$A25,'Cruzamento por Lote'!$B$5:$B$98,$B25) -> 186 | G25: =E25-F25 -> 732 | H25: =SUMIFS('Cruzamento por Lote'!$H$5:$H$98,'Cruzamento por Lote'!$A$5:$A$98,$A25,'Cruzamento por Lote'!$B$5:$B$98,$B25) -> 1272 | I25: =ROUND(H25-G25,2) -> 540 | J25: =IF(ABS(I25)<=Resumo!$C$7,"Confere",IF(I25>0,"Sobrando","Faltando")) -> Sobrando | K25: =IF(J25="Confere","Nada a fazer",IF(J25="Faltando","Procurar saída, ajuste ou devolução que não está na lista",IF(F25>E25,"Saiu mais do que entrou: confirmar o estoque que já existia antes de 09/09","Conferir estoque de antes de 09/09 ou entrada não lançada"))) -> Conferir estoque de antes de 09/09 ou entrada não lançada
A26: 70-30-38-BR-25A | B26: 260370301 | C26: CA MOEDAS 2,01KG/UC 10UC/CX 30CX/PAL | D26: KG | E26: =SUMIFS('Cruzamento por Lote'!$E$5:$E$98,'Cruzamento por Lote'!$A$5:$A$98,$A26,'Cruzamento por Lote'!$B$5:$B$98,$B26) -> 603 | F26: =SUMIFS('Cruzamento por Lote'!$F$5:$F$98,'Cruzamento por Lote'!$A$5:$A$98,$A26,'Cruzamento por Lote'!$B$5:$B$98,$B26) -> 321.6 | G26: =E26-F26 -> 281.4 | H26: =SUMIFS('Cruzamento por Lote'!$H$5:$H$98,'Cruzamento por Lote'!$A$5:$A$98,$A26,'Cruzamento por Lote'!$B$5:$B$98,$B26) -> 623.1 | I26: =ROUND(H26-G26,2) -> 341.7 | J26: =IF(ABS(I26)<=Resumo!$C$7,"Confere",IF(I26>0,"Sobrando","Faltando")) -> Sobrando | K26: =IF(J26="Confere","Nada a fazer",IF(J26="Faltando","Procurar saída, ajuste ou devolução que não está na lista",IF(F26>E26,"Saiu mais do que entrou: confirmar o estoque que já existia antes de 09/09","Conferir estoque de antes de 09/09 ou entrada não lançada"))) -> Conferir estoque de antes de 09/09 ou entrada não lançada
... A40: W3-BR-25A | B40: 261080301 | C40: CA MOEDAS 2,01KG/UC 10UC/CX 30CX/PAL | D40: KG | E40: =SUMIFS('Cruzamento por Lote'!$E$5:$E$98,'Cruzamento por Lote'!$A$5:$A$98,$A40,'Cruzamento por Lote'!$B$5:$B$98,$B40) -> 3025.7 | F40: =SUMIFS('Cruzamento por Lote'!$F$5:$F$98,'Cruzamento por Lote'!$A$5:$A$98,$A40,'Cruzamento por Lote'!$B$5:$B$98,$B40) -> 1366.8 | G40: =E40-F40 -> 1658.9 | H40: =SUMIFS('Cruzamento por Lote'!$H$5:$H$98,'Cruzamento por Lote'!$A$5:$A$98,$A40,'Cruzamento por Lote'!$B$5:$B$98,$B40) -> 1679 | I40: =ROUND(H40-G40,2) -> 20.1 | J40: =IF(ABS(I40)<=Resumo!$C$7,"Confere",IF(I40>0,"Sobrando","Faltando")) -> Sobrando | K40: =IF(J40="Confere","Nada a fazer",IF(J40="Faltando","Procurar saída, ajuste ou devolução que não está na lista",IF(F40>E40,"Saiu mais do que entrou: confirmar o estoque que já existia antes de 09/09","Conferir estoque de antes de 09/09 ou entrada não lançada"))) -> Conferir estoque de antes de 09/09 ou entrada não lançada
A41: 2665-E4-U71 | B41: 252800202 | D41: KG | E41: =SUMIFS('Cruzamento por Lote'!$E$5:$E$98,'Cruzamento por Lote'!$A$5:$A$98,$A41,'Cruzamento por Lote'!$B$5:$B$98,$B41) -> 1200 | F41: =SUMIFS('Cruzamento por Lote'!$F$5:$F$98,'Cruzamento por Lote'!$A$5:$A$98,$A41,'Cruzamento por Lote'!$B$5:$B$98,$B41) -> 0 | G41: =E41-F41 -> 1200 | H41: =SUMIFS('Cruzamento por Lote'!$H$5:$H$98,'Cruzamento por Lote'!$A$5:$A$98,$A41,'Cruzamento por Lote'!$B$5:$B$98,$B41) -> 1200 | I41: =ROUND(H41-G41,2) -> 0 | J41: =IF(ABS(I41)<=Resumo!$C$7,"Confere",IF(I41>0,"Sobrando","Faltando")) -> Confere | K41: =IF(J41="Confere","Nada a fazer",IF(J41="Faltando","Procurar saída, ajuste ou devolução que não está na lista",IF(F41>E41,"Saiu mais do que entrou: confirmar o estoque que já existia antes de 09/09","Conferir estoque de antes de 09/09 ou entrada não lançada"))) -> Nada a fazer
A42: 70-30-38-BR-25A | B42: 260070301 | C42: CA MOEDAS 2,01KG/UC 10UC/CX 30CX/PAL | D42: KG | E42: =SUMIFS('Cruzamento por Lote'!$E$5:$E$98,'Cruzamento por Lote'!$A$5:$A$98,$A42,'Cruzamento por Lote'!$B$5:$B$98,$B42) -> 3015 | F42: =SUMIFS('Cruzamento por Lote'!$F$5:$F$98,'Cruzamento por Lote'!$A$5:$A$98,$A42,'Cruzamento por Lote'!$B$5:$B$98,$B42) -> 2673.3 | G42: =E42-F42 -> 341.7 | H42: =SUMIFS('Cruzamento por Lote'!$H$5:$H$98,'Cruzamento por Lote'!$A$5:$A$98,$A42,'Cruzamento por Lote'!$B$5:$B$98,$B42) -> 341.7 | I42: =ROUND(H42-G42,2) -> 0 | J42: =IF(ABS(I42)<=Resumo!$C$7,"Confere",IF(I42>0,"Sobrando","Faltando")) -> Confere | K42: =IF(J42="Confere","Nada a fazer",IF(J42="Faltando","Procurar saída, ajuste ou devolução que não está na lista",IF(F42>E42,"Saiu mais do que entrou: confirmar o estoque que já existia antes de 09/09","Conferir estoque de antes de 09/09 ou entrada não lançada"))) -> Nada a fazer
A43: 805-BR-D94 | B43: 260130779 | C43: CA MOEDAS 0,4KG/UC 7UC/CX 144CX/PAL | D43: KG | E43: =SUMIFS('Cruzamento por Lote'!$E$5:$E$98,'Cruzamento por Lote'!$A$5:$A$98,$A43,'Cruzamento por Lote'!$B$5:$B$98,$B43) -> 142.8 | F43: =SUMIFS('Cruzamento por Lote'!$F$5:$F$98,'Cruzamento por Lote'!$A$5:$A$98,$A43,'Cruzamento por Lote'!$B$5:$B$98,$B43) -> 0 | G43: =E43-F43 -> 142.8 | H43: =SUMIFS('Cruzamento por Lote'!$H$5:$H$98,'Cruzamento por Lote'!$A$5:$A$98,$A43,'Cruzamento por Lote'!$B$5:$B$98,$B43) -> 142.8 | I43: =ROUND(H43-G43,2) -> 0 | J43: =IF(ABS(I43)<=Resumo!$C$7,"Confere",IF(I43>0,"Sobrando","Faltando")) -> Confere | K43: =IF(J43="Confere","Nada a fazer",IF(J43="Faltando","Procurar saída, ajuste ou devolução que não está na lista",IF(F43>E43,"Saiu mais do que entrou: confirmar o estoque que já existia antes de 09/09","Conferir estoque de antes de 09/09 ou entrada não lançada"))) -> Nada a fazer
A44: 811NV-132 | B44: 252510301 | C44: 96_FU:811NV-50C_CA BLOCKS 5KG/UC 5UC | D44: KG | E44: =SUMIFS('Cruzamento por Lote'!$E$5:$E$98,'Cruzamento por Lote'!$A$5:$A$98,$A44,'Cruzamento por Lote'!$B$5:$B$98,$B44) -> 1500 | F44: =SUMIFS('Cruzamento por Lote'!$F$5:$F$98,'Cruzamento por Lote'!$A$5:$A$98,$A44,'Cruzamento por Lote'!$B$5:$B$98,$B44) -> 0 | G44: =E44-F44 -> 1500 | H44: =SUMIFS('Cruzamento por Lote'!$H$5:$H$98,'Cruzamento por Lote'!$A$5:$A$98,$A44,'Cruzamento por Lote'!$B$5:$B$98,$B44) -> 1500 | I44: =ROUND(H44-G44,2) -> 0 | J44: =IF(ABS(I44)<=Resumo!$C$7,"Confere",IF(I44>0,"Sobrando","Faltando")) -> Confere | K44: =IF(J44="Confere","Nada a fazer",IF(J44="Faltando","Procurar saída, ajuste ou devolução que não está na lista",IF(F44>E44,"Saiu mais do que entrou: confirmar o estoque que já existia antes de 09/09","Conferir estoque de antes de 09/09 ou entrada não lançada"))) -> Nada a fazer
A45: 811NV-132 | B45: 253280301 | C45: 96_FU:811NV-50C_CA BLOCKS 5KG/UC 5UC | D45: KG | E45: =SUMIFS('Cruzamento por Lote'!$E$5:$E$98,'Cruzamento por Lote'!$A$5:$A$98,$A45,'Cruzamento por Lote'!$B$5:$B$98,$B45) -> 1750 | F45: =SUMIFS('Cruzamento por Lote'!$F$5:$F$98,'Cruzamento por Lote'!$A$5:$A$98,$A45,'Cruzamento por Lote'!$B$5:$B$98,$B45) -> 800 | G45: =E45-F45 -> 950 | H45: =SUMIFS('Cruzamento por Lote'!$H$5:$H$98,'Cruzamento por Lote'!$A$5:$A$98,$A45,'Cruzamento por Lote'!$B$5:$B$98,$B45) -> 950 | I45: =ROUND(H45-G45,2) -> 0 | J45: =IF(ABS(I45)<=Resumo!$C$7,"Confere",IF(I45>0,"Sobrando","Faltando")) -> Confere | K45: =IF(J45="Confere","Nada a fazer",IF(J45="Faltando","Procurar saída, ajuste ou devolução que não está na lista",IF(F45>E45,"Saiu mais do que entrou: confirmar o estoque que já existia antes de 09/09","Conferir estoque de antes de 09/09 ou entrada não lançada"))) -> Nada a fazer
A46: 811NV-595 | B46: 260900702 | C46: CA CALLETS 10KG/UC 2UC/BOX 30BOX/PAL | D46: KG | E46: =SUMIFS('Cruzamento por Lote'!$E$5:$E$98,'Cruzamento por Lote'!$A$5:$A$98,$A46,'Cruzamento por Lote'!$B$5:$B$98,$B46) -> 1800 | F46: =SUMIFS('Cruzamento por Lote'!$F$5:$F$98,'Cruzamento por Lote'!$A$5:$A$98,$A46,'Cruzamento por Lote'!$B$5:$B$98,$B46) -> 1780 | G46: =E46-F46 -> 20 | H46: =SUMIFS('Cruzamento por Lote'!$H$5:$H$98,'Cruzamento por Lote'!$A$5:$A$98,$A46,'Cruzamento por Lote'!$B$5:$B$98,$B46) -> 20 | I46: =ROUND(H46-G46,2) -> 0 | J46: =IF(ABS(I46)<=Resumo!$C$7,"Confere",IF(I46>0,"Sobrando","Faltando")) -> Confere | K46: =IF(J46="Confere","Nada a fazer",IF(J46="Faltando","Procurar saída, ajuste ou devolução que não está na lista",IF(F46>E46,"Saiu mais do que entrou: confirmar o estoque que já existia antes de 09/09","Conferir estoque de antes de 09/09 ou entrada não lançada"))) -> Nada a fazer
A47: 811NV-595 | B47: 260920702 | C47: CA CALLETS 10KG/UC 2UC/BOX 30BOX/PAL | D47: KG | E47: =SUMIFS('Cruzamento por Lote'!$E$5:$E$98,'Cruzamento por Lote'!$A$5:$A$98,$A47,'Cruzamento por Lote'!$B$5:$B$98,$B47) -> 600 | F47: =SUMIFS('Cruzamento por Lote'!$F$5:$F$98,'Cruzamento por Lote'!$A$5:$A$98,$A47,'Cruzamento por Lote'!$B$5:$B$98,$B47) -> 0 | G47: =E47-F47 -> 600 | H47: =SUMIFS('Cruzamento por Lote'!$H$5:$H$98,'Cruzamento por Lote'!$A$5:$A$98,$A47,'Cruzamento por Lote'!$B$5:$B$98,$B47) -> 600 | I47: =ROUND(H47-G47,2) -> 0 | J47: =IF(ABS(I47)<=Resumo!$C$7,"Confere",IF(I47>0,"Sobrando","Faltando")) -> Confere | K47: =IF(J47="Confere","Nada a fazer",IF(J47="Faltando","Procurar saída, ajuste ou devolução que não está na lista",IF(F47>E47,"Saiu mais do que entrou: confirmar o estoque que já existia antes de 09/09","Conferir estoque de antes de 09/09 ou entrada não lançada"))) -> Nada a fazer
A48: 811NV-595 | B48: 261146101 | C48: CA CALLETS 10KG/UC 2UC/BOX 30BOX/PAL | D48: KG | E48: =SUMIFS('Cruzamento por Lote'!$E$5:$E$98,'Cruzamento por Lote'!$A$5:$A$98,$A48,'Cruzamento por Lote'!$B$5:$B$98,$B48) -> 1180 | F48: =SUMIFS('Cruzamento por Lote'!$F$5:$F$98,'Cruzamento por Lote'!$A$5:$A$98,$A48,'Cruzamento por Lote'!$B$5:$B$98,$B48) -> 1160 | G48: =E48-F48 -> 20 | H48: =SUMIFS('Cruzamento por Lote'!$H$5:$H$98,'Cruzamento por Lote'!$A$5:$A$98,$A48,'Cruzamento por Lote'!$B$5:$B$98,$B48) -> 20 | I48: =ROUND(H48-G48,2) -> 0 | J48: =IF(ABS(I48)<=Resumo!$C$7,"Confere",IF(I48>0,"Sobrando","Faltando")) -> Confere | K48: =IF(J48="Confere","Nada a fazer",IF(J48="Faltando","Procurar saída, ajuste ou devolução que não está na lista",IF(F48>E48,"Saiu mais do que entrou: confirmar o estoque que já existia antes de 09/09","Conferir estoque de antes de 09/09 ou entrada não lançada"))) -> Nada a fazer
A49: 811NV-595 | B49: 261146102 | C49: CA CALLETS 10KG/UC 2UC/BOX 30BOX/PAL | D49: KG | E49: =SUMIFS('Cruzamento por Lote'!$E$5:$E$98,'Cruzamento por Lote'!$A$5:$A$98,$A49,'Cruzamento por Lote'!$B$5:$B$98,$B49) -> 1660 | F49: =SUMIFS('Cruzamento por Lote'!$F$5:$F$98,'Cruzamento por Lote'!$A$5:$A$98,$A49,'Cruzamento por Lote'!$B$5:$B$98,$B49) -> 580 | G49: =E49-F49 -> 1080 | H49: =SUMIFS('Cruzamento por Lote'!$H$5:$H$98,'Cruzamento por Lote'!$A$5:$A$98,$A49,'Cruzamento por Lote'!$B$5:$B$98,$B49) -> 1080 | I49: =ROUND(H49-G49,2) -> 0 | J49: =IF(ABS(I49)<=Resumo!$C$7,"Confere",IF(I49>0,"Sobrando","Faltando")) -> Confere | K49: =IF(J49="Confere","Nada a fazer",IF(J49="Faltando","Procurar saída, ajuste ou devolução que não está na lista",IF(F49>E49,"Saiu mais do que entrou: confirmar o estoque que já existia antes de 09/09","Conferir estoque de antes de 09/09 ou entrada não lançada"))) -> Nada a fazer
A50: 823-BR-25A | B50: 252100301 | C50: CA MOEDAS 2,01KG/UC 10UC/CX 30CX/PAL | D50: KG | E50: =SUMIFS('Cruzamento por Lote'!$E$5:$E$98,'Cruzamento por Lote'!$A$5:$A$98,$A50,'Cruzamento por Lote'!$B$5:$B$98,$B50) -> 461.9 | F50: =SUMIFS('Cruzamento por Lote'!$F$5:$F$98,'Cruzamento por Lote'!$A$5:$A$98,$A50,'Cruzamento por Lote'!$B$5:$B$98,$B50) -> 442.2 | G50: =E50-F50 -> 19.7 | H50: =SUMIFS('Cruzamento por Lote'!$H$5:$H$98,'Cruzamento por Lote'!$A$5:$A$98,$A50,'Cruzamento por Lote'!$B$5:$B$98,$B50) -> 19.7 | I50: =ROUND(H50-G50,2) -> 0 | J50: =IF(ABS(I50)<=Resumo!$C$7,"Confere",IF(I50>0,"Sobrando","Faltando")) -> Confere | K50: =IF(J50="Confere","Nada a fazer",IF(J50="Faltando","Procurar saída, ajuste ou devolução que não está na lista",IF(F50>E50,"Saiu mais do que entrou: confirmar o estoque que já existia antes de 09/09","Conferir estoque de antes de 09/09 ou entrada não lançada"))) -> Nada a fazer
A51: 823-BR-25A | B51: 252940301 | C51: CA MOEDAS 2,01KG/UC 10UC/CX 30CX/PAL | D51: KG | E51: =SUMIFS('Cruzamento por Lote'!$E$5:$E$98,'Cruzamento por Lote'!$A$5:$A$98,$A51,'Cruzamento por Lote'!$B$5:$B$98,$B51) -> 1809 | F51: =SUMIFS('Cruzamento por Lote'!$F$5:$F$98,'Cruzamento por Lote'!$A$5:$A$98,$A51,'Cruzamento por Lote'!$B$5:$B$98,$B51) -> 1025.1 | G51: =E51-F51 -> 783.9 | H51: =SUMIFS('Cruzamento por Lote'!$H$5:$H$98,'Cruzamento por Lote'!$A$5:$A$98,$A51,'Cruzamento por Lote'!$B$5:$B$98,$B51) -> 783.9 | I51: =ROUND(H51-G51,2) -> 0 | J51: =IF(ABS(I51)<=Resumo!$C$7,"Confere",IF(I51>0,"Sobrando","Faltando")) -> Confere | K51: =IF(J51="Confere","Nada a fazer",IF(J51="Faltando","Procurar saída, ajuste ou devolução que não está na lista",IF(F51>E51,"Saiu mais do que entrou: confirmar o estoque que já existia antes de 09/09","Conferir estoque de antes de 09/09 ou entrada não lançada"))) -> Nada a fazer
A52: 823NV-132 | B52: 260880201 | D52: KG | E52: =SUMIFS('Cruzamento por Lote'!$E$5:$E$98,'Cruzamento por Lote'!$A$5:$A$98,$A52,'Cruzamento por Lote'!$B$5:$B$98,$B52) -> 1000 | F52: =SUMIFS('Cruzamento por Lote'!$F$5:$F$98,'Cruzamento por Lote'!$A$5:$A$98,$A52,'Cruzamento por Lote'!$B$5:$B$98,$B52) -> 0 | G52: =E52-F52 -> 1000 | H52: =SUMIFS('Cruzamento por Lote'!$H$5:$H$98,'Cruzamento por Lote'!$A$5:$A$98,$A52,'Cruzamento por Lote'!$B$5:$B$98,$B52) -> 1000 | I52: =ROUND(H52-G52,2) -> 0 | J52: =IF(ABS(I52)<=Resumo!$C$7,"Confere",IF(I52>0,"Sobrando","Faltando")) -> Confere | K52: =IF(J52="Confere","Nada a fazer",IF(J52="Faltando","Procurar saída, ajuste ou devolução que não está na lista",IF(F52>E52,"Saiu mais do que entrou: confirmar o estoque que já existia antes de 09/09","Conferir estoque de antes de 09/09 ou entrada não lançada"))) -> Nada a fazer
A53: 823NV-595 | B53: 260416102 | C53: CA CALLETS 10KG/UC 2UC/BOX 30BOX/PAL | D53: KG | E53: =SUMIFS('Cruzamento por Lote'!$E$5:$E$98,'Cruzamento por Lote'!$A$5:$A$98,$A53,'Cruzamento por Lote'!$B$5:$B$98,$B53) -> 1800 | F53: =SUMIFS('Cruzamento por Lote'!$F$5:$F$98,'Cruzamento por Lote'!$A$5:$A$98,$A53,'Cruzamento por Lote'!$B$5:$B$98,$B53) -> 0 | G53: =E53-F53 -> 1800 | H53: =SUMIFS('Cruzamento por Lote'!$H$5:$H$98,'Cruzamento por Lote'!$A$5:$A$98,$A53,'Cruzamento por Lote'!$B$5:$B$98,$B53) -> 1800 | I53: =ROUND(H53-G53,2) -> 0 | J53: =IF(ABS(I53)<=Resumo!$C$7,"Confere",IF(I53>0,"Sobrando","Faltando")) -> Confere | K53: =IF(J53="Confere","Nada a fazer",IF(J53="Faltando","Procurar saída, ajuste ou devolução que não está na lista",IF(F53>E53,"Saiu mais do que entrou: confirmar o estoque que já existia antes de 09/09","Conferir estoque de antes de 09/09 ou entrada não lançada"))) -> Nada a fazer
A54: 823NV-595 | B54: 261376101 | C54: CA CALLETS 10KG/UC 2UC/BOX 30BOX/PAL | D54: KG | E54: =SUMIFS('Cruzamento por Lote'!$E$5:$E$98,'Cruzamento por Lote'!$A$5:$A$98,$A54,'Cruzamento por Lote'!$B$5:$B$98,$B54) -> 5940 | F54: =SUMIFS('Cruzamento por Lote'!$F$5:$F$98,'Cruzamento por Lote'!$A$5:$A$98,$A54,'Cruzamento por Lote'!$B$5:$B$98,$B54) -> 4940 | G54: =E54-F54 -> 1000 | H54: =SUMIFS('Cruzamento por Lote'!$H$5:$H$98,'Cruzamento por Lote'!$A$5:$A$98,$A54,'Cruzamento por Lote'!$B$5:$B$98,$B54) -> 1000 | I54: =ROUND(H54-G54,2) -> 0 | J54: =IF(ABS(I54)<=Resumo!$C$7,"Confere",IF(I54>0,"Sobrando","Faltando")) -> Confere | K54: =IF(J54="Confere","Nada a fazer",IF(J54="Faltando","Procurar saída, ajuste ou devolução que não está na lista",IF(F54>E54,"Saiu mais do que entrou: confirmar o estoque que já existia antes de 09/09","Conferir estoque de antes de 09/09 ou entrada não lançada"))) -> Nada a fazer
A55: BIG-PF-1BO-401 | B55: 26093039 | C55: CB PAILLETÉ FEUILLETINE 2.5KG/UC 4UC/BOX | D55: KG | E55: =SUMIFS('Cruzamento por Lote'!$E$5:$E$98,'Cruzamento por Lote'!$A$5:$A$98,$A55,'Cruzamento por Lote'!$B$5:$B$98,$B55) -> 720 | F55: =SUMIFS('Cruzamento por Lote'!$F$5:$F$98,'Cruzamento por Lote'!$A$5:$A$98,$A55,'Cruzamento por Lote'!$B$5:$B$98,$B55) -> 240 | G55: =E55-F55 -> 480 | H55: =SUMIFS('Cruzamento por Lote'!$H$5:$H$98,'Cruzamento por Lote'!$A$5:$A$98,$A55,'Cruzamento por Lote'!$B$5:$B$98,$B55) -> 480 | I55: =ROUND(H55-G55,2) -> 0 | J55: =IF(ABS(I55)<=Resumo!$C$7,"Confere",IF(I55>0,"Sobrando","Faltando")) -> Confere | K55: =IF(J55="Confere","Nada a fazer",IF(J55="Faltando","Procurar saída, ajuste ou devolução que não está na lista",IF(F55>E55,"Saiu mais do que entrou: confirmar o estoque que já existia antes de 09/09","Conferir estoque de antes de 09/09 ou entrada não lançada"))) -> Nada a fazer
A56: BIG-PF-1BO-401 | B56: 26126039 | C56: CB PAILLETÉ FEUILLETINE 2.5KG/UC 4UC/BOX | D56: KG | E56: =SUMIFS('Cruzamento por Lote'!$E$5:$E$98,'Cruzamento por Lote'!$A$5:$A$98,$A56,'Cruzamento por Lote'!$B$5:$B$98,$B56) -> 40 | F56: =SUMIFS('Cruzamento por Lote'!$F$5:$F$98,'Cruzamento por Lote'!$A$5:$A$98,$A56,'Cruzamento por Lote'!$B$5:$B$98,$B56) -> 0 | G56: =E56-F56 -> 40 | H56: =SUMIFS('Cruzamento por Lote'!$H$5:$H$98,'Cruzamento por Lote'!$A$5:$A$98,$A56,'Cruzamento por Lote'!$B$5:$B$98,$B56) -> 40 | I56: =ROUND(H56-G56,2) -> 0 | J56: =IF(ABS(I56)<=Resumo!$C$7,"Confere",IF(I56>0,"Sobrando","Faltando")) -> Confere | K56: =IF(J56="Confere","Nada a fazer",IF(J56="Faltando","Procurar saída, ajuste ou devolução que não está na lista",IF(F56>E56,"Saiu mais do que entrou: confirmar o estoque que já existia antes de 09/09","Conferir estoque de antes de 09/09 ou entrada não lançada"))) -> Nada a fazer
A57: CHD-BB-308BY-357 | B57: 2529778000 | C57: CB EXTRUDED 8CM STICKS 1.6KG/UC 15UC/BOX | D57: UN | E57: =SUMIFS('Cruzamento por Lote'!$E$5:$E$98,'Cruzamento por Lote'!$A$5:$A$98,$A57,'Cruzamento por Lote'!$B$5:$B$98,$B57) -> 2250 | F57: =SUMIFS('Cruzamento por Lote'!$F$5:$F$98,'Cruzamento por Lote'!$A$5:$A$98,$A57,'Cruzamento por Lote'!$B$5:$B$98,$B57) -> 885 | G57: =E57-F57 -> 1365 | H57: =SUMIFS('Cruzamento por Lote'!$H$5:$H$98,'Cruzamento por Lote'!$A$5:$A$98,$A57,'Cruzamento por Lote'!$B$5:$B$98,$B57) -> 1365 | I57: =ROUND(H57-G57,2) -> 0 | J57: =IF(ABS(I57)<=Resumo!$C$7,"Confere",IF(I57>0,"Sobrando","Faltando")) -> Confere | K57: =IF(J57="Confere","Nada a fazer",IF(J57="Faltando","Procurar saída, ajuste ou devolução que não está na lista",IF(F57>E57,"Saiu mais do que entrou: confirmar o estoque que já existia antes de 09/09","Conferir estoque de antes de 09/09 ou entrada não lançada"))) -> Nada a fazer
...

Sheet Lançamentos
A1: DATA | B1: MOVIMENTAÇÃO | C1: SKU | D1: LOTE | E1: DESCRIÇÃO | F1: DEPÓSITO | G1: UM | H1: QTD NO SAP | I1: ENTROU | J1: SAIU | K1: SALDO (±) | L1: DOCUMENTO | M1: CÓD. CLIENTE | N1: CLIENTE | O1: USUÁRIO
A2: 46274 | B2: Saída | C2: 805-BR-D94 | D2: 251633359 | E2: CA MOEDAS 0,4KG/UC 7UC/CX 144CX/PAL | F2: 9999 | G2: KG | H2: =Saida!H80 -> -5.6 | I2: 0 | J2: =Saida!R80 -> 5.6 | K2: =I2-J2 -> -5.6 | L2: 4903838325 | M2: 51879 | N2: TRANSELPE LTDA. - EPP | O2: BC140676
A3: 46274 | B3: Saída | C3: 823-BR-D94 | D3: 252103049 | E3: CA MOEDAS 0,4KG/UC 7UC/CX 144CX/PAL | F3: 9999 | G3: KG | H3: =Saida!H177 -> -5.6 | I3: 0 | J3: =Saida!R177 -> 5.6 | K3: =I3-J3 -> -5.6 | L3: 4903838325 | M3: 51879 | N3: TRANSELPE LTDA. - EPP | O3: BC140676
A4: 46274 | B4: =Entrada!K156 -> Entrada | C4: CHM-TS-22351E0-999 | D4: 2525950306 | F4: 2008 | G4: KG | H4: =Entrada!G156 -> -195.84 | I4: =Entrada!L156 -> 195.84 | J4: 0 | K4: =I4-J4 -> 195.84 | L4: 4903843886
A5: 46274 | B5: =Entrada!K157 -> Entrada | C5: CHM-TS-22351E0-999 | D5: 2526050307 | F5: 2008 | G5: KG | H5: =Entrada!G157 -> -295.12 | I5: =Entrada!L157 -> 295.12 | J5: 0 | K5: =I5-J5 -> 295.12 | L5: 4903843886
A6: 46275 | B6: =Entrada!K117 -> Recebido no 2008 | C6: 70-30-38-BR-25A | D6: 260370301 | E6: CA MOEDAS 2,01KG/UC 10UC/CX 30CX/PAL | F6: 2008 | G6: KG | H6: =Entrada!G117 -> 6633 | I6: =Entrada!L117 -> 0 | J6: 0 | K6: =I6-J6 -> 0 | L6: 4903864964
A7: 46275 | B7: Saída | C7: 70-30-38-BR-25A | D7: 260370301 | E7: CA MOEDAS 2,01KG/UC 10UC/CX 30CX/PAL | F7: 0355 | G7: KG | H7: =Saida!H29 -> -20.1 | I7: 0 | J7: =Saida!R29 -> 20.1 | K7: =I7-J7 -> -20.1 | L7: 4903867283 | M7: 78892 | N7: TANGARA DESENV IMOBIL | O7: BC025148
A8: 46275 | B8: Saída | C8: 70-30-38-BR-25A | D8: 260370301 | E8: CA MOEDAS 2,01KG/UC 10UC/CX 30CX/PAL | F8: 0355 | G8: KG | H8: =Saida!H30 -> -40.2 | I8: 0 | J8: =Saida!R30 -> 40.2 | K8: =I8-J8 -> -40.2 | L8: 4903867234 | M8: 94669 | N8: ARTISANO GELATO LTDA | O8: BC025148
A9: 46275 | B9: Saída | C9: 70-30-38-BR-D94 | D9: 253213449 | E9: CA MOEDAS 0,4KG/UC 7UC/CX 144CX/PAL | F9: 0355 | G9: KG | H9: =Saida!H55 -> -11.2 | I9: 0 | J9: =Saida!R55 -> 11.2 | K9: =I9-J9 -> -11.2 | L9: 4903867892 | M9: 43229 | N9: VIMEG COMERCIO DE CHOCOLATES LTDA | O9: BC025148
A10: 46275 | B10: =Entrada!K124 -> Recebido no 2008 | C10: 811NV-595 | D10: 261146101 | E10: CA CALLETS 10KG/UC 2UC/BOX 30BOX/PAL | F10: 2008 | G10: KG | H10: =Entrada!G124 -> 4360 | I10: =Entrada!L124 -> 0 | J10: 0 | K10: =I10-J10 -> 0 | L10: 4903865743
A11: 46275 | B11: =Entrada!K123 -> Recebido no 2008 | C11: 811NV-595 | D11: 261146102 | E11: CA CALLETS 10KG/UC 2UC/BOX 30BOX/PAL | F11: 2008 | G11: KG | H11: =Entrada!G123 -> 5240 | I11: =Entrada!L123 -> 0 | J11: 0 | K11: =I11-J11 -> 0 | L11: 4903865743
A12: 46275 | B12: Saída | C12: 823-BR-D94 | D12: 252103049 | E12: CA MOEDAS 0,4KG/UC 7UC/CX 144CX/PAL | F12: 9999 | G12: KG | H12: =Saida!H175 -> -28 | I12: 0 | J12: =Saida!R175 -> 28 | K12: =I12-J12 -> -28 | L12: 4903869423 | M12: 48470 | N12: MARIA CHOCOLATE LTDA | O12: BC116065
A13: 46275 | B13: Saída | C13: 823-BR-D94 | D13: 252103049 | E13: CA MOEDAS 0,4KG/UC 7UC/CX 144CX/PAL | F13: 0355 | G13: KG | H13: =Saida!H176 -> -14 | I13: 0 | J13: =Saida!R176 -> 14 | K13: =I13-J13 -> -14 | L13: 4903867892 | M13: 43229 | N13: VIMEG COMERCIO DE CHOCOLATES LTDA | O13: BC025148
A14: 46275 | B14: =Entrada!K128 -> Recebido no 2008 | C14: 823NV-595 | D14: 261376101 | E14: CA CALLETS 10KG/UC 2UC/BOX 30BOX/PAL | F14: 2008 | G14: KG | H14: =Entrada!G128 -> 2400 | I14: =Entrada!L128 -> 0 | J14: 0 | K14: =I14-J14 -> 0 | L14: 4903867530
A15: 46275 | B15: =Entrada!K129 -> Recebido no 2008 | C15: 823NV-595 | D15: 261376101 | E15: CA CALLETS 10KG/UC 2UC/BOX 30BOX/PAL | F15: 2008 | G15: KG | H15: =Entrada!G129 -> 3600 | I15: =Entrada!L129 -> 0 | J15: 0 | K15: =I15-J15 -> 0 | L15: 4903867183
A16: 46275 | B16: Saída | C16: BIG-PF-1BO-401 | D16: 26044019 | E16: CB PAILLETÉ FEUILLETINE 2.5KG/UC 4UC/BOX | F16: 9999 | G16: KG | H16: =Saida!H188 -> -10 | I16: 0 | J16: =Saida!R188 -> 10 | K16: =I16-J16 -> -10 | L16: 4903859705 | M16: 90486 | N16: GI CARVALHO DOCERIA UBERABA LTDA | O16: BC147417
A17: 46275 | B17: =Entrada!K133 -> Recebido no 2008 | C17: BIG-PF-1BO-401 | D17: 26126039 | E17: CB PAILLETÉ FEUILLETINE 2.5KG/UC 4UC/BOX | F17: 2008 | G17: KG | H17: =Entrada!G133 -> 960 | I17: =Entrada!L133 -> 0 | J17: 0 | K17: =I17-J17 -> 0 | L17: 4903866106
A18: 46275 | B18: =Entrada!K134 -> Recebido no 2008 | C18: BIG-PF-1BO-401 | D18: 26126039 | E18: CB PAILLETÉ FEUILLETINE 2.5KG/UC 4UC/BOX | F18: 2008 | G18: KG | H18: =Entrada!G134 -> 1920 | I18: =Entrada!L134 -> 0 | J18: 0 | K18: =I18-J18 -> 0 | L18: 4903863360
A19: 46275 | B19: =Entrada!K137 -> Recebido no 2008 | C19: CHD-SP-1M-2B-U77 | D19: 260880101 | F19: 2008 | G19: KG | H19: =Entrada!G137 -> 600 | I19: =Entrada!L137 -> 0 | J19: 0 | K19: =I19-J19 -> 0 | L19: 4903864964
A20: 46275 | B20: =Entrada!K138 -> Recebido no 2008 | C20: CHD-SP-1M-2B-U77 | D20: 260880101 | F20: 2008 | G20: KG | H20: =Entrada!G138 -> 1800 | I20: =Entrada!L138 -> 0 | J20: 0 | K20: =I20-J20 -> 0 | L20: 4903863360
A21: 46275 | B21: =Entrada!K140 -> Recebido no 2008 | C21: CHD-SP-1M-BR-U73 | D21: 260310301 | F21: 2008 | G21: KG | H21: =Entrada!G140 -> 798 | I21: =Entrada!L140 -> 0 | J21: 0 | K21: =I21-J21 -> 0 | L21: 4903864964
A22: 46275 | B22: =Entrada!K139 -> Recebido no 2008 | C22: CHD-SP-1M-BR-U73 | D22: 260880301 | F22: 2008 | G22: KG | H22: =Entrada!G139 -> 1122 | I22: =Entrada!L139 -> 0 | J22: 0 | K22: =I22-J22 -> 0 | L22: 4903864964
A23: 46275 | B23: =Entrada!K142 -> Recebido no 2008 | C23: CHD-VR-Z2S-E0-U68 | D23: 261160301 | F23: 2008 | G23: KG | H23: =Entrada!G142 -> 1296 | I23: =Entrada!L142 -> 0 | J23: 0 | K23: =I23-J23 -> 0 | L23: 4903863360
A24: 46275 | B24: =Entrada!K146 -> Recebido no 2008 | C24: CHK-R30GOLD-BR-25A | D24: 252750301 | E24: CA MOEDAS 2,01KG/UC 10UC/CX 30CX/PAL | F24: 2008 | G24: KG | H24: =Entrada!G146 -> 160.8 | I24: =Entrada!L146 -> 0 | J24: 0 | K24: =I24-J24 -> 0 | L24: 4903865743
