Workbook

Sheet Lançamentos
A1: Volume por Turno — Setembro 2026
A2: Preencha apenas as células amarelas (Data, Turno, Divisão, Volume Planejado e Volume Realizado). O resto é calculado automaticamente.
A4: Data | B4: Dia | C4: Turno | D4: Divisão | E4: Volume Planejado (t) | F4: Volume Realizado (t) | G4: Atingimento % | H4: Saldo (t) | I4: Observação
A5: 46277 | B5: =IFERROR(CHOOSE(WEEKDAY(A5),"DOMINGO","SEGUNDA","TERÇA","QUARTA","QUINTA","SEXTA","SÁBADO"),"") -> SÁBADO | C5: C | D5: SMART LOG | E5: 13900 | F5: 13900 | G5: =IF(E5=0,"",F5/E5) -> 1 | H5: =IF(E5=0,"",E5-F5) -> 0 | I5: =IF(E5=0,"",IF(G5>=1,"Realizado",IF(G5>=0.9,"Parcial","Abaixo da meta"))) -> Realizado
A6: 46277 | B6: =IFERROR(CHOOSE(WEEKDAY(A6),"DOMINGO","SEGUNDA","TERÇA","QUARTA","QUINTA","SEXTA","SÁBADO"),"") -> SÁBADO | C6: D | D6: SMART LOG | E6: 77159 | F6: 77159 | G6: =IF(E6=0,"",F6/E6) -> 1 | H6: =IF(E6=0,"",E6-F6) -> 0 | I6: =IF(E6=0,"",IF(G6>=1,"Realizado",IF(G6>=0.9,"Parcial","Abaixo da meta"))) -> Realizado
A7: 46278 | B7: =IFERROR(CHOOSE(WEEKDAY(A7),"DOMINGO","SEGUNDA","TERÇA","QUARTA","QUINTA","SEXTA","SÁBADO"),"") -> DOMINGO | C7: C | D7: RJ | E7: 24960 | F7: 24960 | G7: =IF(E7=0,"",F7/E7) -> 1 | H7: =IF(E7=0,"",E7-F7) -> 0 | I7: =IF(E7=0,"",IF(G7>=1,"Realizado",IF(G7>=0.9,"Parcial","Abaixo da meta"))) -> Realizado
A8: 46278 | B8: =IFERROR(CHOOSE(WEEKDAY(A8),"DOMINGO","SEGUNDA","TERÇA","QUARTA","QUINTA","SEXTA","SÁBADO"),"") -> DOMINGO | C8: D | D8: SUL | E8: 40121 | F8: 37121 | G8: =IF(E8=0,"",F8/E8) -> 0.92522619 | H8: =IF(E8=0,"",E8-F8) -> 3000 | I8: =IF(E8=0,"",IF(G8>=1,"Realizado",IF(G8>=0.9,"Parcial","Abaixo da meta"))) -> Parcial
A9: 46279 | B9: =IFERROR(CHOOSE(WEEKDAY(A9),"DOMINGO","SEGUNDA","TERÇA","QUARTA","QUINTA","SEXTA","SÁBADO"),"") -> SEGUNDA | C9: A | D9: SUL | E9: 3000 | F9: 3000 | G9: =IF(E9=0,"",F9/E9) -> 1 | H9: =IF(E9=0,"",E9-F9) -> 0 | I9: =IF(E9=0,"",IF(G9>=1,"Realizado",IF(G9>=0.9,"Parcial","Abaixo da meta"))) -> Realizado
B10: =IFERROR(CHOOSE(WEEKDAY(A10),"DOMINGO","SEGUNDA","TERÇA","QUARTA","QUINTA","SEXTA","SÁBADO"),"") -> SÁBADO | G10: =IF(E10=0,"",F10/E10) | H10: =IF(E10=0,"",E10-F10) | I10: =IF(E10=0,"",IF(G10>=1,"Realizado",IF(G10>=0.9,"Parcial","Abaixo da meta")))
B11: =IFERROR(CHOOSE(WEEKDAY(A11),"DOMINGO","SEGUNDA","TERÇA","QUARTA","QUINTA","SEXTA","SÁBADO"),"") -> SÁBADO | G11: =IF(E11=0,"",F11/E11) | H11: =IF(E11=0,"",E11-F11) | I11: =IF(E11=0,"",IF(G11>=1,"Realizado",IF(G11>=0.9,"Parcial","Abaixo da meta")))
B12: =IFERROR(CHOOSE(WEEKDAY(A12),"DOMINGO","SEGUNDA","TERÇA","QUARTA","QUINTA","SEXTA","SÁBADO"),"") -> SÁBADO | G12: =IF(E12=0,"",F12/E12) | H12: =IF(E12=0,"",E12-F12) | I12: =IF(E12=0,"",IF(G12>=1,"Realizado",IF(G12>=0.9,"Parcial","Abaixo da meta")))
B13: =IFERROR(CHOOSE(WEEKDAY(A13),"DOMINGO","SEGUNDA","TERÇA","QUARTA","QUINTA","SEXTA","SÁBADO"),"") -> SÁBADO | G13: =IF(E13=0,"",F13/E13) | H13: =IF(E13=0,"",E13-F13) | I13: =IF(E13=0,"",IF(G13>=1,"Realizado",IF(G13>=0.9,"Parcial","Abaixo da meta")))
B14: =IFERROR(CHOOSE(WEEKDAY(A14),"DOMINGO","SEGUNDA","TERÇA","QUARTA","QUINTA","SEXTA","SÁBADO"),"") -> SÁBADO | G14: =IF(E14=0,"",F14/E14) | H14: =IF(E14=0,"",E14-F14) | I14: =IF(E14=0,"",IF(G14>=1,"Realizado",IF(G14>=0.9,"Parcial","Abaixo da meta")))
B15: =IFERROR(CHOOSE(WEEKDAY(A15),"DOMINGO","SEGUNDA","TERÇA","QUARTA","QUINTA","SEXTA","SÁBADO"),"") -> SÁBADO | G15: =IF(E15=0,"",F15/E15) | H15: =IF(E15=0,"",E15-F15) | I15: =IF(E15=0,"",IF(G15>=1,"Realizado",IF(G15>=0.9,"Parcial","Abaixo da meta")))
B16: =IFERROR(CHOOSE(WEEKDAY(A16),"DOMINGO","SEGUNDA","TERÇA","QUARTA","QUINTA","SEXTA","SÁBADO"),"") -> SÁBADO | G16: =IF(E16=0,"",F16/E16) | H16: =IF(E16=0,"",E16-F16) | I16: =IF(E16=0,"",IF(G16>=1,"Realizado",IF(G16>=0.9,"Parcial","Abaixo da meta")))
B17: =IFERROR(CHOOSE(WEEKDAY(A17),"DOMINGO","SEGUNDA","TERÇA","QUARTA","QUINTA","SEXTA","SÁBADO"),"") -> SÁBADO | G17: =IF(E17=0,"",F17/E17) | H17: =IF(E17=0,"",E17-F17) | I17: =IF(E17=0,"",IF(G17>=1,"Realizado",IF(G17>=0.9,"Parcial","Abaixo da meta")))
B18: =IFERROR(CHOOSE(WEEKDAY(A18),"DOMINGO","SEGUNDA","TERÇA","QUARTA","QUINTA","SEXTA","SÁBADO"),"") -> SÁBADO | G18: =IF(E18=0,"",F18/E18) | H18: =IF(E18=0,"",E18-F18) | I18: =IF(E18=0,"",IF(G18>=1,"Realizado",IF(G18>=0.9,"Parcial","Abaixo da meta")))
B19: =IFERROR(CHOOSE(WEEKDAY(A19),"DOMINGO","SEGUNDA","TERÇA","QUARTA","QUINTA","SEXTA","SÁBADO"),"") -> SÁBADO | G19: =IF(E19=0,"",F19/E19) | H19: =IF(E19=0,"",E19-F19) | I19: =IF(E19=0,"",IF(G19>=1,"Realizado",IF(G19>=0.9,"Parcial","Abaixo da meta")))
B20: =IFERROR(CHOOSE(WEEKDAY(A20),"DOMINGO","SEGUNDA","TERÇA","QUARTA","QUINTA","SEXTA","SÁBADO"),"") -> SÁBADO | G20: =IF(E20=0,"",F20/E20) | H20: =IF(E20=0,"",E20-F20) | I20: =IF(E20=0,"",IF(G20>=1,"Realizado",IF(G20>=0.9,"Parcial","Abaixo da meta")))
B21: =IFERROR(CHOOSE(WEEKDAY(A21),"DOMINGO","SEGUNDA","TERÇA","QUARTA","QUINTA","SEXTA","SÁBADO"),"") -> SÁBADO | G21: =IF(E21=0,"",F21/E21) | H21: =IF(E21=0,"",E21-F21) | I21: =IF(E21=0,"",IF(G21>=1,"Realizado",IF(G21>=0.9,"Parcial","Abaixo da meta")))
... B155: =IFERROR(CHOOSE(WEEKDAY(A155),"DOMINGO","SEGUNDA","TERÇA","QUARTA","QUINTA","SEXTA","SÁBADO"),"") -> SÁBADO | G155: =IF(E155=0,"",F155/E155) | H155: =IF(E155=0,"",E155-F155) | I155: =IF(E155=0,"",IF(G155>=1,"Realizado",IF(G155>=0.9,"Parcial","Abaixo da meta")))

Sheet Painel
A1: Painel — Volume por Turno
A2: Atualiza automaticamente conforme você preenche a aba Lançamentos.
A4: Totais do mês
A5: Volume Planejado (t) | B5: =SUM(Lançamentos!$E$5:$E$155) -> 159140
A6: Volume Realizado (t) | B6: =SUM(Lançamentos!$F$5:$F$155) -> 156140
A7: Saldo (t) | B7: =B5-B6 -> 3000
A8: Atingimento % geral | B8: =IF(B5=0,"",B6/B5) -> 0.98114867
A10: Resumo por Divisão
A11: Divisão | B11: Planejado (t) | C11: Realizado (t) | D11: Atingimento %
A12: SMART LOG | B12: =SUMIFS(Lançamentos!$E$5:$E$155,Lançamentos!$D$5:$D$155,A12) -> 91059 | C12: =SUMIFS(Lançamentos!$F$5:$F$155,Lançamentos!$D$5:$D$155,A12) -> 91059 | D12: =IF(B12=0,"",C12/B12) -> 1
A13: RJ | B13: =SUMIFS(Lançamentos!$E$5:$E$155,Lançamentos!$D$5:$D$155,A13) -> 24960 | C13: =SUMIFS(Lançamentos!$F$5:$F$155,Lançamentos!$D$5:$D$155,A13) -> 24960 | D13: =IF(B13=0,"",C13/B13) -> 1
A14: SUL | B14: =SUMIFS(Lançamentos!$E$5:$E$155,Lançamentos!$D$5:$D$155,A14) -> 43121 | C14: =SUMIFS(Lançamentos!$F$5:$F$155,Lançamentos!$D$5:$D$155,A14) -> 40121 | D14: =IF(B14=0,"",C14/B14) -> 0.93042833
A15: SP | B15: =SUMIFS(Lançamentos!$E$5:$E$155,Lançamentos!$D$5:$D$155,A15) -> 0 | C15: =SUMIFS(Lançamentos!$F$5:$F$155,Lançamentos!$D$5:$D$155,A15) -> 0 | D15: =IF(B15=0,"",C15/B15)
A16: MG | B16: =SUMIFS(Lançamentos!$E$5:$E$155,Lançamentos!$D$5:$D$155,A16) -> 0 | C16: =SUMIFS(Lançamentos!$F$5:$F$155,Lançamentos!$D$5:$D$155,A16) -> 0 | D16: =IF(B16=0,"",C16/B16)
A17: NORDESTE | B17: =SUMIFS(Lançamentos!$E$5:$E$155,Lançamentos!$D$5:$D$155,A17) -> 0 | C17: =SUMIFS(Lançamentos!$F$5:$F$155,Lançamentos!$D$5:$D$155,A17) -> 0 | D17: =IF(B17=0,"",C17/B17)
A19: Resumo por Turno
A20: Turno | B20: Planejado (t) | C20: Realizado (t) | D20: Atingimento %
A21: A | B21: =SUMIFS(Lançamentos!$E$5:$E$155,Lançamentos!$C$5:$C$155,A21) -> 3000 | C21: =SUMIFS(Lançamentos!$F$5:$F$155,Lançamentos!$C$5:$C$155,A21) -> 3000 | D21: =IF(B21=0,"",C21/B21) -> 1
A22: B | B22: =SUMIFS(Lançamentos!$E$5:$E$155,Lançamentos!$C$5:$C$155,A22) -> 0 | C22: =SUMIFS(Lançamentos!$F$5:$F$155,Lançamentos!$C$5:$C$155,A22) -> 0 | D22: =IF(B22=0,"",C22/B22)
A23: C | B23: =SUMIFS(Lançamentos!$E$5:$E$155,Lançamentos!$C$5:$C$155,A23) -> 38860 | C23: =SUMIFS(Lançamentos!$F$5:$F$155,Lançamentos!$C$5:$C$155,A23) -> 38860 | D23: =IF(B23=0,"",C23/B23) -> 1
A24: D | B24: =SUMIFS(Lançamentos!$E$5:$E$155,Lançamentos!$C$5:$C$155,A24) -> 117280 | C24: =SUMIFS(Lançamentos!$F$5:$F$155,Lançamentos!$C$5:$C$155,A24) -> 114280 | D24: =IF(B24=0,"",C24/B24) -> 0.97442019
A27: Configurações de Alerta
A28: Meta mínima de Atingimento (%) | B28: 0.9
A29: Limite de Saldo Semanal (t) | B29: 5000
A31: Alertas por Divisão
A32: Divisão | B32: Atingimento % | C32: Saldo (t) | D32: Status
A33: =A12 -> SMART LOG | B33: =D12 -> 1 | C33: =B12-C12 -> 0 | D33: =IF(B12=0,"Sem dados",IF(B33<$B$28,"🔴 ALERTA","✅ OK")) -> ✅ OK
A34: =A13 -> RJ | B34: =D13 -> 1 | C34: =B13-C13 -> 0 | D34: =IF(B13=0,"Sem dados",IF(B34<$B$28,"🔴 ALERTA","✅ OK")) -> ✅ OK
A35: =A14 -> SUL | B35: =D14 -> 0.93042833 | C35: =B14-C14 -> 3000 | D35: =IF(B14=0,"Sem dados",IF(B35<$B$28,"🔴 ALERTA","✅ OK")) -> ✅ OK
A36: =A15 -> SP | B36: =D15 | C36: =B15-C15 -> 0 | D36: =IF(B15=0,"Sem dados",IF(B36<$B$28,"🔴 ALERTA","✅ OK")) -> Sem dados
A37: =A16 -> MG | B37: =D16 | C37: =B16-C16 -> 0 | D37: =IF(B16=0,"Sem dados",IF(B37<$B$28,"🔴 ALERTA","✅ OK")) -> Sem dados
A38: =A17 -> NORDESTE | B38: =D17 | C38: =B17-C17 -> 0 | D38: =IF(B17=0,"Sem dados",IF(B38<$B$28,"🔴 ALERTA","✅ OK")) -> Sem dados
A40: Alertas por Turno
A41: Turno | B41: Atingimento % | C41: Saldo (t) | D41: Status
A42: =A21 -> A | B42: =D21 -> 1 | C42: =B21-C21 -> 0 | D42: =IF(B21=0,"Sem dados",IF(B42<$B$28,"🔴 ALERTA","✅ OK")) -> ✅ OK
A43: =A22 -> B | B43: =D22 | C43: =B22-C22 -> 0 | D43: =IF(B22=0,"Sem dados",IF(B43<$B$28,"🔴 ALERTA","✅ OK")) -> Sem dados
A44: =A23 -> C | B44: =D23 -> 1 | C44: =B23-C23 -> 0 | D44: =IF(B23=0,"Sem dados",IF(B44<$B$28,"🔴 ALERTA","✅ OK")) -> ✅ OK
A45: =A24 -> D | B45: =D24 -> 0.97442019 | C45: =B24-C24 -> 3000 | D45: =IF(B24=0,"Sem dados",IF(B45<$B$28,"🔴 ALERTA","✅ OK")) -> ✅ OK
A47: Maiores Desvios do Mês (Top 3 Divisões)
A48: Divisão | B48: Saldo (t) | C48: Atingimento %
...
