Workbook

Sheet MENU
B2: ZBR IMPORTADO
B3: Relatório de Gestão de Estoque
B4: Entradas, saídas, estoque físico, conciliação e plano de ação · Centro BR01
B7: Fonte dos dados | C7: Exportação SAP "Analise_ZBR_importado.XLSX" (abas Entrada, Saida, Estoque atual)
B8: Período dos movimentos | C8: 09/09/2026 a 01/10/2026
B9: Gerado em | C9: =Parâmetros!K9 -> 46297
B11: RESULTADO EM 1 MINUTO
B12: ="Conferem: "&'2 Resumo Gerencial'!D19&" de "&'2 Resumo Gerencial'!C19&" SKU·lote ("&FIXED('2 Resumo Gerencial'!F19*100,1)&"%)." -> Conferem: 66 de 94 SKU·lote (70.2%).
B13: ="Com diferença: "&'2 Resumo Gerencial'!E19&" SKU·lote — "&'2 Resumo Gerencial'!C34&" críticos, tratar primeiro (ver 6 Plano de Ação)." -> Com diferença: 28 SKU·lote — 3 críticos, tratar primeiro (ver 6 Plano de Ação).
B14: ="Parado no depósito 2008: "&FIXED('2 Resumo Gerencial'!C54,1)&" KG de importação em "&'2 Resumo Gerencial'!C53&" lotes, aguardando transferência." -> Parado no depósito 2008: 54,295.8 KG de importação em 33 lotes, aguardando transferência.
B15: =IF(SUM('3 Base Saldo Inicial 08-09'!$E$2:$E$5000)=0,"Saldo inicial de 08/09: ainda não informado — preencha a aba 3 Base Saldo Inicial (ou use o Power Query).","Saldo inicial de 08/09: informado e já considerado nas diferenças.") -> Saldo inicial de 08/09: ainda não informado — preencha a aba 3 Base Saldo Inicial (ou use o Power Query).
B16: ="Plano de ação: "&('2 Resumo Gerencial'!C58-'2 Resumo Gerencial'!C61)&" ações em aberto, "&'2 Resumo Gerencial'!C64&" sem responsável." -> Plano de ação: 61 ações em aberto, 61 sem responsável.
B18: NAVEGAÇÃO
B19: ABA | C19: PARA QUE SERVE | D19: ABRIR
B20: 1 Dashboard | C20: Visão executiva: indicadores, gráficos e filtros | D20: Abrir →
B21: 2 Resumo Gerencial | C21: O que aconteceu, em poucas linhas e números | D21: Abrir →
B22: 3 Base Entrada 2008 | C22: Dados do SAP: movimentos do depósito 2008 | D22: Abrir →
B23: 3 Base Saídas | C23: Dados do SAP: saídas 601 | D23: Abrir →
B24: 3 Base Estoque Físico | C24: Dados do SAP: posições de estoque | D24: Abrir →
B25: 3 Base Saldo Inicial 08-09 | C25: Estoque de 08/09 (preencher) — melhora a precisão das diferenças | D25: Abrir →
B26: 3 Base Movimentos | C26: Entradas e saídas juntas, para consulta | D26: Abrir →
B27: 4 Análise ZBR | C27: Por SKU·lote: deveria ter × tem, diferença, motivo e solução | D27: Abrir →
B28: 4 Análise Depósito 2008 | C28: Importação recebida, transferida e parada no 2008 | D28: Abrir →
B29: 5 Conciliação | C29: Todas as diferenças com motivo, categoria e criticidade | D29: Abrir →
B30: 6 Plano de Ação | C30: O que fazer, quem, até quando e status | D30: Abrir →
... B33: Parâmetros | C33: Datas, tolerância, limites e caminho do arquivo SAP | D33: Abrir →
B35: COMO USAR
B36: 1. Leia o "Resultado em 1 minuto" acima.
B37: 2. No 1 Dashboard, escolha período, SKU, lote, unidade e status nas células azul-claras (seta ▼).
B38: 3. Para saber o porquê de uma diferença, veja Motivo e Solução no 4 Análise ZBR.
B39: 4. Registre responsável, prazo e status no 6 Plano de Ação.
B40: 5. Nova extração do SAP: aba 8 Atualizar Dados (Power Query) — inclua o saldo de 08/09.
B42: CORES
B43: Verde: confere / concluído
B44: Amarelo: atenção / em andamento
B45: Vermelho: crítico / vencido / faltando
B46: Cinza: não iniciado / sem informação
B47: Azul-claro: célula para escolher ou preencher

Sheet 1 Dashboard
A1: Dashboard Executivo — ZBR Importado | P1: ◄ MENU
A2: Centro BR01 · movimentos de 09/09 a 01/10/2026 · fonte: exportação SAP "Analise_ZBR_importado.XLSX" · relatório gerado em 02/10/2026
A4: DATA INICIAL | C4: DATA FINAL | E4: SKU (CATEGORIA) | H4: LOTE | J4: UNIDADE | K4: TIPO DE MOVIMENTAÇÃO | N4: STATUS (SITUAÇÃO)
A5: 46274 | C5: 46296 | E5: Todos | H5: Todos | J5: KG | K5: Todas | N5: Todos
A6: ='4 Análise ZBR'!A7&IF(N5="Todos",""," · status "&N5) -> Mostrando: todos os SKUs · 9/9/2026 a 1/10/2026 · unidade KG | K6: Clique numa célula azul-clara e use a seta ▼. Os filtros valem para todas as análises.
A7: INDICADORES PRINCIPAIS
A8: ="VOLUME ANALISADO · "&'4 Análise ZBR'!$R$3 -> VOLUME ANALISADO · KG | C8: SKU·LOTE ANALISADOS | E8: MOVIMENTAÇÕES | G8: DIVERGÊNCIAS | I8: % CONFORMIDADE | K8: PENDÊNCIAS EM ABERTO | M8: OCORRÊNCIAS CRÍTICAS | O8: % CONCLUSÃO DAS AÇÕES
A9: =SUMPRODUCT('4 Análise ZBR'!$AA$40:$AA$133,'4 Análise ZBR'!$W$40:$W$133)+SUMPRODUCT('4 Análise ZBR'!$AA$40:$AA$133,'4 Análise ZBR'!$X$40:$X$133) -> 92199.08 | C9: =SUM('4 Análise ZBR'!$AA$40:$AA$133) -> 81 | E9: =SUMPRODUCT('4 Análise ZBR'!$AA$40:$AA$133,'4 Análise ZBR'!$AD$40:$AD$133) -> 526 | G9: =COUNTIFS('4 Análise ZBR'!$AA$40:$AA$133,1,'4 Análise ZBR'!$AC$40:$AC$133,"<>Confere") -> 23 | I9: =IF(SUM('4 Análise ZBR'!$AA$40:$AA$133)=0,0,COUNTIFS('4 Análise ZBR'!$AA$40:$AA$133,1,'4 Análise ZBR'!$AC$40:$AC$133,"Confere")/SUM('4 Análise ZBR'!$AA$40:$AA$133)) -> 0.71604938 | K9: =COUNTIFS('6 Plano de Ação'!$A$8:$A$507,"OC-*",'6 Plano de Ação'!$O$8:$O$507,"<>Concluído",'6 Plano de Ação'!$O$8:$O$507,"<>Cancelado") -> 61 | M9: =COUNTIFS('4 Análise ZBR'!$AA$40:$AA$133,1,'4 Análise ZBR'!$BF$40:$BF$133,"Crítica") -> 3 | O9: =IF(COUNTIF('6 Plano de Ação'!$A$8:$A$507,"OC-*")=0,0,COUNTIF('6 Plano de Ação'!$O$8:$O$507,"Concluído")/COUNTIF('6 Plano de Ação'!$A$8:$A$507,"OC-*")) -> 0
A10: entrou + saiu no ZBR | C10: registros no filtro | E10: lançamentos no filtro | G10: SKU·lote com diferença | I10: SKU·lote que conferem | K10: ações do plano (geral) | M10: criticidade proposta | O10: plano de ação (geral)
A12: ="QUANTIDADES · "&'4 Análise ZBR'!$R$3 -> QUANTIDADES · KG
A13: ENTROU NO ZBR | D13: SAIU | G13: DEVERIA TER | J13: ESTOQUE FÍSICO | M13: DIFERENÇA | O13: AGUARDANDO NO 2008
A14: =SUMPRODUCT('4 Análise ZBR'!$AA$40:$AA$133,'4 Análise ZBR'!$W$40:$W$133) -> 65930.28 | D14: =SUMPRODUCT('4 Análise ZBR'!$AA$40:$AA$133,'4 Análise ZBR'!$X$40:$X$133) -> 26268.8 | G14: =SUMPRODUCT('4 Análise ZBR'!$AA$40:$AA$133,'4 Análise ZBR'!$BH$40:$BH$133)+A14-D14 -> 39661.48 | J14: =SUMPRODUCT('4 Análise ZBR'!$AA$40:$AA$133,'4 Análise ZBR'!$Y$40:$Y$133) -> 59270.487 | M14: =ROUND(J14-G14,3) -> 19609.007 | O14: =SUMPRODUCT('4 Análise Depósito 2008'!$Z$40:$Z$133*('4 Análise Depósito 2008'!$Y$40:$Y$133>0)*'4 Análise Depósito 2008'!$Y$40:$Y$133) -> 54295.8
A15: transferido do 2008 | D15: vendas e entregas (601) | G15: saldo inicial + entrou − saiu | J15: posição atual no depósito | M15: físico − deveria ter | O15: importação não transferida
A17: GRÁFICOS GERENCIAIS
T19: Categoria da causa | U19: Ocorrências
T20: Falta sem explicação | U20: =COUNTIFS('4 Análise ZBR'!$AA$40:$AA$133,1,'4 Análise ZBR'!$BE$40:$BE$133,T20) -> 2
T21: Não localizado no estoque | U21: =COUNTIFS('4 Análise ZBR'!$AA$40:$AA$133,1,'4 Análise ZBR'!$BE$40:$BE$133,T21) -> 1
T22: Saída sem baixa no estoque | U22: =COUNTIFS('4 Análise ZBR'!$AA$40:$AA$133,1,'4 Análise ZBR'!$BE$40:$BE$133,T22) -> 8
T23: Doca/transferência pendente | U23: =COUNTIFS('4 Análise ZBR'!$AA$40:$AA$133,1,'4 Análise ZBR'!$BE$40:$BE$133,T23) -> 1
T24: Estoque anterior a 09/09 | U24: =COUNTIFS('4 Análise ZBR'!$AA$40:$AA$133,1,'4 Análise ZBR'!$BE$40:$BE$133,T24) -> 3
T25: Troca de lote | U25: =COUNTIFS('4 Análise ZBR'!$AA$40:$AA$133,1,'4 Análise ZBR'!$BE$40:$BE$133,T25) -> 0
T26: Sobra parcialmente explicada | U26: =COUNTIFS('4 Análise ZBR'!$AA$40:$AA$133,1,'4 Análise ZBR'!$BE$40:$BE$133,T26) -> 7
T27: Sobra sem explicação | U27: =COUNTIFS('4 Análise ZBR'!$AA$40:$AA$133,1,'4 Análise ZBR'!$BE$40:$BE$133,T27) -> 1
T30: Situação | U30: SKU·lote
T31: Confere | U31: =COUNTIFS('4 Análise ZBR'!$AA$40:$AA$133,1,'4 Análise ZBR'!$AC$40:$AC$133,T31) -> 58
T32: Sobrando | U32: =COUNTIFS('4 Análise ZBR'!$AA$40:$AA$133,1,'4 Análise ZBR'!$AC$40:$AC$133,T32) -> 20
T33: Faltando | U33: =COUNTIFS('4 Análise ZBR'!$AA$40:$AA$133,1,'4 Análise ZBR'!$AC$40:$AC$133,T33) -> 3
T36: Criticidade | U36: Ocorrências
T37: Crítica | U37: =COUNTIFS('4 Análise ZBR'!$AA$40:$AA$133,1,'4 Análise ZBR'!$BF$40:$BF$133,T37) -> 3
T38: Alta | U38: =COUNTIFS('4 Análise ZBR'!$AA$40:$AA$133,1,'4 Análise ZBR'!$BF$40:$BF$133,T38) -> 4
T39: Média | U39: =COUNTIFS('4 Análise ZBR'!$AA$40:$AA$133,1,'4 Análise ZBR'!$BF$40:$BF$133,T39) -> 4
T40: Baixa | U40: =COUNTIFS('4 Análise ZBR'!$AA$40:$AA$133,1,'4 Análise ZBR'!$BF$40:$BF$133,T40) -> 12
T43: Status do plano | U43: Ações
T44: Não iniciado | U44: =COUNTIF('6 Plano de Ação'!$O$8:$O$507,T44) -> 61
T45: Em andamento | U45: =COUNTIF('6 Plano de Ação'!$O$8:$O$507,T45) -> 0
T46: Concluído | U46: =COUNTIF('6 Plano de Ação'!$O$8:$O$507,T46) -> 0
T47: Cancelado | U47: =COUNTIF('6 Plano de Ação'!$O$8:$O$507,T47) -> 0
I73: Leitura rápida
I74: • Azul = entrou no ZBR · azul-claro = saiu. Verde = regular · amarelo = atenção · vermelho = crítico.
I75: • Todos os números seguem os filtros do topo, exceto Pendências e % Conclusão (plano de ação geral).
...

Sheet 2 Resumo Gerencial
A1: Resumo Gerencial | I1: ◄ MENU
A2: Síntese das análises, principais ocorrências e conclusões · visão geral (sem filtros)
B5: 1. Escopo da análise
B6: Item | C6: Valor
B7: Primeira data de movimento | C7: =MIN(MIN('3 Base Entrada 2008'!$F$2:$F$5000),MIN('3 Base Saídas'!$G$2:$G$5000)) -> 46274
B8: Última data de movimento | C8: =MAX(MAX('3 Base Entrada 2008'!$F$2:$F$5000),MAX('3 Base Saídas'!$G$2:$G$5000)) -> 46296
B9: SKU·lote conciliados | C9: =COUNTA('5 Conciliação'!$A$14:$A$107) -> 94
B10: Lançamentos no depósito 2008 (base Entrada) | C10: =COUNTA('3 Base Entrada 2008'!$A$2:$A$5000) -> 201
B11: Lançamentos de saída 601 (base Saídas) | C11: =COUNTA('3 Base Saídas'!$A$2:$A$5000) -> 405
B12: Posições de estoque físico (base Estoque) | C12: =COUNTA('3 Base Estoque Físico'!$A$2:$A$5000) -> 228
B14: 2. Resultado da conciliação por unidade de medida
B15: Unidade | C15: SKU·lote | D15: Conferem | E15: Divergentes | F15: % conformidade | G15: Diferença líquida | H15: Sem explicação
B16: KG | C16: =COUNTIFS('5 Conciliação'!$D$14:$D$107,"KG") -> 81 | D16: =COUNTIFS('5 Conciliação'!$D$14:$D$107,"KG",'5 Conciliação'!$J$14:$J$107,"Confere") -> 58 | E16: =C16-D16 -> 23 | F16: =IF(C16=0,0,D16/C16) -> 0.71604938 | G16: =SUMIFS('5 Conciliação'!$I$14:$I$107,'5 Conciliação'!$D$14:$D$107,"KG") -> 19609.01 | H16: =SUMIFS('5 Conciliação'!$O$14:$O$107,'5 Conciliação'!$D$14:$D$107,"KG") -> 4630.78
B17: UN | C17: =COUNTIFS('5 Conciliação'!$D$14:$D$107,"UN") -> 6 | D17: =COUNTIFS('5 Conciliação'!$D$14:$D$107,"UN",'5 Conciliação'!$J$14:$J$107,"Confere") -> 3 | E17: =C17-D17 -> 3 | F17: =IF(C17=0,0,D17/C17) -> 0.5 | G17: =SUMIFS('5 Conciliação'!$I$14:$I$107,'5 Conciliação'!$D$14:$D$107,"UN") -> 64.22 | H17: =SUMIFS('5 Conciliação'!$O$14:$O$107,'5 Conciliação'!$D$14:$D$107,"UN") -> 4.22
B18: CX | C18: =COUNTIFS('5 Conciliação'!$D$14:$D$107,"CX") -> 7 | D18: =COUNTIFS('5 Conciliação'!$D$14:$D$107,"CX",'5 Conciliação'!$J$14:$J$107,"Confere") -> 5 | E18: =C18-D18 -> 2 | F18: =IF(C18=0,0,D18/C18) -> 0.71428571 | G18: =SUMIFS('5 Conciliação'!$I$14:$I$107,'5 Conciliação'!$D$14:$D$107,"CX") -> 0 | H18: =SUMIFS('5 Conciliação'!$O$14:$O$107,'5 Conciliação'!$D$14:$D$107,"CX") -> 0
B19: Total | C19: =SUM(C16:C18) -> 94 | D19: =SUM(D16:D18) -> 66 | E19: =SUM(E16:E18) -> 28 | F19: =IF(C19=0,0,D19/C19) -> 0.70212766
B21: 3. Divergências por categoria de causa
B22: Categoria | C22: Ocorrências | D22: Diferença (KG)
B23: Falta sem explicação | C23: =COUNTIFS('5 Conciliação'!$Q$14:$Q$107,B23) -> 3 | D23: =SUMIFS('5 Conciliação'!$I$14:$I$107,'5 Conciliação'!$Q$14:$Q$107,B23,'5 Conciliação'!$D$14:$D$107,"KG") -> -652.2
B24: Não localizado no estoque | C24: =COUNTIFS('5 Conciliação'!$Q$14:$Q$107,B24) -> 1 | D24: =SUMIFS('5 Conciliação'!$I$14:$I$107,'5 Conciliação'!$Q$14:$Q$107,B24,'5 Conciliação'!$D$14:$D$107,"KG") -> -261.12
B25: Saída sem baixa no estoque | C25: =COUNTIFS('5 Conciliação'!$Q$14:$Q$107,B25) -> 9 | D25: =SUMIFS('5 Conciliação'!$I$14:$I$107,'5 Conciliação'!$Q$14:$Q$107,B25,'5 Conciliação'!$D$14:$D$107,"KG") -> 2941.6
B26: Doca/transferência pendente | C26: =COUNTIFS('5 Conciliação'!$Q$14:$Q$107,B26) -> 1 | D26: =SUMIFS('5 Conciliação'!$I$14:$I$107,'5 Conciliação'!$Q$14:$Q$107,B26,'5 Conciliação'!$D$14:$D$107,"KG") -> 20.1
B27: Estoque anterior a 09/09 | C27: =COUNTIFS('5 Conciliação'!$Q$14:$Q$107,B27) -> 3 | D27: =SUMIFS('5 Conciliação'!$I$14:$I$107,'5 Conciliação'!$Q$14:$Q$107,B27,'5 Conciliação'!$D$14:$D$107,"KG") -> 410.04
B28: Troca de lote | C28: =COUNTIFS('5 Conciliação'!$Q$14:$Q$107,B28) -> 2 | D28: =SUMIFS('5 Conciliação'!$I$14:$I$107,'5 Conciliação'!$Q$14:$Q$107,B28,'5 Conciliação'!$D$14:$D$107,"KG") -> 0
B29: Sobra parcialmente explicada | C29: =COUNTIFS('5 Conciliação'!$Q$14:$Q$107,B29) -> 7 | D29: =SUMIFS('5 Conciliação'!$I$14:$I$107,'5 Conciliação'!$Q$14:$Q$107,B29,'5 Conciliação'!$D$14:$D$107,"KG") -> 16902.59
B30: Sobra sem explicação | C30: =COUNTIFS('5 Conciliação'!$Q$14:$Q$107,B30) -> 2 | D30: =SUMIFS('5 Conciliação'!$I$14:$I$107,'5 Conciliação'!$Q$14:$Q$107,B30,'5 Conciliação'!$D$14:$D$107,"KG") -> 248
B32: 4. Ocorrências por criticidade (proposta para validação)
B33: Criticidade | C33: Ocorrências | D33: Critério
B34: Crítica | C34: =COUNTIF('5 Conciliação'!$R$14:$R$107,"Crítica") -> 3 | D34: ="Não localizado no estoque, ou falta sem explicação ≥ "&Parâmetros!$K$6 -> Não localizado no estoque, ou falta sem explicação ≥ 200
B35: Alta | C35: =COUNTIF('5 Conciliação'!$R$14:$R$107,"Alta") -> 5 | D35: ="Outras faltas sem explicação, ou sobra sem explicação ≥ "&Parâmetros!$K$7 -> Outras faltas sem explicação, ou sobra sem explicação ≥ 500
B36: Média | C36: =COUNTIF('5 Conciliação'!$R$14:$R$107,"Média") -> 5 | D36: Sobra com parte sem explicação abaixo do limite
B37: Baixa | C37: =COUNTIF('5 Conciliação'!$R$14:$R$107,"Baixa") -> 15 | D37: Diferença totalmente explicada pelos dados
B39: 5. Cinco maiores ocorrências (diferença sem explicação)
B40: SKU | C40: Lote | D40: UM | E40: Diferença | F40: Sem explicação | G40: Categoria | H40: Criticidade
B41: =IFERROR(INDEX('5 Conciliação'!$A$14:$A$107,MATCH(LARGE('5 Conciliação'!$T$14:$T$107,1),'5 Conciliação'!$T$14:$T$107,0)),"") -> CHM-SP-Z3L-BR-U73 | C41: =IFERROR(INDEX('5 Conciliação'!$B$14:$B$107,MATCH(LARGE('5 Conciliação'!$T$14:$T$107,1),'5 Conciliação'!$T$14:$T$107,0)),"") -> 251880301 | D41: =IFERROR(INDEX('5 Conciliação'!$D$14:$D$107,MATCH(LARGE('5 Conciliação'!$T$14:$T$107,1),'5 Conciliação'!$T$14:$T$107,0)),"") -> KG | E41: =IFERROR(INDEX('5 Conciliação'!$I$14:$I$107,MATCH(LARGE('5 Conciliação'!$T$14:$T$107,1),'5 Conciliação'!$T$14:$T$107,0)),"") -> 3695 | F41: =IFERROR(INDEX('5 Conciliação'!$O$14:$O$107,MATCH(LARGE('5 Conciliação'!$T$14:$T$107,1),'5 Conciliação'!$T$14:$T$107,0)),"") -> 2148 | G41: =IFERROR(INDEX('5 Conciliação'!$Q$14:$Q$107,MATCH(LARGE('5 Conciliação'!$T$14:$T$107,1),'5 Conciliação'!$T$14:$T$107,0)),"") -> Sobra parcialmente explicada | H41: =IFERROR(INDEX('5 Conciliação'!$R$14:$R$107,MATCH(LARGE('5 Conciliação'!$T$14:$T$107,1),'5 Conciliação'!$T$14:$T$107,0)),"") -> Alta
B42: =IFERROR(INDEX('5 Conciliação'!$A$14:$A$107,MATCH(LARGE('5 Conciliação'!$T$14:$T$107,2),'5 Conciliação'!$T$14:$T$107,0)),"") -> 823-BR-D94 | C42: =IFERROR(INDEX('5 Conciliação'!$B$14:$B$107,MATCH(LARGE('5 Conciliação'!$T$14:$T$107,2),'5 Conciliação'!$T$14:$T$107,0)),"") -> 252103049 | D42: =IFERROR(INDEX('5 Conciliação'!$D$14:$D$107,MATCH(LARGE('5 Conciliação'!$T$14:$T$107,2),'5 Conciliação'!$T$14:$T$107,0)),"") -> KG | E42: =IFERROR(INDEX('5 Conciliação'!$I$14:$I$107,MATCH(LARGE('5 Conciliação'!$T$14:$T$107,2),'5 Conciliação'!$T$14:$T$107,0)),"") -> 2528.4 | F42: =IFERROR(INDEX('5 Conciliação'!$O$14:$O$107,MATCH(LARGE('5 Conciliação'!$T$14:$T$107,2),'5 Conciliação'!$T$14:$T$107,0)),"") -> 1260 | G42: =IFERROR(INDEX('5 Conciliação'!$Q$14:$Q$107,MATCH(LARGE('5 Conciliação'!$T$14:$T$107,2),'5 Conciliação'!$T$14:$T$107,0)),"") -> Sobra parcialmente explicada | H42: =IFERROR(INDEX('5 Conciliação'!$R$14:$R$107,MATCH(LARGE('5 Conciliação'!$T$14:$T$107,2),'5 Conciliação'!$T$14:$T$107,0)),"") -> Alta
B43: =IFERROR(INDEX('5 Conciliação'!$A$14:$A$107,MATCH(LARGE('5 Conciliação'!$T$14:$T$107,3),'5 Conciliação'!$T$14:$T$107,0)),"") -> W3-BR-25A | C43: =IFERROR(INDEX('5 Conciliação'!$B$14:$B$107,MATCH(LARGE('5 Conciliação'!$T$14:$T$107,3),'5 Conciliação'!$T$14:$T$107,0)),"") -> 253540301 | D43: =IFERROR(INDEX('5 Conciliação'!$D$14:$D$107,MATCH(LARGE('5 Conciliação'!$T$14:$T$107,3),'5 Conciliação'!$T$14:$T$107,0)),"") -> KG | E43: =IFERROR(INDEX('5 Conciliação'!$I$14:$I$107,MATCH(LARGE('5 Conciliação'!$T$14:$T$107,3),'5 Conciliação'!$T$14:$T$107,0)),"") -> 1083.39 | F43: =IFERROR(INDEX('5 Conciliação'!$O$14:$O$107,MATCH(LARGE('5 Conciliação'!$T$14:$T$107,3),'5 Conciliação'!$T$14:$T$107,0)),"") -> 562.8 | G43: =IFERROR(INDEX('5 Conciliação'!$Q$14:$Q$107,MATCH(LARGE('5 Conciliação'!$T$14:$T$107,3),'5 Conciliação'!$T$14:$T$107,0)),"") -> Sobra parcialmente explicada | H43: =IFERROR(INDEX('5 Conciliação'!$R$14:$R$107,MATCH(LARGE('5 Conciliação'!$T$14:$T$107,3),'5 Conciliação'!$T$14:$T$107,0)),"") -> Alta
B44: =IFERROR(INDEX('5 Conciliação'!$A$14:$A$107,MATCH(LARGE('5 Conciliação'!$T$14:$T$107,4),'5 Conciliação'!$T$14:$T$107,0)),"") -> CHP-20SICHP-760 | C44: =IFERROR(INDEX('5 Conciliação'!$B$14:$B$107,MATCH(LARGE('5 Conciliação'!$T$14:$T$107,4),'5 Conciliação'!$T$14:$T$107,0)),"") -> 252843369 | D44: =IFERROR(INDEX('5 Conciliação'!$D$14:$D$107,MATCH(LARGE('5 Conciliação'!$T$14:$T$107,4),'5 Conciliação'!$T$14:$T$107,0)),"") -> KG | E44: =IFERROR(INDEX('5 Conciliação'!$I$14:$I$107,MATCH(LARGE('5 Conciliação'!$T$14:$T$107,4),'5 Conciliação'!$T$14:$T$107,0)),"") -> 540 | F44: =IFERROR(INDEX('5 Conciliação'!$O$14:$O$107,MATCH(LARGE('5 Conciliação'!$T$14:$T$107,4),'5 Conciliação'!$T$14:$T$107,0)),"") -> 516 | G44: =IFERROR(INDEX('5 Conciliação'!$Q$14:$Q$107,MATCH(LARGE('5 Conciliação'!$T$14:$T$107,4),'5 Conciliação'!$T$14:$T$107,0)),"") -> Sobra parcialmente explicada | H44: =IFERROR(INDEX('5 Conciliação'!$R$14:$R$107,MATCH(LARGE('5 Conciliação'!$T$14:$T$107,4),'5 Conciliação'!$T$14:$T$107,0)),"") -> Alta
B45: =IFERROR(INDEX('5 Conciliação'!$A$14:$A$107,MATCH(LARGE('5 Conciliação'!$T$14:$T$107,5),'5 Conciliação'!$T$14:$T$107,0)),"") -> CHK-R30GOLD-BR-25A | C45: =IFERROR(INDEX('5 Conciliação'!$B$14:$B$107,MATCH(LARGE('5 Conciliação'!$T$14:$T$107,5),'5 Conciliação'!$T$14:$T$107,0)),"") -> 261130301 | D45: =IFERROR(INDEX('5 Conciliação'!$D$14:$D$107,MATCH(LARGE('5 Conciliação'!$T$14:$T$107,5),'5 Conciliação'!$T$14:$T$107,0)),"") -> KG | E45: =IFERROR(INDEX('5 Conciliação'!$I$14:$I$107,MATCH(LARGE('5 Conciliação'!$T$14:$T$107,5),'5 Conciliação'!$T$14:$T$107,0)),"") -> -442.2 | F45: =IFERROR(INDEX('5 Conciliação'!$O$14:$O$107,MATCH(LARGE('5 Conciliação'!$T$14:$T$107,5),'5 Conciliação'!$T$14:$T$107,0)),"") -> -442.2 | G45: =IFERROR(INDEX('5 Conciliação'!$Q$14:$Q$107,MATCH(LARGE('5 Conciliação'!$T$14:$T$107,5),'5 Conciliação'!$T$14:$T$107,0)),"") -> Falta sem explicação | H45: =IFERROR(INDEX('5 Conciliação'!$R$14:$R$107,MATCH(LARGE('5 Conciliação'!$T$14:$T$107,5),'5 Conciliação'!$T$14:$T$107,0)),"") -> Crítica
B47: 6. Depósito 2008 (importação) · KG
...

Sheet 3 Base Entrada 2008
A1: DOC.MATERIAL | B1: SKU | C1: LOTE | D1: DEPÓSITO | E1: CENTRO | F1: DATA DE LANÇAMENTO | G1: QUANTIDADE | H1: UM | I1: DATA DE ENTRADA | J1: HORA DO REGISTRO | K1: MOVIMENTAÇÃO | L1: ENTROU NO ZBR
A2: 4904083265 | B2: 2665-E4-U71 | C2: 252800202 | D2: 2008 | E2: BR01 | F2: 46289 | G2: -600 | H2: KG | I2: 46289 | J2: 0.87827546 | K2: =IF(AND(G2>0,F2<=Parâmetros!$C$6),"Recebido no 2008",IF(G2<0,"Entrada","Estorno")) -> Entrada | L2: =IF(K2="Recebido no 2008",0,-G2) -> 600
A3: 4904083324 | B3: 2665-E4-U71 | C3: 252800202 | D3: 2008 | E3: BR01 | F3: 46289 | G3: -600 | H3: KG | I3: 46289 | J3: 0.88203704 | K3: =IF(AND(G3>0,F3<=Parâmetros!$C$6),"Recebido no 2008",IF(G3<0,"Entrada","Estorno")) -> Entrada | L3: =IF(K3="Recebido no 2008",0,-G3) -> 600
A4: 4904153691 | B4: 70-30-38-BR-25A | C4: 260370301 | D4: 2008 | E4: BR01 | F4: 46294 | G4: -603 | H4: KG | I4: 46294 | J4: 0.68579861 | K4: =IF(AND(G4>0,F4<=Parâmetros!$C$6),"Recebido no 2008",IF(G4<0,"Entrada","Estorno")) -> Entrada | L4: =IF(K4="Recebido no 2008",0,-G4) -> 603
A5: 4904053448 | B5: 70-30-38-BR-25A | C5: 260070301 | D5: 2008 | E5: BR01 | F5: 46288 | G5: -2412 | H5: KG | I5: 46288 | J5: 0.26028935 | K5: =IF(AND(G5>0,F5<=Parâmetros!$C$6),"Recebido no 2008",IF(G5<0,"Entrada","Estorno")) -> Entrada | L5: =IF(K5="Recebido no 2008",0,-G5) -> 2412
A6: 4904053657 | B6: 70-30-38-BR-25A | C6: 260070301 | D6: 2008 | E6: BR01 | F6: 46288 | G6: -603 | H6: KG | I6: 46288 | J6: 0.27048611 | K6: =IF(AND(G6>0,F6<=Parâmetros!$C$6),"Recebido no 2008",IF(G6<0,"Entrada","Estorno")) -> Entrada | L6: =IF(K6="Recebido no 2008",0,-G6) -> 603
A7: 4904053653 | B7: 70-30-38-BR-D94 | C7: 253213449 | D7: 2008 | E7: BR01 | F7: 46288 | G7: -940.8 | H7: KG | I7: 46288 | J7: 0.26896991 | K7: =IF(AND(G7>0,F7<=Parâmetros!$C$6),"Recebido no 2008",IF(G7<0,"Entrada","Estorno")) -> Entrada | L7: =IF(K7="Recebido no 2008",0,-G7) -> 940.8
A8: 4904151607 | B8: 805-BR-D94 | C8: 251633359 | D8: 2008 | E8: BR01 | F8: 46294 | G8: -313.6 | H8: KG | I8: 46294 | J8: 0.61137731 | K8: =IF(AND(G8>0,F8<=Parâmetros!$C$6),"Recebido no 2008",IF(G8<0,"Entrada","Estorno")) -> Entrada | L8: =IF(K8="Recebido no 2008",0,-G8) -> 313.6
A9: 4904151607 | B9: 805-BR-D94 | C9: 260130779 | D9: 2008 | E9: BR01 | F9: 46294 | G9: -142.8 | H9: KG | I9: 46294 | J9: 0.61137731 | K9: =IF(AND(G9>0,F9<=Parâmetros!$C$6),"Recebido no 2008",IF(G9<0,"Entrada","Estorno")) -> Entrada | L9: =IF(K9="Recebido no 2008",0,-G9) -> 142.8
A10: 4904175204 | B10: 811-BR-25A | C10: 252450301 | D10: 2008 | E10: BR01 | F10: 46295 | G10: -221.1 | H10: KG | I10: 46295 | J10: 0.74815972 | K10: =IF(AND(G10>0,F10<=Parâmetros!$C$6),"Recebido no 2008",IF(G10<0,"Entrada","Estorno")) -> Entrada | L10: =IF(K10="Recebido no 2008",0,-G10) -> 221.1
A11: 4904153935 | B11: 811-BR-25A | C11: 252450301 | D11: 2008 | E11: BR01 | F11: 46294 | G11: -482.4 | H11: KG | I11: 46294 | J11: 0.69373843 | K11: =IF(AND(G11>0,F11<=Parâmetros!$C$6),"Recebido no 2008",IF(G11<0,"Entrada","Estorno")) -> Entrada | L11: =IF(K11="Recebido no 2008",0,-G11) -> 482.4
A12: 4904153935 | B12: 811-BR-25A | C12: 252450301 | D12: 2008 | E12: BR01 | F12: 46294 | G12: -221.1 | H12: KG | I12: 46294 | J12: 0.69373843 | K12: =IF(AND(G12>0,F12<=Parâmetros!$C$6),"Recebido no 2008",IF(G12<0,"Entrada","Estorno")) -> Entrada | L12: =IF(K12="Recebido no 2008",0,-G12) -> 221.1
A13: 4904153935 | B13: 811-BR-25A | C13: 252450301 | D13: 2008 | E13: BR01 | F13: 46294 | G13: -603 | H13: KG | I13: 46294 | J13: 0.69373843 | K13: =IF(AND(G13>0,F13<=Parâmetros!$C$6),"Recebido no 2008",IF(G13<0,"Entrada","Estorno")) -> Entrada | L13: =IF(K13="Recebido no 2008",0,-G13) -> 603
... A202: 4903864964 | B202: W3-BR-25A | C202: 261080301 | D202: 2008 | E202: BR01 | F202: 46275 | G202: 2995 | H202: KG | I202: 46275 | J202: 0.79055556 | K202: =IF(AND(G202>0,F202<=Parâmetros!$C$6),"Recebido no 2008",IF(G202<0,"Entrada","Estorno")) -> Recebido no 2008 | L202: =IF(K202="Recebido no 2008",0,-G202) -> 0

Sheet 3 Base Saídas
A1: DOC.MATERIAL | B1: SKU | C1: LOTE | D1: DESCRIÇÃO | E1: DEPÓSITO | F1: CENTRO | G1: DATA DE LANÇAMENTO | H1: QUANTIDADE | I1: UM | J1: DATA DE ENTRADA | K1: TIPO DE MOVIMENTO | L1: MOTIVO DO MOVIMENTO | M1: HORA DO REGISTRO | N1: NOME DO USUÁRIO | O1: REFERÊNCIA | P1: CLIENTE | Q1: NOME 1 | R1: SAIU
A2: 4904167047 | B2: 70-30-38-BR-25A | C2: 260070301 | D2: CA MOEDAS 2,01KG/UC 10UC/CX 30CX/PAL | E2: 9999 | F2: BR01 | G2: 46295 | H2: -40.2 | I2: KG | J2: 46295 | K2: 601 | L2: 0 | M2: 0.43071759 | N2: BC140676 | O2: 0017883533 | P2: 50643 | Q2: PRODUPAN - PRODUTOS PARA PANIFICACA | R2: =-H2 -> 40.2
A3: 4904165495 | B3: 70-30-38-BR-25A | C3: 260070301 | D3: CA MOEDAS 2,01KG/UC 10UC/CX 30CX/PAL | E3: 9999 | F3: BR01 | G3: 46295 | H3: -60.3 | I3: KG | J3: 46295 | K3: 601 | L3: 0 | M3: 0.3559838 | N3: BC140676 | O3: 0017883681 | P3: 218096 | Q3: T & F ALIMENTOS LTDA | R3: =-H3 -> 60.3
A4: 4904175148 | B4: 70-30-38-BR-25A | C4: 260370301 | D4: CA MOEDAS 2,01KG/UC 10UC/CX 30CX/PAL | E4: 0355 | F4: BR01 | G4: 46295 | H4: -20.1 | I4: KG | J4: 46295 | K4: 601 | L4: 0 | M4: 0.74501157 | N4: BC025150 | O4: 0017883735 | P4: 218814 | Q4: ANGELA PRATI FAVARO . LTDA | R4: =-H4 -> 20.1
A5: 4904159986 | B5: 70-30-38-BR-25A | C5: 260070301 | D5: CA MOEDAS 2,01KG/UC 10UC/CX 30CX/PAL | E5: 9999 | F5: BR01 | G5: 46294 | H5: -80.4 | I5: KG | J5: 46295 | K5: 601 | L5: 0 | M5: 0.0053935185 | N5: BC140676 | O5: 0017884035 | P5: 50588 | Q5: DISTRIBUIDORA E IMPORTADORA IRMAOS | R5: =-H5 -> 80.4
A6: 4904134037 | B6: 70-30-38-BR-25A | C6: 260370301 | D6: CA MOEDAS 2,01KG/UC 10UC/CX 30CX/PAL | E6: 0355 | F6: BR01 | G6: 46293 | H6: -20.1 | I6: KG | J6: 46293 | K6: 601 | L6: 0 | M6: 0.68363426 | N6: BC025148 | O6: 0017878206 | P6: 78892 | Q6: TANGARA DESENV IMOBIL | R6: =-H6 -> 20.1
A7: 4904119924 | B7: 70-30-38-BR-25A | C7: 260070301 | D7: CA MOEDAS 2,01KG/UC 10UC/CX 30CX/PAL | E7: 9999 | F7: BR01 | G7: 46292 | H7: -201 | I7: KG | J7: 46292 | K7: 601 | L7: 0 | M7: 0.82452546 | N7: BC147417 | O7: 0017871992 | P7: 73161 | Q7: LARGO DO CONFEITEIRO | R7: =-H7 -> 201
A8: 4904118269 | B8: 70-30-38-BR-25A | C8: 260070301 | D8: CA MOEDAS 2,01KG/UC 10UC/CX 30CX/PAL | E8: 9999 | F8: BR01 | G8: 46292 | H8: -20.1 | I8: KG | J8: 46292 | K8: 601 | L8: 0 | M8: 0.6312963 | N8: BC147417 | O8: 0017883375 | P8: 91915 | Q8: CHOCOLANDIA SOBELA LTDA | R8: =-H8 -> 20.1
A9: 4904119956 | B9: 70-30-38-BR-25A | C9: 260070301 | D9: CA MOEDAS 2,01KG/UC 10UC/CX 30CX/PAL | E9: 9999 | F9: BR01 | G9: 46292 | H9: -40.2 | I9: KG | J9: 46292 | K9: 601 | L9: 0 | M9: 0.82537037 | N9: BC147417 | O9: 0017878161 | P9: 99526 | Q9: BRUNO MENEGATTE COMERCIO LTDA | R9: =-H9 -> 40.2
A10: 4904122562 | B10: 70-30-38-BR-25A | C10: 260070301 | D10: CA MOEDAS 2,01KG/UC 10UC/CX 30CX/PAL | E10: 9999 | F10: BR01 | G10: 46292 | H10: -261.3 | I10: KG | J10: 46293 | K10: 601 | L10: 0 | M10: 0.12189815 | N10: BC116065 | O10: 0017871957 | P10: 68094 | Q10: NOVA GERACAO COMESTIVEIS LTDA | R10: =-H10 -> 261.3
A11: 4904119981 | B11: 70-30-38-BR-25A | C11: 260070301 | D11: CA MOEDAS 2,01KG/UC 10UC/CX 30CX/PAL | E11: 9999 | F11: BR01 | G11: 46292 | H11: -40.2 | I11: KG | J11: 46292 | K11: 601 | L11: 0 | M11: 0.82577546 | N11: BC147417 | O11: 0017881061 | P11: 218044 | Q11: GELATERIA PIEMONTE LTDA | R11: =-H11 -> 40.2
A12: 4904119985 | B12: 70-30-38-BR-25A | C12: 260070301 | D12: CA MOEDAS 2,01KG/UC 10UC/CX 30CX/PAL | E12: 9999 | F12: BR01 | G12: 46292 | H12: -20.1 | I12: KG | J12: 46292 | K12: 601 | L12: 0 | M12: 0.82583333 | N12: BC147417 | O12: 0017881065 | P12: 216990 | Q12: PANIFICACAO IPANEMA LTDA | R12: =-H12 -> 20.1
A13: 4904119988 | B13: 70-30-38-BR-25A | C13: 260070301 | D13: CA MOEDAS 2,01KG/UC 10UC/CX 30CX/PAL | E13: 9999 | F13: BR01 | G13: 46292 | H13: -40.2 | I13: KG | J13: 46292 | K13: 601 | L13: 0 | M13: 0.82590278 | N13: BC147417 | O13: 0017881171 | P13: 218068 | Q13: ABSURDINHA CONFEITARIA LTDA | R13: =-H13 -> 40.2
... A406: 4903864174 | B406: W3-BR-25A | C406: 253540301 | D406: CA MOEDAS 2,01KG/UC 10UC/CX 30CX/PAL | E406: 9999 | F406: BR01 | G406: 46275 | H406: -20.1 | I406: KG | J406: 46275 | K406: 601 | L406: 0 | M406: 0.74628472 | N406: BC129357 | O406: 0017854540 | P406: 94517 | Q406: JANE'S APPLE FACTORY LTDA | R406: =-H406 -> 20.1

Sheet 3 Base Estoque Físico
A1: SKU | B1: LOTE | C1: TIPO DE DEPÓSITO | D1: POSIÇÃO NO DEPÓSITO | E1: Nº DE QUANTOS | F1: TIPO DE ESTOQUE | G1: UNIDADE DE DEPÓSITO | H1: ESTOQUE DISPONÍVEL | I1: ÚLTIMO MOVIMENTO | J1: ESTOQUE FÍSICO | K1: UM | L1: DURAÇÃO | M1: DEPÓSITO | N1: DATA DO VENCIMENTO | O1: CENTRO
A2: CHK-R30GOLD-BR-25A | B2: 261130301 | C2: 922 | D2: TR-ZONE | E2: 55 | H2: 603 | I2: 46293 | J2: 603 | K2: KG | L2: 3 | M2: 0355 | O2: BR01
A3: CHK-R30GOLD-BR-25A | B3: 261130301 | C3: 922 | D3: TR-ZONE | E3: 55 | H3: -603 | I3: 46293 | J3: -603 | K3: KG | L3: 0 | M3: 9999 | O3: BR01
A4: W3-BR-25A | B4: 253540301 | C4: 922 | D4: U-ZONE | E4: 54 | H4: 281.4 | I4: 46280 | J4: 281.4 | K4: KG | L4: 54 | M4: 0355 | O4: BR01
A5: W3-BR-25A | B5: 253540301 | C5: DCK | D5: 0017854245 | E5: 1 | H5: -20.1 | I5: 46275 | J5: -20.1 | K5: KG | L5: 0 | M5: 9999 | O5: BR01
A6: 70-30-38-BR-25A | B6: 260370301 | C6: DCK | D6: 0017854263 | E6: 3 | H6: 20.1 | I6: 46279 | J6: 20.1 | K6: KG | L6: 17 | M6: 0355 | N6: 46789 | O6: BR01
A7: W3-BR-25A | B7: 253540301 | C7: DCK | D7: 0017854540 | E7: 1 | H7: -20.1 | I7: 46275 | J7: -20.1 | K7: KG | L7: 0 | M7: 9999 | O7: BR01
A8: W3-BR-25A | B8: 253540301 | C8: DCK | D8: 0017854808 | E8: 2 | H8: -20.1 | I8: 46275 | J8: -20.1 | K8: KG | L8: 0 | M8: 9999 | N8: 46558 | O8: BR01
A9: CHK-R30GOLD-E0-D94 | B9: 260720939 | C9: DCK | D9: 0017871931 | E9: 1 | H9: 19.599 | I9: 46287 | J9: 19.599 | K9: KG | L9: 9 | M9: 0355 | N9: 46459 | O9: BR01
A10: CHM-SP-Z3L-BR-U73 | B10: 251880301 | C10: DCK | D10: 0017872245 | E10: 1 | H10: 144 | I10: 46293 | J10: 144 | K10: KG | L10: 9 | M10: 9999 | N10: 46394 | O10: BR01
A11: CHK-R30GOLD-BR-25A | B11: 261130301 | C11: DCK | D11: 0017882892 | E11: 1 | H11: 804 | I11: 46291 | J11: 804 | K11: KG | L11: 5 | M11: 9999 | N11: 46683 | O11: BR01
A12: CHK-R30GOLD-BR-25A | B12: 261130301 | C12: DCK | D12: 0017883414 | E12: 2 | H12: 60.3 | I12: 46291 | J12: 60.3 | K12: KG | L12: 5 | M12: 9999 | N12: 46683 | O12: BR01
A13: CHR-Q37RB2-2B-U75 | B13: 261320202 | C13: DCK | D13: 0017883414 | E13: 2 | H13: 40 | I13: 46291 | J13: 40 | K13: KG | L13: 5 | M13: 9999 | N13: 46703 | O13: BR01
A14: 805-BR-D94 | B14: 251633359 | C14: DIF | D14: PICKLINE | E14: 40 | H14: 2.8 | I14: 46291 | J14: 2.8 | K14: KG | L14: 5 | M14: 9999 | N14: 46550 | O14: BR01
A15: 823NV-595 | B15: 261376101 | C15: DIF | D15: PICKLINE | E15: 40 | H15: 20 | I15: 46294 | J15: 20 | K15: KG | L15: 2 | M15: 9999 | O15: BR01
A16: CW2-BR-25A | B16: 252650301 | C16: DIF | D16: PICKLINE | E16: 40 | H16: 20.1 | I16: 46293 | J16: 20.1 | K16: KG | L16: 3 | M16: 9999 | N16: 46468 | O16: BR01
A17: CW2-BR-25A | B17: 253470301 | C17: FGF | D17: 06-18-E | E17: 1 | G17: 1021977000 | H17: 603 | I17: 46291 | J17: 603 | K17: KG | L17: 5 | M17: 9999 | N17: 46551 | O17: BR01
A18: CW2-BR-25A | B18: 252590301 | C18: FGF | D18: 06-20-E | E18: 1 | G18: 1021976000 | H18: 603 | I18: 46291 | J18: 603 | K18: KG | L18: 5 | M18: 9999 | N18: 46462 | O18: BR01
A19: NIBS-S502-X47 | B19: 252643099 | C19: FGF | D19: 06-87-E | E19: 1 | G19: 1021970000 | H19: 120 | I19: 46291 | J19: 120 | K19: CX | L19: 5 | M19: 9999 | N19: 46651 | O19: BR01
A20: CW2-BR-25A | B20: 261070301 | C20: FGF | D20: 07-107-E | E20: 1 | G20: 1021963000 | H20: 180.9 | I20: 46291 | J20: 180.9 | K20: KG | L20: 8 | M20: 9999 | N20: 46677 | O20: BR01
A21: 823-BR-25A | B21: 252100301 | C21: FGF | D21: 07-78-C | E21: 1 | G21: 1021970000 | H21: 19.7 | I21: 46291 | J21: 19.7 | K21: KG | L21: 5 | M21: 9999 | N21: 46416 | O21: BR01
A22: NIBS-S502-X47 | B22: 253490619 | C22: FGF | D22: 07-85-E | E22: 1 | G22: 1021970000 | H22: 120 | I22: 46291 | J22: 120 | K22: CX | L22: 5 | M22: 9999 | N22: 46736 | O22: BR01
A23: PRA-T14 | B23: 2611895339 | C23: FLR | D23: 0007939602 | E23: 1 | G23: 1021969000 | H23: 40 | I23: 46289 | J23: 40 | K23: KG | L23: 7 | M23: 9999 | N23: 46505 | O23: BR01
A24: NIBS-S502-X47 | B24: 242643099 | C24: FLR | D24: 0007940118 | E24: 1 | G24: 1021970000 | H24: 120 | I24: 46289 | J24: 120 | K24: CX | L24: 7 | M24: 9999 | N24: 46736 | O24: BR01
A25: PNP-T14 | B25: 2613495951 | C25: FLR | D25: 0007950573 | E25: 1 | G25: 1021986000 | H25: 300 | I25: 46294 | J25: 300 | K25: KG | L25: 2 | M25: 9999 | N25: 46521 | O25: BR01
A26: PNP-T14 | B26: 2613495951 | C26: FLR | D26: 0007950576 | E26: 1 | G26: 1021986000 | H26: 500 | I26: 46294 | J26: 500 | K26: KG | L26: 2 | M26: 9999 | N26: 46521 | O26: BR01
A27: DCP-10BONOI-89B | B27: 260778132 | C27: FLR | D27: 0007950581 | E27: 1 | G27: 1021986000 | H27: 126 | I27: 46295 | J27: 126 | K27: KG | L27: 2 | M27: 9999 | N27: 46830 | O27: BR01
A28: 811-BR-25A | B28: 252450301 | C28: FLR | D28: 0007950649 | E28: 1 | G28: 1021986000 | H28: 221.1 | I28: 46294 | J28: 221.1 | K28: KG | L28: 2 | M28: 9999 | N28: 46632 | O28: BR01
... A34: 811NV-132 | B34: 252510301 | C34: FLR | D34: AREA | E34: 44 | G34: 1021983000 | H34: 500 | I34: 46293 | J34: 500 | K34: KG | L34: 3 | M34: 9999 | N34: 46638 | O34: BR01
A35: 811NV-595 | B35: 260920702 | C35: FLR | D35: AREA | E35: 44 | F35: S | G35: 1021917000 | H35: 600 | I35: 46276 | J35: 600 | K35: KG | L35: 20 | M35: 9999 | N35: 46845 | O35: BR01
A36: BIG-PF-1BO-401 | B36: 26126039 | C36: FLR | D36: AREA | E36: 44 | F36: S | G36: 1021917000 | H36: 40 | I36: 46276 | J36: 40 | K36: KG | L36: 20 | M36: 9999 | N36: 46568 | O36: BR01
A37: CHM-TS-22351E0-999 | B37: 2526050307 | C37: FLR | D37: AREA | E37: 44 | F37: Q | G37: 1021907000 | H37: 1.36 | I37: 46274 | J37: 1.36 | K37: KG | L37: 22 | M37: 9999 | N37: 46463 | O37: BR01
A38: 70-30-38-BR-D94 | B38: 253213449 | C38: FLR | D38: D2 | E38: 530 | F38: R | G38: 1021981000 | H38: 11.2 | I38: 46293 | J38: 11.2 | K38: KG | L38: 3 | M38: 0355 | N38: 46708 | O38: BR01
A39: 823-BR-D94 | B39: 252103049 | C39: FLR | D39: D2 | E39: 530 | F39: R | G39: 1021981000 | H39: 14 | I39: 46293 | J39: 14 | K39: KG | L39: 3 | M39: 0355 | N39: 46416 | O39: BR01
A40: CHK-R30GOLD-BR-25A | B40: 253620301 | C40: FLR | D40: D2 | E40: 530 | F40: R | G40: 1021956000 | H40: 80.4 | I40: 46286 | J40: 80.4 | K40: KG | L40: 10 | M40: 9999 | N40: 46566 | O40: BR01
A41: CW2-BR-25A | B41: 252350301 | C41: FLR | D41: D2 | E41: 530 | F41: R | G41: 1021956000 | H41: 20.1 | I41: 46286 | J41: 20.1 | K41: KG | L41: 10 | M41: 9999 | N41: 46441 | O41: BR01
A42: 811-BR-25A | B42: 250880301 | C42: FLR | D42: DESCARTE | E42: 519 | F42: R | G42: 1021773000 | H42: 20.1 | I42: 46240 | J42: 20.1 | K42: KG | L42: 56 | M42: 9999 | N42: 46475 | O42: BR01
A43: CHM-SP-Z3L-BR-U73 | B43: 251880301 | C43: FLR | D43: DESCARTE | E43: 519 | F43: R | G43: 1021929000 | H43: 60 | I43: 46279 | J43: 60 | K43: KG | L43: 17 | M43: 9999 | N43: 46394 | O43: BR01
A44: CHD-SP-9Z4-BR-U73 | B44: 250500301 | C44: FLR | D44: DEVOLUÇÃO | E44: 397 | F44: S | G44: 1021640000 | H44: 30 | I44: 46241 | J44: 30 | K44: KG | L44: 55 | M44: 9999 | N44: 46437 | O44: BR01
A45: CHM-SP-Z3L-BR-U73 | B45: 251880301 | C45: FM1 | D45: 10-002-F | E45: 1 | G45: 1021182000 | H45: 384 | I45: 46289 | J45: 384 | K45: KG | L45: 7 | M45: 9999 | N45: 46394 | O45: BR01
...

Sheet 3 Base Saldo Inicial 08-09
A1: SKU | B1: LOTE | C1: DEPÓSITO | D1: UM | E1: QUANTIDADE | F1: OBSERVAÇÃO | H1: COMO PREENCHER
H2: Cole aqui o estoque de cada SKU + lote + depósito em 08/09/2026 (dia anterior ao primeiro movimento).
H3: Fonte sugerida no SAP: estoque por data (ex.: MB5B) por material, lote e depósito, ou carregue pela consulta qSaldoInicial (aba 8 Atualizar Dados).
H4: Depósito 2008 → entra no saldo do 4 Análise Depósito 2008. Demais depósitos (9999, 0355…) → entram no Deveria ter do ZBR.
H5: Enquanto estiver vazia, a análise funciona como antes (sem saldo inicial).
H6: ="Saldo inicial informado: "&FIXED(SUM(E2:E5000),1)&" (somando todas as unidades) em "&COUNTA(A2:A5000)&" linhas." -> Saldo inicial informado: 0.0 (somando todas as unidades) em 0 linhas.

Sheet 3 Base Movimentos
A1: DATA | B1: MOVIMENTAÇÃO | C1: SKU | D1: LOTE | E1: DESCRIÇÃO | F1: DEPÓSITO | G1: UM | H1: QTD NO SAP | I1: ENTROU | J1: SAIU | K1: SALDO (±) | L1: DOCUMENTO | M1: CÓD. CLIENTE | N1: CLIENTE | O1: USUÁRIO
A2: 46274 | B2: Saída | C2: 805-BR-D94 | D2: 251633359 | E2: CA MOEDAS 0,4KG/UC 7UC/CX 144CX/PAL | F2: 9999 | G2: KG | H2: ='3 Base Saídas'!H80 -> -5.6 | I2: 0 | J2: ='3 Base Saídas'!R80 -> 5.6 | K2: =I2-J2 -> -5.6 | L2: 4903838325 | M2: 51879 | N2: TRANSELPE LTDA. - EPP | O2: BC140676
A3: 46274 | B3: Saída | C3: 823-BR-D94 | D3: 252103049 | E3: CA MOEDAS 0,4KG/UC 7UC/CX 144CX/PAL | F3: 9999 | G3: KG | H3: ='3 Base Saídas'!H177 -> -5.6 | I3: 0 | J3: ='3 Base Saídas'!R177 -> 5.6 | K3: =I3-J3 -> -5.6 | L3: 4903838325 | M3: 51879 | N3: TRANSELPE LTDA. - EPP | O3: BC140676
A4: 46274 | B4: ='3 Base Entrada 2008'!K156 -> Entrada | C4: CHM-TS-22351E0-999 | D4: 2525950306 | F4: 2008 | G4: KG | H4: ='3 Base Entrada 2008'!G156 -> -195.84 | I4: ='3 Base Entrada 2008'!L156 -> 195.84 | J4: 0 | K4: =I4-J4 -> 195.84 | L4: 4903843886
A5: 46274 | B5: ='3 Base Entrada 2008'!K157 -> Entrada | C5: CHM-TS-22351E0-999 | D5: 2526050307 | F5: 2008 | G5: KG | H5: ='3 Base Entrada 2008'!G157 -> -295.12 | I5: ='3 Base Entrada 2008'!L157 -> 295.12 | J5: 0 | K5: =I5-J5 -> 295.12 | L5: 4903843886
A6: 46275 | B6: ='3 Base Entrada 2008'!K117 -> Recebido no 2008 | C6: 70-30-38-BR-25A | D6: 260370301 | E6: CA MOEDAS 2,01KG/UC 10UC/CX 30CX/PAL | F6: 2008 | G6: KG | H6: ='3 Base Entrada 2008'!G117 -> 6633 | I6: ='3 Base Entrada 2008'!L117 -> 0 | J6: 0 | K6: =I6-J6 -> 0 | L6: 4903864964
A7: 46275 | B7: Saída | C7: 70-30-38-BR-25A | D7: 260370301 | E7: CA MOEDAS 2,01KG/UC 10UC/CX 30CX/PAL | F7: 0355 | G7: KG | H7: ='3 Base Saídas'!H29 -> -20.1 | I7: 0 | J7: ='3 Base Saídas'!R29 -> 20.1 | K7: =I7-J7 -> -20.1 | L7: 4903867283 | M7: 78892 | N7: TANGARA DESENV IMOBIL | O7: BC025148
A8: 46275 | B8: Saída | C8: 70-30-38-BR-25A | D8: 260370301 | E8: CA MOEDAS 2,01KG/UC 10UC/CX 30CX/PAL | F8: 0355 | G8: KG | H8: ='3 Base Saídas'!H30 -> -40.2 | I8: 0 | J8: ='3 Base Saídas'!R30 -> 40.2 | K8: =I8-J8 -> -40.2 | L8: 4903867234 | M8: 94669 | N8: ARTISANO GELATO LTDA | O8: BC025148
A9: 46275 | B9: Saída | C9: 70-30-38-BR-D94 | D9: 253213449 | E9: CA MOEDAS 0,4KG/UC 7UC/CX 144CX/PAL | F9: 0355 | G9: KG | H9: ='3 Base Saídas'!H55 -> -11.2 | I9: 0 | J9: ='3 Base Saídas'!R55 -> 11.2 | K9: =I9-J9 -> -11.2 | L9: 4903867892 | M9: 43229 | N9: VIMEG COMERCIO DE CHOCOLATES LTDA | O9: BC025148
A10: 46275 | B10: ='3 Base Entrada 2008'!K124 -> Recebido no 2008 | C10: 811NV-595 | D10: 261146101 | E10: CA CALLETS 10KG/UC 2UC/BOX 30BOX/PAL | F10: 2008 | G10: KG | H10: ='3 Base Entrada 2008'!G124 -> 4360 | I10: ='3 Base Entrada 2008'!L124 -> 0 | J10: 0 | K10: =I10-J10 -> 0 | L10: 4903865743
A11: 46275 | B11: ='3 Base Entrada 2008'!K123 -> Recebido no 2008 | C11: 811NV-595 | D11: 261146102 | E11: CA CALLETS 10KG/UC 2UC/BOX 30BOX/PAL | F11: 2008 | G11: KG | H11: ='3 Base Entrada 2008'!G123 -> 5240 | I11: ='3 Base Entrada 2008'!L123 -> 0 | J11: 0 | K11: =I11-J11 -> 0 | L11: 4903865743
A12: 46275 | B12: Saída | C12: 823-BR-D94 | D12: 252103049 | E12: CA MOEDAS 0,4KG/UC 7UC/CX 144CX/PAL | F12: 9999 | G12: KG | H12: ='3 Base Saídas'!H175 -> -28 | I12: 0 | J12: ='3 Base Saídas'!R175 -> 28 | K12: =I12-J12 -> -28 | L12: 4903869423 | M12: 48470 | N12: MARIA CHOCOLATE LTDA | O12: BC116065
A13: 46275 | B13: Saída | C13: 823-BR-D94 | D13: 252103049 | E13: CA MOEDAS 0,4KG/UC 7UC/CX 144CX/PAL | F13: 0355 | G13: KG | H13: ='3 Base Saídas'!H176 -> -14 | I13: 0 | J13: ='3 Base Saídas'!R176 -> 14 | K13: =I13-J13 -> -14 | L13: 4903867892 | M13: 43229 | N13: VIMEG COMERCIO DE CHOCOLATES LTDA | O13: BC025148
A14: 46275 | B14: ='3 Base Entrada 2008'!K128 -> Recebido no 2008 | C14: 823NV-595 | D14: 261376101 | E14: CA CALLETS 10KG/UC 2UC/BOX 30BOX/PAL | F14: 2008 | G14: KG | H14: ='3 Base Entrada 2008'!G128 -> 2400 | I14: ='3 Base Entrada 2008'!L128 -> 0 | J14: 0 | K14: =I14-J14 -> 0 | L14: 4903867530
A15: 46275 | B15: ='3 Base Entrada 2008'!K129 -> Recebido no 2008 | C15: 823NV-595 | D15: 261376101 | E15: CA CALLETS 10KG/UC 2UC/BOX 30BOX/PAL | F15: 2008 | G15: KG | H15: ='3 Base Entrada 2008'!G129 -> 3600 | I15: ='3 Base Entrada 2008'!L129 -> 0 | J15: 0 | K15: =I15-J15 -> 0 | L15: 4903867183
A16: 46275 | B16: Saída | C16: BIG-PF-1BO-401 | D16: 26044019 | E16: CB PAILLETÉ FEUILLETINE 2.5KG/UC 4UC/BOX | F16: 9999 | G16: KG | H16: ='3 Base Saídas'!H188 -> -10 | I16: 0 | J16: ='3 Base Saídas'!R188 -> 10 | K16: =I16-J16 -> -10 | L16: 4903859705 | M16: 90486 | N16: GI CARVALHO DOCERIA UBERABA LTDA | O16: BC147417
A17: 46275 | B17: ='3 Base Entrada 2008'!K133 -> Recebido no 2008 | C17: BIG-PF-1BO-401 | D17: 26126039 | E17: CB PAILLETÉ FEUILLETINE 2.5KG/UC 4UC/BOX | F17: 2008 | G17: KG | H17: ='3 Base Entrada 2008'!G133 -> 960 | I17: ='3 Base Entrada 2008'!L133 -> 0 | J17: 0 | K17: =I17-J17 -> 0 | L17: 4903866106
A18: 46275 | B18: ='3 Base Entrada 2008'!K134 -> Recebido no 2008 | C18: BIG-PF-1BO-401 | D18: 26126039 | E18: CB PAILLETÉ FEUILLETINE 2.5KG/UC 4UC/BOX | F18: 2008 | G18: KG | H18: ='3 Base Entrada 2008'!G134 -> 1920 | I18: ='3 Base Entrada 2008'!L134 -> 0 | J18: 0 | K18: =I18-J18 -> 0 | L18: 4903863360
A19: 46275 | B19: ='3 Base Entrada 2008'!K137 -> Recebido no 2008 | C19: CHD-SP-1M-2B-U77 | D19: 260880101 | F19: 2008 | G19: KG | H19: ='3 Base Entrada 2008'!G137 -> 600 | I19: ='3 Base Entrada 2008'!L137 -> 0 | J19: 0 | K19: =I19-J19 -> 0 | L19: 4903864964
A20: 46275 | B20: ='3 Base Entrada 2008'!K138 -> Recebido no 2008 | C20: CHD-SP-1M-2B-U77 | D20: 260880101 | F20: 2008 | G20: KG | H20: ='3 Base Entrada 2008'!G138 -> 1800 | I20: ='3 Base Entrada 2008'!L138 -> 0 | J20: 0 | K20: =I20-J20 -> 0 | L20: 4903863360
A21: 46275 | B21: ='3 Base Entrada 2008'!K140 -> Recebido no 2008 | C21: CHD-SP-1M-BR-U73 | D21: 260310301 | F21: 2008 | G21: KG | H21: ='3 Base Entrada 2008'!G140 -> 798 | I21: ='3 Base Entrada 2008'!L140 -> 0 | J21: 0 | K21: =I21-J21 -> 0 | L21: 4903864964
A22: 46275 | B22: ='3 Base Entrada 2008'!K139 -> Recebido no 2008 | C22: CHD-SP-1M-BR-U73 | D22: 260880301 | F22: 2008 | G22: KG | H22: ='3 Base Entrada 2008'!G139 -> 1122 | I22: ='3 Base Entrada 2008'!L139 -> 0 | J22: 0 | K22: =I22-J22 -> 0 | L22: 4903864964
A23: 46275 | B23: ='3 Base Entrada 2008'!K142 -> Recebido no 2008 | C23: CHD-VR-Z2S-E0-U68 | D23: 261160301 | F23: 2008 | G23: KG | H23: ='3 Base Entrada 2008'!G142 -> 1296 | I23: ='3 Base Entrada 2008'!L142 -> 0 | J23: 0 | K23: =I23-J23 -> 0 | L23: 4903863360
A24: 46275 | B24: ='3 Base Entrada 2008'!K146 -> Recebido no 2008 | C24: CHK-R30GOLD-BR-25A | D24: 252750301 | E24: CA MOEDAS 2,01KG/UC 10UC/CX 30CX/PAL | F24: 2008 | G24: KG | H24: ='3 Base Entrada 2008'!G146 -> 160.8 | I24: ='3 Base Entrada 2008'!L146 -> 0 | J24: 0 | K24: =I24-J24 -> 0 | L24: 4903865743
A25: 46275 | B25: ='3 Base Entrada 2008'!K147 -> Recebido no 2008 | C25: CHK-R30GOLD-BR-25A | D25: 261130301 | E25: CA MOEDAS 2,01KG/UC 10UC/CX 30CX/PAL | F25: 2008 | G25: KG | H25: ='3 Base Entrada 2008'!G147 -> 1025.1 | I25: ='3 Base Entrada 2008'!L147 -> 0 | J25: 0 | K25: =I25-J25 -> 0 | L25: 4903865743
A26: 46275 | B26: ='3 Base Entrada 2008'!K149 -> Recebido no 2008 | C26: CHM-BS-9U15-E0-07B | D26: 260701069 | E26: CA MILK BLOSSOMS BLOSSOMS 1KG/UC 4UC/BOX | F26: 2008 | G26: KG | H26: ='3 Base Entrada 2008'!G149 -> 1920 | I26: ='3 Base Entrada 2008'!L149 -> 0 | J26: 0 | K26: =I26-J26 -> 0 | L26: 4903864617
A27: 46275 | B27: ='3 Base Entrada 2008'!K151 -> Recebido no 2008 | C27: CHM-Q41ALUN-2B-U73 | D27: 260660303 | F27: 2008 | G27: KG | H27: ='3 Base Entrada 2008'!G151 -> 384 | I27: ='3 Base Entrada 2008'!L151 -> 0 | J27: 0 | K27: =I27-J27 -> 0 | L27: 4903864964
A28: 46275 | B28: Saída | C28: CHM-SP-Z3L-BR-U73 | D28: 251880301 | E28: CA MILK LARGE FLAKES SPLITTERS 1KG/UC | F28: 9999 | G28: KG | H28: ='3 Base Saídas'!H292 -> -42 | I28: 0 | J28: ='3 Base Saídas'!R292 -> 42 | K28: =I28-J28 -> -42 | L28: 4903869423 | M28: 48470 | N28: MARIA CHOCOLATE LTDA | O28: BC116065
A29: 46275 | B29: Saída | C29: CHP-20SICHP-760 | D29: 252843369 | E29: CA SILKY CHOCO POWDER POWDER 1KG/UC | F29: 9999 | G29: KG | H29: ='3 Base Saídas'!H302 -> -12 | I29: 0 | J29: ='3 Base Saídas'!R302 -> 12 | K29: =I29-J29 -> -12 | L29: 4903869423 | M29: 48470 | N29: MARIA CHOCOLATE LTDA | O29: BC116065
A30: 46275 | B30: ='3 Base Entrada 2008'!K161 -> Recebido no 2008 | C30: CHR-Q37RB2-2B-U75 | D30: 261320203 | E30: CA RUBY CALLETS 2.5KG/UC 4UC/BOX | F30: 2008 | G30: KG | H30: ='3 Base Entrada 2008'!G161 -> 840 | I30: ='3 Base Entrada 2008'!L161 -> 0 | J30: 0 | K30: =I30-J30 -> 0 | L30: 4903863360
A31: 46275 | B31: ='3 Base Entrada 2008'!K163 -> Recebido no 2008 | C31: CHR-Q37RB2-E0-D94 | D31: 261301539 | F31: 2008 | G31: KG | H31: ='3 Base Entrada 2008'!G163 -> 940.8 | I31: ='3 Base Entrada 2008'!L163 -> 0 | J31: 0 | K31: =I31-J31 -> 0 | L31: 4903863360
A32: 46275 | B32: ='3 Base Entrada 2008'!K164 -> Recebido no 2008 | C32: CHR-Q37RB2-E0-D94 | D32: 261301539 | F32: 2008 | G32: KG | H32: ='3 Base Entrada 2008'!G164 -> 932.4 | I32: ='3 Base Entrada 2008'!L164 -> 0 | J32: 0 | K32: =I32-J32 -> 0 | L32: 4903867530
A33: 46275 | B33: ='3 Base Entrada 2008'!K170 -> Recebido no 2008 | C33: CW2-BR-25A | D33: 252650301 | E33: CA MOEDAS 2,01KG/UC 10UC/CX 30CX/PAL | F33: 2008 | G33: KG | H33: ='3 Base Entrada 2008'!G170 -> 40 | I33: ='3 Base Entrada 2008'!L170 -> 0 | J33: 0 | K33: =I33-J33 -> 0 | L33: 4903864964
A34: 46275 | B34: Saída | C34: CW2-BR-25A | D34: 252650301 | E34: CA MOEDAS 2,01KG/UC 10UC/CX 30CX/PAL | F34: 9999 | G34: KG | H34: ='3 Base Saídas'!H354 -> -40.2 | I34: 0 | J34: ='3 Base Saídas'!R354 -> 40.2 | K34: =I34-J34 -> -40.2 | L34: 4903868815 | M34: 94605 | N34: BAKERY LTDA | O34: BC116065
A35: 46275 | B35: Saída | C35: CW2-BR-25A | D35: 253470301 | E35: CA MOEDAS 2,01KG/UC 10UC/CX 30CX/PAL | F35: 0355 | G35: KG | H35: ='3 Base Saídas'!H355 -> -60.3 | I35: 0 | J35: ='3 Base Saídas'!R355 -> 60.3 | K35: =I35-J35 -> -60.3 | L35: 4903867802 | M35: 42925 | N35: MORUMBY HOTEIS LTDA | O35: BC025148
A36: 46275 | B36: Saída | C36: CW2-BR-25A | D36: 253470301 | E36: CA MOEDAS 2,01KG/UC 10UC/CX 30CX/PAL | F36: 0355 | G36: KG | H36: ='3 Base Saídas'!H356 -> -80.4 | I36: 0 | J36: ='3 Base Saídas'!R356 -> 80.4 | K36: =I36-J36 -> -80.4 | L36: 4903867287 | M36: 75158 | N36: ATELIE MJ COMERCIO | O36: BC025148
A37: 46275 | B37: ='3 Base Entrada 2008'!K169 -> Recebido no 2008 | C37: CW2-BR-25A | D37: 261070301 | E37: CA MOEDAS 2,01KG/UC 10UC/CX 30CX/PAL | F37: 2008 | G37: KG | H37: ='3 Base Entrada 2008'!G169 -> 1166 | I37: ='3 Base Entrada 2008'!L169 -> 0 | J37: 0 | K37: =I37-J37 -> 0 | L37: 4903864964
A38: 46275 | B38: ='3 Base Entrada 2008'!K172 -> Recebido no 2008 | C38: CW2NV-595 | D38: 261070601 | F38: 2008 | G38: KG | H38: ='3 Base Entrada 2008'!G172 -> 600 | I38: ='3 Base Entrada 2008'!L172 -> 0 | J38: 0 | K38: =I38-J38 -> 0 | L38: 4903864964
A39: 46275 | B39: ='3 Base Entrada 2008'!K173 -> Recebido no 2008 | C39: CW2NV-595 | D39: 261070601 | F39: 2008 | G39: KG | H39: ='3 Base Entrada 2008'!G173 -> 1800 | I39: ='3 Base Entrada 2008'!L173 -> 0 | J39: 0 | K39: =I39-J39 -> 0 | L39: 4903864617
A40: 46275 | B40: ='3 Base Entrada 2008'!K174 -> Recebido no 2008 | C40: DCP-10BONOI-89B | D40: 260778132 | E40: CA BOTANICAL NOIR INTENSE 1KG/UC 6UC/BOX | F40: 2008 | G40: KG | H40: ='3 Base Entrada 2008'!G174 -> 864 | I40: ='3 Base Entrada 2008'!L174 -> 0 | J40: 0 | K40: =I40-J40 -> 0 | L40: 4903867530
...

Sheet 4 Análise ZBR
A1: Análise ZBR — por SKU e lote | O1: ◄ MENU | R1: =IF(A5="Todos","*",A5) -> * | AS1: Todos | AU1: 46274 | AV1: Todos | AW1: 2665-E4-U71 | AX1: 252800202 | AY1: =IF(OR($A$5="Todos",AW1=$A$5),1,0) -> 1 | AZ1: KG | BA1: Todas | BG1: Todos
A2: Entradas, saídas, estoque físico, diferença, motivo e solução por SKU e lote · filtros definidos no Dashboard | R2: =IF(OR(D5="Todos",D5=""),"*",D5) -> * | AS2: 2665-E4-U71 | AU2: 46275 | AV2: =IFERROR(INDEX($AX$1:$AX$94,MATCH(1,$AY$1:$AY$94,0)),"") -> 252800202 | AW2: 70-30-38-BR-25A | AX2: 260070301 | AY2: =IF(OR($A$5="Todos",AW2=$A$5),MAX(AY$1:AY1)+1,0) -> 2 | AZ2: UN | BA2: Entrada | BG2: Confere
R3: =IF(A5="Todos",J5,IFERROR(INDEX($U$40:$U$133,MATCH(A5,$T$40:$T$133,0)),J5)) -> KG | AS3: 70-30-38-BR-25A | AU3: 46276 | AV3: =IFERROR(INDEX($AX$1:$AX$94,MATCH(2,$AY$1:$AY$94,0)),"") -> 260070301 | AW3: 70-30-38-BR-25A | AX3: 260370301 | AY3: =IF(OR($A$5="Todos",AW3=$A$5),MAX(AY$1:AY2)+1,0) -> 3 | AZ3: CX | BA3: Saída | BG3: Sobrando
A4: SKU | D4: LOTE | F4: DATA INICIAL | H4: DATA FINAL | J4: UNIDADE | K4: MOVIMENTAÇÃO | R4: =IF(K5="Entrada","Entrada",IF(K5="Saída","Saída",IF(K5="Recebido no 2008","Recebido no 2008",IF(K5="Estorno","Estorno","*")))) -> * | AS4: 70-30-38-BR-D94 | AU4: 46277 | AV4: =IFERROR(INDEX($AX$1:$AX$94,MATCH(3,$AY$1:$AY$94,0)),"") -> 260370301 | AW4: 70-30-38-BR-D94 | AX4: 253213449 | AY4: =IF(OR($A$5="Todos",AW4=$A$5),MAX(AY$1:AY3)+1,0) -> 4 | BA4: Recebido no 2008 | BG4: Faltando
A5: ='1 Dashboard'!E5 -> Todos | D5: ='1 Dashboard'!H5 -> Todos | F5: ='1 Dashboard'!A5 -> 46274 | H5: ='1 Dashboard'!C5 -> 46296 | J5: ='1 Dashboard'!J5 -> KG | K5: ='1 Dashboard'!K5 -> Todas | R5: =Parâmetros!$C$7 -> 0.01 | AS5: 805-BR-D94 | AU5: 46278 | AV5: =IFERROR(INDEX($AX$1:$AX$94,MATCH(4,$AY$1:$AY$94,0)),"") -> 253213449 | AW5: 805-BR-D94 | AX5: 251633359 | AY5: =IF(OR($A$5="Todos",AW5=$A$5),MAX(AY$1:AY4)+1,0) -> 5 | BA5: Estorno
A6: Filtros definidos no Dashboard (fonte única para todas as análises). Para filtrar só esta tabela, use as setas do cabeçalho. | R6: =IF('1 Dashboard'!$N$5="Todos","*",'1 Dashboard'!$N$5) -> * | AS6: 811-BR-25A | AU6: 46279 | AV6: =IFERROR(INDEX($AX$1:$AX$94,MATCH(5,$AY$1:$AY$94,0)),"") -> 251633359 | AW6: 805-BR-D94 | AX6: 260130779 | AY6: =IF(OR($A$5="Todos",AW6=$A$5),MAX(AY$1:AY5)+1,0) -> 6
A7: ="Mostrando: "&IF(A5="Todos","todos os SKUs",A5)&IF(D5="Todos",""," · lote "&D5)&" · "&DAY(F5)&"/"&MONTH(F5)&"/"&YEAR(F5)&" a "&DAY(H5)&"/"&MONTH(H5)&"/"&YEAR(H5)&" · unidade "&$R$3&IF(K5="Todas",""," · movimentação "&K5) -> Mostrando: todos os SKUs · 9/9/2026 a 1/10/2026 · unidade KG | AS7: 811-BR-D94 | AU7: 46280 | AV7: =IFERROR(INDEX($AX$1:$AX$94,MATCH(6,$AY$1:$AY$94,0)),"") -> 260130779 | AW7: 811-BR-25A | AX7: 250880301 | AY7: =IF(OR($A$5="Todos",AW7=$A$5),MAX(AY$1:AY6)+1,0) -> 7
AS8: 811NV-132 | AU8: 46281 | AV8: =IFERROR(INDEX($AX$1:$AX$94,MATCH(7,$AY$1:$AY$94,0)),"") -> 250880301 | AW8: 811-BR-25A | AX8: 252450301 | AY8: =IF(OR($A$5="Todos",AW8=$A$5),MAX(AY$1:AY7)+1,0) -> 8
A9: ="ENTROU · "&$R$3 -> ENTROU · KG | C9: ="SAIU · "&$R$3 -> SAIU · KG | F9: ="DEVERIA TER · "&$R$3 -> DEVERIA TER · KG | H9: ="ESTOQUE FÍSICO · "&$R$3 -> ESTOQUE FÍSICO · KG | J9: ="DIFERENÇA · "&$R$3 -> DIFERENÇA · KG | L9: ="Confere: "&COUNTIFS($AA$40:$AA$133,1,$AC$40:$AC$133,"Confere")&" SKU·lote" -> Confere: 58 SKU·lote | N9: Indicadores e gráficos: aba Dashboard → | AS9: 811NV-595 | AU9: 46282 | AV9: =IFERROR(INDEX($AX$1:$AX$94,MATCH(8,$AY$1:$AY$94,0)),"") -> 252450301 | AW9: 811-BR-D94 | AX9: 251643289 | AY9: =IF(OR($A$5="Todos",AW9=$A$5),MAX(AY$1:AY8)+1,0) -> 9
A10: =SUMPRODUCT($AA$40:$AA$133,$W$40:$W$133) -> 65930.28 | C10: =SUMPRODUCT($AA$40:$AA$133,$X$40:$X$133) -> 26268.8 | F10: =SUMPRODUCT($AA$40:$AA$133,$BH$40:$BH$133)+A10-C10 -> 39661.48 | H10: =SUMPRODUCT($AA$40:$AA$133,$Y$40:$Y$133) -> 59270.487 | J10: =ROUND(H10-F10,3) -> 19609.007 | L10: ="Sobrando: "&COUNTIFS($AA$40:$AA$133,1,$AC$40:$AC$133,"Sobrando")&" SKU·lote" -> Sobrando: 20 SKU·lote | AS10: 823-BR-25A | AU10: 46283 | AV10: =IFERROR(INDEX($AX$1:$AX$94,MATCH(9,$AY$1:$AY$94,0)),"") -> 251643289 | AW10: 811NV-132 | AX10: 252510301 | AY10: =IF(OR($A$5="Todos",AW10=$A$5),MAX(AY$1:AY9)+1,0) -> 10
A11: transferido do 2008 para o ZBR | C11: vendas e entregas | F11: saldo inicial + entrou − saiu | H11: o que tem no depósito hoje | J11: =IF(OR(F5<>DATE(2026,9,9),H5<>DATE(2026,10,1)),"período parcial: compare com cuidado",IF(ABS(J10)<=$R$5,"tudo confere",IF(J10>0,"sobrando no estoque","faltando no estoque"))) -> sobrando no estoque | L11: ="Faltando: "&COUNTIFS($AA$40:$AA$133,1,$AC$40:$AC$133,"Faltando")&" SKU·lote" -> Faltando: 3 SKU·lote | AS11: 823-BR-D94 | AU11: 46284 | AV11: =IFERROR(INDEX($AX$1:$AX$94,MATCH(10,$AY$1:$AY$94,0)),"") -> 252510301 | AW11: 811NV-132 | AX11: 253280301 | AY11: =IF(OR($A$5="Todos",AW11=$A$5),MAX(AY$1:AY10)+1,0) -> 11
AS12: 823NV-132 | AU12: 46285 | AV12: =IFERROR(INDEX($AX$1:$AX$94,MATCH(11,$AY$1:$AY$94,0)),"") -> 253280301 | AW12: 811NV-595 | AX12: 260900702 | AY12: =IF(OR($A$5="Todos",AW12=$A$5),MAX(AY$1:AY11)+1,0) -> 12
A13: SKU | B13: LOTE | C13: UM | D13: SALDO INICIAL 08/09 | E13: ENTROU | F13: SAIU | G13: DEVERIA TER | H13: ESTOQUE FÍSICO | I13: DIFERENÇA | J13: SITUAÇÃO | K13: LANÇAMENTOS | L13: 1º LANÇAMENTO | M13: ÚLTIMO LANÇAMENTO | N13: MOTIVO DA DIFERENÇA | O13: SOLUÇÃO DE AJUSTE (SUGESTÃO) | AS13: 823NV-595 | AU13: 46286 | AV13: =IFERROR(INDEX($AX$1:$AX$94,MATCH(12,$AY$1:$AY$94,0)),"") -> 260900702 | AW13: 811NV-595 | AX13: 260920702 | AY13: =IF(OR($A$5="Todos",AW13=$A$5),MAX(AY$1:AY12)+1,0) -> 13
A14: =IF(IFERROR(MATCH(1,$AB$40:$AB$133,0),0)=0,"",INDEX($T$40:$T$133,IFERROR(MATCH(1,$AB$40:$AB$133,0),0))) -> CHK-R30GOLD-BR-25A | B14: =IF(IFERROR(MATCH(1,$AB$40:$AB$133,0),0)=0,"",INDEX($AG$40:$AG$133,IFERROR(MATCH(1,$AB$40:$AB$133,0),0))) -> 261130301 | C14: =IF(IFERROR(MATCH(1,$AB$40:$AB$133,0),0)=0,"",INDEX($U$40:$U$133,IFERROR(MATCH(1,$AB$40:$AB$133,0),0))) -> KG | D14: =IF(IFERROR(MATCH(1,$AB$40:$AB$133,0),0)=0,"",INDEX($BH$40:$BH$133,IFERROR(MATCH(1,$AB$40:$AB$133,0),0))) -> 0 | E14: =IF(IFERROR(MATCH(1,$AB$40:$AB$133,0),0)=0,"",INDEX($W$40:$W$133,IFERROR(MATCH(1,$AB$40:$AB$133,0),0))) -> 2673.3 | F14: =IF(IFERROR(MATCH(1,$AB$40:$AB$133,0),0)=0,"",INDEX($X$40:$X$133,IFERROR(MATCH(1,$AB$40:$AB$133,0),0))) -> 1005 | G14: =IF(A14="","",D14+E14-F14) -> 1668.3 | H14: =IF(IFERROR(MATCH(1,$AB$40:$AB$133,0),0)=0,"",INDEX($Y$40:$Y$133,IFERROR(MATCH(1,$AB$40:$AB$133,0),0))) -> 1226.1 | I14: =IF(IFERROR(MATCH(1,$AB$40:$AB$133,0),0)=0,"",INDEX($Z$40:$Z$133,IFERROR(MATCH(1,$AB$40:$AB$133,0),0))) -> -442.2 | J14: =IF(IFERROR(MATCH(1,$AB$40:$AB$133,0),0)=0,"",INDEX($AC$40:$AC$133,IFERROR(MATCH(1,$AB$40:$AB$133,0),0))) -> Faltando | K14: =IF(IFERROR(MATCH(1,$AB$40:$AB$133,0),0)=0,"",INDEX($AD$40:$AD$133,IFERROR(MATCH(1,$AB$40:$AB$133,0),0))) -> 17 | L14: =IF(IFERROR(MATCH(1,$AB$40:$AB$133,0),0)=0,"",IF(INDEX($BB$40:$BB$133,IFERROR(MATCH(1,$AB$40:$AB$133,0),0))>=99999,"",INDEX($BB$40:$BB$133,IFERROR(MATCH(1,$AB$40:$AB$133,0),0)))) -> 46275 | M14: =IF(IFERROR(MATCH(1,$AB$40:$AB$133,0),0)=0,"",IF(INDEX($BC$40:$BC$133,IFERROR(MATCH(1,$AB$40:$AB$133,0),0))=0,"",INDEX($BC$40:$BC$133,IFERROR(MATCH(1,$AB$40:$AB$133,0),0)))) -> 46295 | N14: =IF(IFERROR(MATCH(1,$AB$40:$AB$133,0),0)=0,"",INDEX($AE$40:$AE$133,IFERROR(MATCH(1,$AB$40:$AB$133,0),0))&"") -> Estoque físico menor que o esperado: saída, ajuste ou perda não lançada no período | O14: =IF(IFERROR(MATCH(1,$AB$40:$AB$133,0),0)=0,"",INDEX($BD$40:$BD$133,IFERROR(MATCH(1,$AB$40:$AB$133,0),0))&"") -> Contar o lote. Se a falta se confirmar: lançar a saída esquecida (601) ou ajuste de inventário de −442.2 KG | AS14: BIG-PF-1BO-401 | AU14: 46287 | AV14: =IFERROR(INDEX($AX$1:$AX$94,MATCH(13,$AY$1:$AY$94,0)),"") -> 260920702 | AW14: 811NV-595 | AX14: 261146101 | AY14: =IF(OR($A$5="Todos",AW14=$A$5),MAX(AY$1:AY13)+1,0) -> 14
A15: =IF(IFERROR(MATCH(2,$AB$40:$AB$133,0),0)=0,"",INDEX($T$40:$T$133,IFERROR(MATCH(2,$AB$40:$AB$133,0),0))) -> CHM-TS-P23-E0-999 | B15: =IF(IFERROR(MATCH(2,$AB$40:$AB$133,0),0)=0,"",INDEX($AG$40:$AG$133,IFERROR(MATCH(2,$AB$40:$AB$133,0),0))) -> 2605567696 | C15: =IF(IFERROR(MATCH(2,$AB$40:$AB$133,0),0)=0,"",INDEX($U$40:$U$133,IFERROR(MATCH(2,$AB$40:$AB$133,0),0))) -> KG | D15: =IF(IFERROR(MATCH(2,$AB$40:$AB$133,0),0)=0,"",INDEX($BH$40:$BH$133,IFERROR(MATCH(2,$AB$40:$AB$133,0),0))) -> 0 | E15: =IF(IFERROR(MATCH(2,$AB$40:$AB$133,0),0)=0,"",INDEX($W$40:$W$133,IFERROR(MATCH(2,$AB$40:$AB$133,0),0))) -> 261.12 | F15: =IF(IFERROR(MATCH(2,$AB$40:$AB$133,0),0)=0,"",INDEX($X$40:$X$133,IFERROR(MATCH(2,$AB$40:$AB$133,0),0))) -> 0 | G15: =IF(A15="","",D15+E15-F15) -> 261.12 | H15: =IF(IFERROR(MATCH(2,$AB$40:$AB$133,0),0)=0,"",INDEX($Y$40:$Y$133,IFERROR(MATCH(2,$AB$40:$AB$133,0),0))) -> 0 | I15: =IF(IFERROR(MATCH(2,$AB$40:$AB$133,0),0)=0,"",INDEX($Z$40:$Z$133,IFERROR(MATCH(2,$AB$40:$AB$133,0),0))) -> -261.12 | J15: =IF(IFERROR(MATCH(2,$AB$40:$AB$133,0),0)=0,"",INDEX($AC$40:$AC$133,IFERROR(MATCH(2,$AB$40:$AB$133,0),0))) -> Faltando | K15: =IF(IFERROR(MATCH(2,$AB$40:$AB$133,0),0)=0,"",INDEX($AD$40:$AD$133,IFERROR(MATCH(2,$AB$40:$AB$133,0),0))) -> 1 | L15: =IF(IFERROR(MATCH(2,$AB$40:$AB$133,0),0)=0,"",IF(INDEX($BB$40:$BB$133,IFERROR(MATCH(2,$AB$40:$AB$133,0),0))>=99999,"",INDEX($BB$40:$BB$133,IFERROR(MATCH(2,$AB$40:$AB$133,0),0)))) -> 46288 | M15: =IF(IFERROR(MATCH(2,$AB$40:$AB$133,0),0)=0,"",IF(INDEX($BC$40:$BC$133,IFERROR(MATCH(2,$AB$40:$AB$133,0),0))=0,"",INDEX($BC$40:$BC$133,IFERROR(MATCH(2,$AB$40:$AB$133,0),0)))) -> 46288 | N15: =IF(IFERROR(MATCH(2,$AB$40:$AB$133,0),0)=0,"",INDEX($AE$40:$AE$133,IFERROR(MATCH(2,$AB$40:$AB$133,0),0))&"") -> Entrou no ZBR, mas não está no estoque físico: não chegou ou foi guardado em outro lote | O15: =IF(IFERROR(MATCH(2,$AB$40:$AB$133,0),0)=0,"",INDEX($BD$40:$BD$133,IFERROR(MATCH(2,$AB$40:$AB$133,0),0))&"") -> Procurar a OT de armazenagem pendente no ZBR. Se não achar: contar e lançar ajuste de inventário de −261.1 KG | AS15: CHD-BB-308BY-357 | AU15: 46288 | AV15: =IFERROR(INDEX($AX$1:$AX$94,MATCH(14,$AY$1:$AY$94,0)),"") -> 261146101 | AW15: 811NV-595 | AX15: 261146102 | AY15: =IF(OR($A$5="Todos",AW15=$A$5),MAX(AY$1:AY14)+1,0) -> 15
A16: =IF(IFERROR(MATCH(3,$AB$40:$AB$133,0),0)=0,"",INDEX($T$40:$T$133,IFERROR(MATCH(3,$AB$40:$AB$133,0),0))) -> BIG-PF-1BO-401 | B16: =IF(IFERROR(MATCH(3,$AB$40:$AB$133,0),0)=0,"",INDEX($AG$40:$AG$133,IFERROR(MATCH(3,$AB$40:$AB$133,0),0))) -> 26044019 | C16: =IF(IFERROR(MATCH(3,$AB$40:$AB$133,0),0)=0,"",INDEX($U$40:$U$133,IFERROR(MATCH(3,$AB$40:$AB$133,0),0))) -> KG | D16: =IF(IFERROR(MATCH(3,$AB$40:$AB$133,0),0)=0,"",INDEX($BH$40:$BH$133,IFERROR(MATCH(3,$AB$40:$AB$133,0),0))) -> 0 | E16: =IF(IFERROR(MATCH(3,$AB$40:$AB$133,0),0)=0,"",INDEX($W$40:$W$133,IFERROR(MATCH(3,$AB$40:$AB$133,0),0))) -> 480 | F16: =IF(IFERROR(MATCH(3,$AB$40:$AB$133,0),0)=0,"",INDEX($X$40:$X$133,IFERROR(MATCH(3,$AB$40:$AB$133,0),0))) -> 60 | G16: =IF(A16="","",D16+E16-F16) -> 420 | H16: =IF(IFERROR(MATCH(3,$AB$40:$AB$133,0),0)=0,"",INDEX($Y$40:$Y$133,IFERROR(MATCH(3,$AB$40:$AB$133,0),0))) -> 210 | I16: =IF(IFERROR(MATCH(3,$AB$40:$AB$133,0),0)=0,"",INDEX($Z$40:$Z$133,IFERROR(MATCH(3,$AB$40:$AB$133,0),0))) -> -210 | J16: =IF(IFERROR(MATCH(3,$AB$40:$AB$133,0),0)=0,"",INDEX($AC$40:$AC$133,IFERROR(MATCH(3,$AB$40:$AB$133,0),0))) -> Faltando | K16: =IF(IFERROR(MATCH(3,$AB$40:$AB$133,0),0)=0,"",INDEX($AD$40:$AD$133,IFERROR(MATCH(3,$AB$40:$AB$133,0),0))) -> 5 | L16: =IF(IFERROR(MATCH(3,$AB$40:$AB$133,0),0)=0,"",IF(INDEX($BB$40:$BB$133,IFERROR(MATCH(3,$AB$40:$AB$133,0),0))>=99999,"",INDEX($BB$40:$BB$133,IFERROR(MATCH(3,$AB$40:$AB$133,0),0)))) -> 46275 | M16: =IF(IFERROR(MATCH(3,$AB$40:$AB$133,0),0)=0,"",IF(INDEX($BC$40:$BC$133,IFERROR(MATCH(3,$AB$40:$AB$133,0),0))=0,"",INDEX($BC$40:$BC$133,IFERROR(MATCH(3,$AB$40:$AB$133,0),0)))) -> 46295 | N16: =IF(IFERROR(MATCH(3,$AB$40:$AB$133,0),0)=0,"",INDEX($AE$40:$AE$133,IFERROR(MATCH(3,$AB$40:$AB$133,0),0))&"") -> Estoque físico menor que o esperado: saída, ajuste ou perda não lançada no período | O16: =IF(IFERROR(MATCH(3,$AB$40:$AB$133,0),0)=0,"",INDEX($BD$40:$BD$133,IFERROR(MATCH(3,$AB$40:$AB$133,0),0))&"") -> Contar o lote. Se a falta se confirmar: lançar a saída esquecida (601) ou ajuste de inventário de −210.0 KG | AS16: CHD-DR-75Y5-E1-U68 | AU16: 46289 | AV16: =IFERROR(INDEX($AX$1:$AX$94,MATCH(15,$AY$1:$AY$94,0)),"") -> 261146102 | AW16: 823-BR-25A | AX16: 252100301 | AY16: =IF(OR($A$5="Todos",AW16=$A$5),MAX(AY$1:AY15)+1,0) -> 16
